[2024-11-05T13:47:50.249+0000] {local_task_job_runner.py:123} INFO - ::group::Pre task execution logs
[2024-11-05T13:47:50.271+0000] {taskinstance.py:2612} INFO - Dependencies all met for dep_context=non-requeueable deps ti=<TaskInstance: dbt_docs_serve_dag.stop_dbt_docs_serve manual__2024-11-05T13:47:37.636530+00:00 [queued]>
[2024-11-05T13:47:50.282+0000] {taskinstance.py:2612} INFO - Dependencies all met for dep_context=requeueable deps ti=<TaskInstance: dbt_docs_serve_dag.stop_dbt_docs_serve manual__2024-11-05T13:47:37.636530+00:00 [queued]>
[2024-11-05T13:47:50.282+0000] {taskinstance.py:2865} INFO - Starting attempt 1 of 2
[2024-11-05T13:47:50.302+0000] {taskinstance.py:2888} INFO - Executing <Task(BashOperator): stop_dbt_docs_serve> on 2024-11-05 13:47:37.636530+00:00
[2024-11-05T13:47:50.310+0000] {warnings.py:112} WARNING - /home/***/.local/lib/python3.12/site-packages/***/task/task_runner/standard_task_runner.py:70: DeprecationWarning: This process (pid=455) is multi-threaded, use of fork() may lead to deadlocks in the child.
  pid = os.fork()

[2024-11-05T13:47:50.311+0000] {standard_task_runner.py:72} INFO - Started process 456 to run task
[2024-11-05T13:47:50.312+0000] {standard_task_runner.py:104} INFO - Running: ['***', 'tasks', 'run', 'dbt_docs_serve_dag', 'stop_dbt_docs_serve', 'manual__2024-11-05T13:47:37.636530+00:00', '--job-id', '106', '--raw', '--subdir', 'DAGS_FOLDER/dbt_docs_serve_dag.py', '--cfg-path', '/tmp/tmpqxwgzebh']
[2024-11-05T13:47:50.313+0000] {standard_task_runner.py:105} INFO - Job 106: Subtask stop_dbt_docs_serve
[2024-11-05T13:47:50.365+0000] {task_command.py:467} INFO - Running <TaskInstance: dbt_docs_serve_dag.stop_dbt_docs_serve manual__2024-11-05T13:47:37.636530+00:00 [running]> on host bbd20199defe
[2024-11-05T13:47:50.454+0000] {taskinstance.py:3131} INFO - Exporting env vars: AIRFLOW_CTX_DAG_OWNER='***' AIRFLOW_CTX_DAG_ID='dbt_docs_serve_dag' AIRFLOW_CTX_TASK_ID='stop_dbt_docs_serve' AIRFLOW_CTX_EXECUTION_DATE='2024-11-05T13:47:37.636530+00:00' AIRFLOW_CTX_TRY_NUMBER='1' AIRFLOW_CTX_DAG_RUN_ID='manual__2024-11-05T13:47:37.636530+00:00'
[2024-11-05T13:47:50.455+0000] {taskinstance.py:731} INFO - ::endgroup::
[2024-11-05T13:47:50.474+0000] {subprocess.py:63} INFO - Tmp dir root location: /tmp
[2024-11-05T13:47:50.475+0000] {subprocess.py:75} INFO - Running command: ['/usr/bin/bash', '-c', 'pkill -f "dbt docs serve"']
[2024-11-05T13:47:50.487+0000] {subprocess.py:86} INFO - Output:
[2024-11-05T13:47:50.489+0000] {subprocess.py:93} INFO - /usr/bin/bash: line 1: pkill: command not found
[2024-11-05T13:47:50.490+0000] {subprocess.py:97} INFO - Command exited with return code 127
[2024-11-05T13:47:50.503+0000] {taskinstance.py:3310} ERROR - Task failed with exception
Traceback (most recent call last):
  File "/home/airflow/.local/lib/python3.12/site-packages/airflow/models/taskinstance.py", line 767, in _execute_task
    result = _execute_callable(context=context, **execute_callable_kwargs)
             ^^^^^^^^^^^^^^^^^^^^^^^^^^^^^^^^^^^^^^^^^^^^^^^^^^^^^^^^^^^^^
  File "/home/airflow/.local/lib/python3.12/site-packages/airflow/models/taskinstance.py", line 733, in _execute_callable
    return ExecutionCallableRunner(
           ^^^^^^^^^^^^^^^^^^^^^^^^
  File "/home/airflow/.local/lib/python3.12/site-packages/airflow/utils/operator_helpers.py", line 252, in run
    return self.func(*args, **kwargs)
           ^^^^^^^^^^^^^^^^^^^^^^^^^^
  File "/home/airflow/.local/lib/python3.12/site-packages/airflow/models/baseoperator.py", line 406, in wrapper
    return func(self, *args, **kwargs)
           ^^^^^^^^^^^^^^^^^^^^^^^^^^^
  File "/home/airflow/.local/lib/python3.12/site-packages/airflow/operators/bash.py", line 249, in execute
    raise AirflowException(
airflow.exceptions.AirflowException: Bash command failed. The command returned a non-zero exit code 127.
[2024-11-05T13:47:50.512+0000] {taskinstance.py:1225} INFO - Marking task as UP_FOR_RETRY. dag_id=dbt_docs_serve_dag, task_id=stop_dbt_docs_serve, run_id=manual__2024-11-05T13:47:37.636530+00:00, execution_date=20241105T134737, start_date=20241105T134750, end_date=20241105T134750
[2024-11-05T13:47:50.532+0000] {taskinstance.py:340} INFO - ::group::Post task execution logs
[2024-11-05T13:47:50.533+0000] {standard_task_runner.py:124} ERROR - Failed to execute job 106 for task stop_dbt_docs_serve (Bash command failed. The command returned a non-zero exit code 127.; 456)
Traceback (most recent call last):
  File "/home/airflow/.local/lib/python3.12/site-packages/airflow/task/task_runner/standard_task_runner.py", line 117, in _start_by_fork
    ret = args.func(args, dag=self.dag)
          ^^^^^^^^^^^^^^^^^^^^^^^^^^^^^
  File "/home/airflow/.local/lib/python3.12/site-packages/airflow/cli/cli_config.py", line 49, in command
    return func(*args, **kwargs)
           ^^^^^^^^^^^^^^^^^^^^^
  File "/home/airflow/.local/lib/python3.12/site-packages/airflow/utils/cli.py", line 115, in wrapper
    return f(*args, **kwargs)
           ^^^^^^^^^^^^^^^^^^
  File "/home/airflow/.local/lib/python3.12/site-packages/airflow/cli/commands/task_command.py", line 483, in task_run
    task_return_code = _run_task_by_selected_method(args, _dag, ti)
                       ^^^^^^^^^^^^^^^^^^^^^^^^^^^^^^^^^^^^^^^^^^^^
  File "/home/airflow/.local/lib/python3.12/site-packages/airflow/cli/commands/task_command.py", line 256, in _run_task_by_selected_method
    return _run_raw_task(args, ti)
           ^^^^^^^^^^^^^^^^^^^^^^^
  File "/home/airflow/.local/lib/python3.12/site-packages/airflow/cli/commands/task_command.py", line 341, in _run_raw_task
    return ti._run_raw_task(
           ^^^^^^^^^^^^^^^^^
  File "/home/airflow/.local/lib/python3.12/site-packages/airflow/utils/session.py", line 97, in wrapper
    return func(*args, session=session, **kwargs)
           ^^^^^^^^^^^^^^^^^^^^^^^^^^^^^^^^^^^^^^
  File "/home/airflow/.local/lib/python3.12/site-packages/airflow/models/taskinstance.py", line 3004, in _run_raw_task
    return _run_raw_task(
           ^^^^^^^^^^^^^^
  File "/home/airflow/.local/lib/python3.12/site-packages/airflow/models/taskinstance.py", line 273, in _run_raw_task
    TaskInstance._execute_task_with_callbacks(
  File "/home/airflow/.local/lib/python3.12/site-packages/airflow/models/taskinstance.py", line 3158, in _execute_task_with_callbacks
    result = self._execute_task(context, task_orig)
             ^^^^^^^^^^^^^^^^^^^^^^^^^^^^^^^^^^^^^^
  File "/home/airflow/.local/lib/python3.12/site-packages/airflow/models/taskinstance.py", line 3182, in _execute_task
    return _execute_task(self, context, task_orig)
           ^^^^^^^^^^^^^^^^^^^^^^^^^^^^^^^^^^^^^^^
  File "/home/airflow/.local/lib/python3.12/site-packages/airflow/models/taskinstance.py", line 767, in _execute_task
    result = _execute_callable(context=context, **execute_callable_kwargs)
             ^^^^^^^^^^^^^^^^^^^^^^^^^^^^^^^^^^^^^^^^^^^^^^^^^^^^^^^^^^^^^
  File "/home/airflow/.local/lib/python3.12/site-packages/airflow/models/taskinstance.py", line 733, in _execute_callable
    return ExecutionCallableRunner(
           ^^^^^^^^^^^^^^^^^^^^^^^^
  File "/home/airflow/.local/lib/python3.12/site-packages/airflow/utils/operator_helpers.py", line 252, in run
    return self.func(*args, **kwargs)
           ^^^^^^^^^^^^^^^^^^^^^^^^^^
  File "/home/airflow/.local/lib/python3.12/site-packages/airflow/models/baseoperator.py", line 406, in wrapper
    return func(self, *args, **kwargs)
           ^^^^^^^^^^^^^^^^^^^^^^^^^^^
  File "/home/airflow/.local/lib/python3.12/site-packages/airflow/operators/bash.py", line 249, in execute
    raise AirflowException(
airflow.exceptions.AirflowException: Bash command failed. The command returned a non-zero exit code 127.
[2024-11-05T13:47:50.566+0000] {local_task_job_runner.py:266} INFO - Task exited with return code 1
[2024-11-05T13:47:50.586+0000] {taskinstance.py:3900} INFO - 0 downstream tasks scheduled from follow-on schedule check
[2024-11-05T13:47:50.591+0000] {local_task_job_runner.py:245} INFO - ::endgroup::
