[2024-11-05T19:10:53.810+0000] {local_task_job_runner.py:123} INFO - ::group::Pre task execution logs
[2024-11-05T19:10:53.871+0000] {taskinstance.py:2612} INFO - Dependencies all met for dep_context=non-requeueable deps ti=<TaskInstance: data_quality_dag.run_great_expectations manual__2024-11-05T19:10:49.048810+00:00 [queued]>
[2024-11-05T19:10:53.897+0000] {taskinstance.py:2612} INFO - Dependencies all met for dep_context=requeueable deps ti=<TaskInstance: data_quality_dag.run_great_expectations manual__2024-11-05T19:10:49.048810+00:00 [queued]>
[2024-11-05T19:10:53.897+0000] {taskinstance.py:2865} INFO - Starting attempt 1 of 2
[2024-11-05T19:10:53.932+0000] {taskinstance.py:2888} INFO - Executing <Task(BashOperator): run_great_expectations> on 2024-11-05 19:10:49.048810+00:00
[2024-11-05T19:10:53.945+0000] {standard_task_runner.py:104} INFO - Running: ['***', 'tasks', 'run', 'data_quality_dag', 'run_great_expectations', 'manual__2024-11-05T19:10:49.048810+00:00', '--job-id', '134', '--raw', '--subdir', 'DAGS_FOLDER/data_quality_dag.py', '--cfg-path', '/tmp/tmpikkxmfxt']
[2024-11-05T19:10:53.943+0000] {warnings.py:112} WARNING - /home/***/.local/lib/python3.12/site-packages/***/task/task_runner/standard_task_runner.py:70: DeprecationWarning: This process (pid=594) is multi-threaded, use of fork() may lead to deadlocks in the child.
  pid = os.fork()

[2024-11-05T19:10:53.947+0000] {standard_task_runner.py:105} INFO - Job 134: Subtask run_great_expectations
[2024-11-05T19:10:53.947+0000] {standard_task_runner.py:72} INFO - Started process 597 to run task
[2024-11-05T19:10:54.032+0000] {task_command.py:467} INFO - Running <TaskInstance: data_quality_dag.run_great_expectations manual__2024-11-05T19:10:49.048810+00:00 [running]> on host 5183c4c0ec1d
[2024-11-05T19:10:54.184+0000] {taskinstance.py:3131} INFO - Exporting env vars: AIRFLOW_CTX_DAG_OWNER='***' AIRFLOW_CTX_DAG_ID='data_quality_dag' AIRFLOW_CTX_TASK_ID='run_great_expectations' AIRFLOW_CTX_EXECUTION_DATE='2024-11-05T19:10:49.048810+00:00' AIRFLOW_CTX_TRY_NUMBER='1' AIRFLOW_CTX_DAG_RUN_ID='manual__2024-11-05T19:10:49.048810+00:00'
[2024-11-05T19:10:54.185+0000] {taskinstance.py:731} INFO - ::endgroup::
[2024-11-05T19:10:54.351+0000] {subprocess.py:63} INFO - Tmp dir root location: /tmp
[2024-11-05T19:10:54.355+0000] {subprocess.py:75} INFO - Running command: ['/usr/bin/bash', '-c', 'great_expectations checkpoint run my_checkpoint']
[2024-11-05T19:10:54.373+0000] {subprocess.py:86} INFO - Output:
[2024-11-05T19:11:01.789+0000] {subprocess.py:93} INFO - /home/***/.local/lib/python3.12/site-packages/sqlalchemy_redshift/commands.py:31: SyntaxWarning: invalid escape sequence '\-'
[2024-11-05T19:11:01.790+0000] {subprocess.py:93} INFO -   IAM_ROLE_NAME_RE = re.compile('[A-Za-z0-9+=,.@\-_]{1,64}')  # noqa
[2024-11-05T19:11:01.791+0000] {subprocess.py:93} INFO - /home/***/.local/lib/python3.12/site-packages/sqlalchemy_redshift/commands.py:33: SyntaxWarning: invalid escape sequence '\-'
[2024-11-05T19:11:01.791+0000] {subprocess.py:93} INFO -   '[0-9]{12}:role/[A-Za-z0-9+=,.@\-_]{1,64}')  # noqa
[2024-11-05T19:11:09.771+0000] {subprocess.py:93} INFO - Error: No gx directory was found here!
[2024-11-05T19:11:09.771+0000] {subprocess.py:93} INFO -     - Please check that you are in the correct directory or have specified the correct directory.
[2024-11-05T19:11:09.772+0000] {subprocess.py:93} INFO -     - If you have never run Great Expectations in this project, please run `great_expectations init` to get started.
[2024-11-05T19:11:09.774+0000] {subprocess.py:93} INFO - 
[2024-11-05T19:11:11.416+0000] {subprocess.py:97} INFO - Command exited with return code 1
[2024-11-05T19:11:11.447+0000] {taskinstance.py:3310} ERROR - Task failed with exception
Traceback (most recent call last):
  File "/home/airflow/.local/lib/python3.12/site-packages/airflow/models/taskinstance.py", line 767, in _execute_task
    result = _execute_callable(context=context, **execute_callable_kwargs)
             ^^^^^^^^^^^^^^^^^^^^^^^^^^^^^^^^^^^^^^^^^^^^^^^^^^^^^^^^^^^^^
  File "/home/airflow/.local/lib/python3.12/site-packages/airflow/models/taskinstance.py", line 733, in _execute_callable
    return ExecutionCallableRunner(
           ^^^^^^^^^^^^^^^^^^^^^^^^
  File "/home/airflow/.local/lib/python3.12/site-packages/airflow/utils/operator_helpers.py", line 252, in run
    return self.func(*args, **kwargs)
           ^^^^^^^^^^^^^^^^^^^^^^^^^^
  File "/home/airflow/.local/lib/python3.12/site-packages/airflow/models/baseoperator.py", line 406, in wrapper
    return func(self, *args, **kwargs)
           ^^^^^^^^^^^^^^^^^^^^^^^^^^^
  File "/home/airflow/.local/lib/python3.12/site-packages/airflow/operators/bash.py", line 249, in execute
    raise AirflowException(
airflow.exceptions.AirflowException: Bash command failed. The command returned a non-zero exit code 1.
[2024-11-05T19:11:11.495+0000] {taskinstance.py:1225} INFO - Marking task as UP_FOR_RETRY. dag_id=data_quality_dag, task_id=run_great_expectations, run_id=manual__2024-11-05T19:10:49.048810+00:00, execution_date=20241105T191049, start_date=20241105T191053, end_date=20241105T191111
[2024-11-05T19:11:11.535+0000] {taskinstance.py:340} INFO - ::group::Post task execution logs
[2024-11-05T19:11:11.536+0000] {standard_task_runner.py:124} ERROR - Failed to execute job 134 for task run_great_expectations (Bash command failed. The command returned a non-zero exit code 1.; 597)
Traceback (most recent call last):
  File "/home/airflow/.local/lib/python3.12/site-packages/airflow/task/task_runner/standard_task_runner.py", line 117, in _start_by_fork
    ret = args.func(args, dag=self.dag)
          ^^^^^^^^^^^^^^^^^^^^^^^^^^^^^
  File "/home/airflow/.local/lib/python3.12/site-packages/airflow/cli/cli_config.py", line 49, in command
    return func(*args, **kwargs)
           ^^^^^^^^^^^^^^^^^^^^^
  File "/home/airflow/.local/lib/python3.12/site-packages/airflow/utils/cli.py", line 115, in wrapper
    return f(*args, **kwargs)
           ^^^^^^^^^^^^^^^^^^
  File "/home/airflow/.local/lib/python3.12/site-packages/airflow/cli/commands/task_command.py", line 483, in task_run
    task_return_code = _run_task_by_selected_method(args, _dag, ti)
                       ^^^^^^^^^^^^^^^^^^^^^^^^^^^^^^^^^^^^^^^^^^^^
  File "/home/airflow/.local/lib/python3.12/site-packages/airflow/cli/commands/task_command.py", line 256, in _run_task_by_selected_method
    return _run_raw_task(args, ti)
           ^^^^^^^^^^^^^^^^^^^^^^^
  File "/home/airflow/.local/lib/python3.12/site-packages/airflow/cli/commands/task_command.py", line 341, in _run_raw_task
    return ti._run_raw_task(
           ^^^^^^^^^^^^^^^^^
  File "/home/airflow/.local/lib/python3.12/site-packages/airflow/utils/session.py", line 97, in wrapper
    return func(*args, session=session, **kwargs)
           ^^^^^^^^^^^^^^^^^^^^^^^^^^^^^^^^^^^^^^
  File "/home/airflow/.local/lib/python3.12/site-packages/airflow/models/taskinstance.py", line 3004, in _run_raw_task
    return _run_raw_task(
           ^^^^^^^^^^^^^^
  File "/home/airflow/.local/lib/python3.12/site-packages/airflow/models/taskinstance.py", line 273, in _run_raw_task
    TaskInstance._execute_task_with_callbacks(
  File "/home/airflow/.local/lib/python3.12/site-packages/airflow/models/taskinstance.py", line 3158, in _execute_task_with_callbacks
    result = self._execute_task(context, task_orig)
             ^^^^^^^^^^^^^^^^^^^^^^^^^^^^^^^^^^^^^^
  File "/home/airflow/.local/lib/python3.12/site-packages/airflow/models/taskinstance.py", line 3182, in _execute_task
    return _execute_task(self, context, task_orig)
           ^^^^^^^^^^^^^^^^^^^^^^^^^^^^^^^^^^^^^^^
  File "/home/airflow/.local/lib/python3.12/site-packages/airflow/models/taskinstance.py", line 767, in _execute_task
    result = _execute_callable(context=context, **execute_callable_kwargs)
             ^^^^^^^^^^^^^^^^^^^^^^^^^^^^^^^^^^^^^^^^^^^^^^^^^^^^^^^^^^^^^
  File "/home/airflow/.local/lib/python3.12/site-packages/airflow/models/taskinstance.py", line 733, in _execute_callable
    return ExecutionCallableRunner(
           ^^^^^^^^^^^^^^^^^^^^^^^^
  File "/home/airflow/.local/lib/python3.12/site-packages/airflow/utils/operator_helpers.py", line 252, in run
    return self.func(*args, **kwargs)
           ^^^^^^^^^^^^^^^^^^^^^^^^^^
  File "/home/airflow/.local/lib/python3.12/site-packages/airflow/models/baseoperator.py", line 406, in wrapper
    return func(self, *args, **kwargs)
           ^^^^^^^^^^^^^^^^^^^^^^^^^^^
  File "/home/airflow/.local/lib/python3.12/site-packages/airflow/operators/bash.py", line 249, in execute
    raise AirflowException(
airflow.exceptions.AirflowException: Bash command failed. The command returned a non-zero exit code 1.
[2024-11-05T19:11:11.592+0000] {local_task_job_runner.py:266} INFO - Task exited with return code 1
[2024-11-05T19:11:11.629+0000] {taskinstance.py:3900} INFO - 0 downstream tasks scheduled from follow-on schedule check
[2024-11-05T19:11:11.631+0000] {local_task_job_runner.py:245} INFO - ::endgroup::
