[2024-11-05T12:59:07.740+0000] {local_task_job_runner.py:123} INFO - ::group::Pre task execution logs
[2024-11-05T12:59:07.885+0000] {taskinstance.py:2612} INFO - Dependencies all met for dep_context=non-requeueable deps ti=<TaskInstance: dbt_workflow_orchestration.transform.production.seed.adventureworks.productcategory scheduled__2024-11-04T00:00:00+00:00 [queued]>
[2024-11-05T12:59:07.956+0000] {taskinstance.py:2612} INFO - Dependencies all met for dep_context=requeueable deps ti=<TaskInstance: dbt_workflow_orchestration.transform.production.seed.adventureworks.productcategory scheduled__2024-11-04T00:00:00+00:00 [queued]>
[2024-11-05T12:59:07.957+0000] {taskinstance.py:2865} INFO - Starting attempt 2 of 2
[2024-11-05T12:59:08.123+0000] {taskinstance.py:2888} INFO - Executing <Task(DbtSeedBashOperator): transform.production.seed.adventureworks.productcategory> on 2024-11-04 00:00:00+00:00
[2024-11-05T12:59:08.140+0000] {warnings.py:112} WARNING - /home/***/.local/lib/python3.12/site-packages/***/task/task_runner/standard_task_runner.py:70: DeprecationWarning: This process (pid=459) is multi-threaded, use of fork() may lead to deadlocks in the child.
  pid = os.fork()

[2024-11-05T12:59:08.149+0000] {standard_task_runner.py:72} INFO - Started process 488 to run task
[2024-11-05T12:59:08.173+0000] {standard_task_runner.py:104} INFO - Running: ['***', 'tasks', 'run', 'dbt_workflow_orchestration', 'transform.production.seed.adventureworks.productcategory', 'scheduled__2024-11-04T00:00:00+00:00', '--job-id', '56', '--raw', '--subdir', 'DAGS_FOLDER/dbt_orchestration.py', '--cfg-path', '/tmp/tmpx0a6q0u6']
[2024-11-05T12:59:08.181+0000] {standard_task_runner.py:105} INFO - Job 56: Subtask transform.production.seed.adventureworks.productcategory
[2024-11-05T12:59:08.557+0000] {task_command.py:467} INFO - Running <TaskInstance: dbt_workflow_orchestration.transform.production.seed.adventureworks.productcategory scheduled__2024-11-04T00:00:00+00:00 [running]> on host e36b82c08833
[2024-11-05T12:59:09.178+0000] {taskinstance.py:3131} INFO - Exporting env vars: AIRFLOW_CTX_DAG_OWNER='***' AIRFLOW_CTX_DAG_ID='dbt_workflow_orchestration' AIRFLOW_CTX_TASK_ID='transform.production.seed.adventureworks.productcategory' AIRFLOW_CTX_EXECUTION_DATE='2024-11-04T00:00:00+00:00' AIRFLOW_CTX_TRY_NUMBER='2' AIRFLOW_CTX_DAG_RUN_ID='scheduled__2024-11-04T00:00:00+00:00'
[2024-11-05T12:59:09.184+0000] {taskinstance.py:731} INFO - ::endgroup::
[2024-11-05T12:59:12.815+0000] {subprocess.py:63} INFO - Tmp dir root location: /tmp
[2024-11-05T12:59:12.816+0000] {subprocess.py:75} INFO - Running command: ['/usr/bin/bash', '-c', 'dbt --no-write-json seed --project-dir /opt/dbt --profiles-dir /opt/dbt --target dev --select productcategory']
[2024-11-05T12:59:12.874+0000] {subprocess.py:86} INFO - Output:
[2024-11-05T12:59:31.502+0000] {subprocess.py:93} INFO - [0m12:59:31  Running with dbt=1.8.2
[2024-11-05T12:59:31.507+0000] {subprocess.py:93} INFO - [0m12:59:31  Encountered an error:
[2024-11-05T12:59:31.507+0000] {subprocess.py:93} INFO - Runtime Error
[2024-11-05T12:59:31.508+0000] {subprocess.py:93} INFO -   The profile 'adventureworks' does not have a target named 'dev'. The valid target names for this profile are:
[2024-11-05T12:59:31.508+0000] {subprocess.py:93} INFO -    - postgres
[2024-11-05T12:59:34.377+0000] {subprocess.py:97} INFO - Command exited with return code 2
[2024-11-05T12:59:34.464+0000] {taskinstance.py:3310} ERROR - Task failed with exception
Traceback (most recent call last):
  File "/home/airflow/.local/lib/python3.12/site-packages/airflow/models/taskinstance.py", line 767, in _execute_task
    result = _execute_callable(context=context, **execute_callable_kwargs)
             ^^^^^^^^^^^^^^^^^^^^^^^^^^^^^^^^^^^^^^^^^^^^^^^^^^^^^^^^^^^^^
  File "/home/airflow/.local/lib/python3.12/site-packages/airflow/models/taskinstance.py", line 733, in _execute_callable
    return ExecutionCallableRunner(
           ^^^^^^^^^^^^^^^^^^^^^^^^
  File "/home/airflow/.local/lib/python3.12/site-packages/airflow/utils/operator_helpers.py", line 252, in run
    return self.func(*args, **kwargs)
           ^^^^^^^^^^^^^^^^^^^^^^^^^^
  File "/home/airflow/.local/lib/python3.12/site-packages/airflow/models/baseoperator.py", line 406, in wrapper
    return func(self, *args, **kwargs)
           ^^^^^^^^^^^^^^^^^^^^^^^^^^^
  File "/home/airflow/.local/lib/python3.12/site-packages/airflow/operators/bash.py", line 249, in execute
    raise AirflowException(
airflow.exceptions.AirflowException: Bash command failed. The command returned a non-zero exit code 2.
[2024-11-05T12:59:34.525+0000] {taskinstance.py:1225} INFO - Marking task as FAILED. dag_id=dbt_workflow_orchestration, task_id=transform.production.seed.adventureworks.productcategory, run_id=scheduled__2024-11-04T00:00:00+00:00, execution_date=20241104T000000, start_date=20241105T125907, end_date=20241105T125934
[2024-11-05T12:59:34.735+0000] {taskinstance.py:340} INFO - ::group::Post task execution logs
[2024-11-05T12:59:34.752+0000] {standard_task_runner.py:124} ERROR - Failed to execute job 56 for task transform.production.seed.adventureworks.productcategory (Bash command failed. The command returned a non-zero exit code 2.; 488)
Traceback (most recent call last):
  File "/home/airflow/.local/lib/python3.12/site-packages/airflow/task/task_runner/standard_task_runner.py", line 117, in _start_by_fork
    ret = args.func(args, dag=self.dag)
          ^^^^^^^^^^^^^^^^^^^^^^^^^^^^^
  File "/home/airflow/.local/lib/python3.12/site-packages/airflow/cli/cli_config.py", line 49, in command
    return func(*args, **kwargs)
           ^^^^^^^^^^^^^^^^^^^^^
  File "/home/airflow/.local/lib/python3.12/site-packages/airflow/utils/cli.py", line 115, in wrapper
    return f(*args, **kwargs)
           ^^^^^^^^^^^^^^^^^^
  File "/home/airflow/.local/lib/python3.12/site-packages/airflow/cli/commands/task_command.py", line 483, in task_run
    task_return_code = _run_task_by_selected_method(args, _dag, ti)
                       ^^^^^^^^^^^^^^^^^^^^^^^^^^^^^^^^^^^^^^^^^^^^
  File "/home/airflow/.local/lib/python3.12/site-packages/airflow/cli/commands/task_command.py", line 256, in _run_task_by_selected_method
    return _run_raw_task(args, ti)
           ^^^^^^^^^^^^^^^^^^^^^^^
  File "/home/airflow/.local/lib/python3.12/site-packages/airflow/cli/commands/task_command.py", line 341, in _run_raw_task
    return ti._run_raw_task(
           ^^^^^^^^^^^^^^^^^
  File "/home/airflow/.local/lib/python3.12/site-packages/airflow/utils/session.py", line 97, in wrapper
    return func(*args, session=session, **kwargs)
           ^^^^^^^^^^^^^^^^^^^^^^^^^^^^^^^^^^^^^^
  File "/home/airflow/.local/lib/python3.12/site-packages/airflow/models/taskinstance.py", line 3004, in _run_raw_task
    return _run_raw_task(
           ^^^^^^^^^^^^^^
  File "/home/airflow/.local/lib/python3.12/site-packages/airflow/models/taskinstance.py", line 273, in _run_raw_task
    TaskInstance._execute_task_with_callbacks(
  File "/home/airflow/.local/lib/python3.12/site-packages/airflow/models/taskinstance.py", line 3158, in _execute_task_with_callbacks
    result = self._execute_task(context, task_orig)
             ^^^^^^^^^^^^^^^^^^^^^^^^^^^^^^^^^^^^^^
  File "/home/airflow/.local/lib/python3.12/site-packages/airflow/models/taskinstance.py", line 3182, in _execute_task
    return _execute_task(self, context, task_orig)
           ^^^^^^^^^^^^^^^^^^^^^^^^^^^^^^^^^^^^^^^
  File "/home/airflow/.local/lib/python3.12/site-packages/airflow/models/taskinstance.py", line 767, in _execute_task
    result = _execute_callable(context=context, **execute_callable_kwargs)
             ^^^^^^^^^^^^^^^^^^^^^^^^^^^^^^^^^^^^^^^^^^^^^^^^^^^^^^^^^^^^^
  File "/home/airflow/.local/lib/python3.12/site-packages/airflow/models/taskinstance.py", line 733, in _execute_callable
    return ExecutionCallableRunner(
           ^^^^^^^^^^^^^^^^^^^^^^^^
  File "/home/airflow/.local/lib/python3.12/site-packages/airflow/utils/operator_helpers.py", line 252, in run
    return self.func(*args, **kwargs)
           ^^^^^^^^^^^^^^^^^^^^^^^^^^
  File "/home/airflow/.local/lib/python3.12/site-packages/airflow/models/baseoperator.py", line 406, in wrapper
    return func(self, *args, **kwargs)
           ^^^^^^^^^^^^^^^^^^^^^^^^^^^
  File "/home/airflow/.local/lib/python3.12/site-packages/airflow/operators/bash.py", line 249, in execute
    raise AirflowException(
airflow.exceptions.AirflowException: Bash command failed. The command returned a non-zero exit code 2.
[2024-11-05T12:59:34.857+0000] {local_task_job_runner.py:266} INFO - Task exited with return code 1
[2024-11-05T12:59:35.230+0000] {taskinstance.py:3900} INFO - 0 downstream tasks scheduled from follow-on schedule check
[2024-11-05T12:59:35.244+0000] {local_task_job_runner.py:245} INFO - ::endgroup::
