[2024-11-05T16:15:10.943+0000] {local_task_job_runner.py:123} INFO - ::group::Pre task execution logs
[2024-11-05T16:15:10.965+0000] {taskinstance.py:2612} INFO - Dependencies all met for dep_context=non-requeueable deps ti=<TaskInstance: dbt_docs_serve_dag.dbt_docs_serve manual__2024-11-05T16:15:09.644321+00:00 [queued]>
[2024-11-05T16:15:10.977+0000] {taskinstance.py:2612} INFO - Dependencies all met for dep_context=requeueable deps ti=<TaskInstance: dbt_docs_serve_dag.dbt_docs_serve manual__2024-11-05T16:15:09.644321+00:00 [queued]>
[2024-11-05T16:15:10.978+0000] {taskinstance.py:2865} INFO - Starting attempt 1 of 2
[2024-11-05T16:15:10.996+0000] {taskinstance.py:2888} INFO - Executing <Task(BashOperator): dbt_docs_serve> on 2024-11-05 16:15:09.644321+00:00
[2024-11-05T16:15:11.005+0000] {warnings.py:112} WARNING - /home/***/.local/lib/python3.12/site-packages/***/task/task_runner/standard_task_runner.py:70: DeprecationWarning: This process (pid=98) is multi-threaded, use of fork() may lead to deadlocks in the child.
  pid = os.fork()

[2024-11-05T16:15:11.007+0000] {standard_task_runner.py:72} INFO - Started process 99 to run task
[2024-11-05T16:15:11.008+0000] {standard_task_runner.py:104} INFO - Running: ['***', 'tasks', 'run', 'dbt_docs_serve_dag', 'dbt_docs_serve', 'manual__2024-11-05T16:15:09.644321+00:00', '--job-id', '124', '--raw', '--subdir', 'DAGS_FOLDER/dbt_docs_serve_dag.py', '--cfg-path', '/tmp/tmp0y76jxaq']
[2024-11-05T16:15:11.009+0000] {standard_task_runner.py:105} INFO - Job 124: Subtask dbt_docs_serve
[2024-11-05T16:15:11.071+0000] {task_command.py:467} INFO - Running <TaskInstance: dbt_docs_serve_dag.dbt_docs_serve manual__2024-11-05T16:15:09.644321+00:00 [running]> on host 97a2f369554a
[2024-11-05T16:15:11.194+0000] {taskinstance.py:3131} INFO - Exporting env vars: AIRFLOW_CTX_DAG_OWNER='***' AIRFLOW_CTX_DAG_ID='dbt_docs_serve_dag' AIRFLOW_CTX_TASK_ID='dbt_docs_serve' AIRFLOW_CTX_EXECUTION_DATE='2024-11-05T16:15:09.644321+00:00' AIRFLOW_CTX_TRY_NUMBER='1' AIRFLOW_CTX_DAG_RUN_ID='manual__2024-11-05T16:15:09.644321+00:00'
[2024-11-05T16:15:11.195+0000] {taskinstance.py:731} INFO - ::endgroup::
[2024-11-05T16:15:11.215+0000] {subprocess.py:63} INFO - Tmp dir root location: /tmp
[2024-11-05T16:15:11.216+0000] {subprocess.py:75} INFO - Running command: ['/usr/bin/bash', '-c', 'cd /opt/dbt && nohup dbt docs serve --port 8001 --host 0.0.0.0 &']
[2024-11-05T16:15:11.230+0000] {subprocess.py:86} INFO - Output:
[2024-11-05T16:15:14.586+0000] {subprocess.py:93} INFO - [0m16:15:14  Running with dbt=1.8.2
[2024-11-05T16:15:15.144+0000] {subprocess.py:93} INFO - Serving docs at 8001
[2024-11-05T16:15:15.145+0000] {subprocess.py:93} INFO - To access from your browser, navigate to: http://localhost:8001
[2024-11-05T16:15:15.146+0000] {subprocess.py:93} INFO - 
[2024-11-05T16:15:15.146+0000] {subprocess.py:93} INFO - 
[2024-11-05T16:15:15.147+0000] {subprocess.py:93} INFO - 
[2024-11-05T16:15:15.147+0000] {subprocess.py:93} INFO - Press Ctrl+C to exit.
[2024-11-05T16:18:02.860+0000] {local_task_job_runner.py:346} WARNING - State of this instance has been externally set to None. Terminating instance.
[2024-11-05T16:18:02.860+0000] {local_task_job_runner.py:245} INFO - ::endgroup::
[2024-11-05T16:18:02.863+0000] {process_utils.py:132} INFO - Sending 15 to group 99. PIDs of all processes in the group: [101, 99]
[2024-11-05T16:18:02.864+0000] {process_utils.py:87} INFO - Sending the signal 15 to group 99
[2024-11-05T16:18:02.865+0000] {taskinstance.py:3092} ERROR - Received SIGTERM. Terminating subprocesses.
[2024-11-05T16:18:02.866+0000] {subprocess.py:104} INFO - Sending SIGTERM signal to process group
[2024-11-05T16:18:02.880+0000] {taskinstance.py:3310} ERROR - Task failed with exception
Traceback (most recent call last):
  File "/home/airflow/.local/lib/python3.12/site-packages/airflow/models/taskinstance.py", line 767, in _execute_task
    result = _execute_callable(context=context, **execute_callable_kwargs)
             ^^^^^^^^^^^^^^^^^^^^^^^^^^^^^^^^^^^^^^^^^^^^^^^^^^^^^^^^^^^^^
  File "/home/airflow/.local/lib/python3.12/site-packages/airflow/models/taskinstance.py", line 733, in _execute_callable
    return ExecutionCallableRunner(
           ^^^^^^^^^^^^^^^^^^^^^^^^
  File "/home/airflow/.local/lib/python3.12/site-packages/airflow/utils/operator_helpers.py", line 252, in run
    return self.func(*args, **kwargs)
           ^^^^^^^^^^^^^^^^^^^^^^^^^^
  File "/home/airflow/.local/lib/python3.12/site-packages/airflow/models/baseoperator.py", line 406, in wrapper
    return func(self, *args, **kwargs)
           ^^^^^^^^^^^^^^^^^^^^^^^^^^^
  File "/home/airflow/.local/lib/python3.12/site-packages/airflow/operators/bash.py", line 240, in execute
    result = self.subprocess_hook.run_command(
             ^^^^^^^^^^^^^^^^^^^^^^^^^^^^^^^^^
  File "/home/airflow/.local/lib/python3.12/site-packages/airflow/hooks/subprocess.py", line 91, in run_command
    for raw_line in iter(self.sub_process.stdout.readline, b""):
                    ^^^^^^^^^^^^^^^^^^^^^^^^^^^^^^^^^^^^^^^^^^^
  File "/home/airflow/.local/lib/python3.12/site-packages/airflow/models/taskinstance.py", line 3094, in signal_handler
    raise AirflowTaskTerminated("Task received SIGTERM signal")
airflow.exceptions.AirflowTaskTerminated: Task received SIGTERM signal
[2024-11-05T16:18:02.890+0000] {taskinstance.py:1225} INFO - Marking task as UP_FOR_RETRY. dag_id=dbt_docs_serve_dag, task_id=dbt_docs_serve, run_id=manual__2024-11-05T16:15:09.644321+00:00, execution_date=20241105T161509, start_date=20241105T161510, end_date=20241105T161802
[2024-11-05T16:18:02.909+0000] {taskinstance.py:340} INFO - ::group::Post task execution logs
[2024-11-05T16:18:02.910+0000] {standard_task_runner.py:124} ERROR - Failed to execute job 124 for task dbt_docs_serve ((psycopg2.errors.ForeignKeyViolation) insert or update on table "task_fail" violates foreign key constraint "task_fail_ti_fkey"
DETAIL:  Key (dag_id, task_id, run_id, map_index)=(dbt_docs_serve_dag, dbt_docs_serve, manual__2024-11-05T16:15:09.644321+00:00, -1) is not present in table "task_instance".

[SQL: INSERT INTO task_fail (task_id, dag_id, run_id, map_index, start_date, end_date, duration) VALUES (%(task_id)s, %(dag_id)s, %(run_id)s, %(map_index)s, %(start_date)s, %(end_date)s, %(duration)s) RETURNING task_fail.id]
[parameters: {'task_id': 'dbt_docs_serve', 'dag_id': 'dbt_docs_serve_dag', 'run_id': 'manual__2024-11-05T16:15:09.644321+00:00', 'map_index': -1, 'start_date': datetime.datetime(2024, 11, 5, 16, 15, 10, 965960, tzinfo=Timezone('UTC')), 'end_date': datetime.datetime(2024, 11, 5, 16, 18, 2, 889513, tzinfo=Timezone('UTC')), 'duration': 171}]
(Background on this error at: https://sqlalche.me/e/14/gkpj); 99)
Traceback (most recent call last):
  File "/home/airflow/.local/lib/python3.12/site-packages/airflow/models/taskinstance.py", line 273, in _run_raw_task
    TaskInstance._execute_task_with_callbacks(
  File "/home/airflow/.local/lib/python3.12/site-packages/airflow/models/taskinstance.py", line 3158, in _execute_task_with_callbacks
    result = self._execute_task(context, task_orig)
             ^^^^^^^^^^^^^^^^^^^^^^^^^^^^^^^^^^^^^^
  File "/home/airflow/.local/lib/python3.12/site-packages/airflow/models/taskinstance.py", line 3182, in _execute_task
    return _execute_task(self, context, task_orig)
           ^^^^^^^^^^^^^^^^^^^^^^^^^^^^^^^^^^^^^^^
  File "/home/airflow/.local/lib/python3.12/site-packages/airflow/models/taskinstance.py", line 767, in _execute_task
    result = _execute_callable(context=context, **execute_callable_kwargs)
             ^^^^^^^^^^^^^^^^^^^^^^^^^^^^^^^^^^^^^^^^^^^^^^^^^^^^^^^^^^^^^
  File "/home/airflow/.local/lib/python3.12/site-packages/airflow/models/taskinstance.py", line 733, in _execute_callable
    return ExecutionCallableRunner(
           ^^^^^^^^^^^^^^^^^^^^^^^^
  File "/home/airflow/.local/lib/python3.12/site-packages/airflow/utils/operator_helpers.py", line 252, in run
    return self.func(*args, **kwargs)
           ^^^^^^^^^^^^^^^^^^^^^^^^^^
  File "/home/airflow/.local/lib/python3.12/site-packages/airflow/models/baseoperator.py", line 406, in wrapper
    return func(self, *args, **kwargs)
           ^^^^^^^^^^^^^^^^^^^^^^^^^^^
  File "/home/airflow/.local/lib/python3.12/site-packages/airflow/operators/bash.py", line 240, in execute
    result = self.subprocess_hook.run_command(
             ^^^^^^^^^^^^^^^^^^^^^^^^^^^^^^^^^
  File "/home/airflow/.local/lib/python3.12/site-packages/airflow/hooks/subprocess.py", line 91, in run_command
    for raw_line in iter(self.sub_process.stdout.readline, b""):
                    ^^^^^^^^^^^^^^^^^^^^^^^^^^^^^^^^^^^^^^^^^^^
  File "/home/airflow/.local/lib/python3.12/site-packages/airflow/models/taskinstance.py", line 3094, in signal_handler
    raise AirflowTaskTerminated("Task received SIGTERM signal")
airflow.exceptions.AirflowTaskTerminated: Task received SIGTERM signal

During handling of the above exception, another exception occurred:

Traceback (most recent call last):
  File "/home/airflow/.local/lib/python3.12/site-packages/sqlalchemy/engine/base.py", line 1910, in _execute_context
    self.dialect.do_execute(
  File "/home/airflow/.local/lib/python3.12/site-packages/sqlalchemy/engine/default.py", line 736, in do_execute
    cursor.execute(statement, parameters)
psycopg2.errors.ForeignKeyViolation: insert or update on table "task_fail" violates foreign key constraint "task_fail_ti_fkey"
DETAIL:  Key (dag_id, task_id, run_id, map_index)=(dbt_docs_serve_dag, dbt_docs_serve, manual__2024-11-05T16:15:09.644321+00:00, -1) is not present in table "task_instance".


The above exception was the direct cause of the following exception:

Traceback (most recent call last):
  File "/home/airflow/.local/lib/python3.12/site-packages/airflow/task/task_runner/standard_task_runner.py", line 117, in _start_by_fork
    ret = args.func(args, dag=self.dag)
          ^^^^^^^^^^^^^^^^^^^^^^^^^^^^^
  File "/home/airflow/.local/lib/python3.12/site-packages/airflow/cli/cli_config.py", line 49, in command
    return func(*args, **kwargs)
           ^^^^^^^^^^^^^^^^^^^^^
  File "/home/airflow/.local/lib/python3.12/site-packages/airflow/utils/cli.py", line 115, in wrapper
    return f(*args, **kwargs)
           ^^^^^^^^^^^^^^^^^^
  File "/home/airflow/.local/lib/python3.12/site-packages/airflow/cli/commands/task_command.py", line 483, in task_run
    task_return_code = _run_task_by_selected_method(args, _dag, ti)
                       ^^^^^^^^^^^^^^^^^^^^^^^^^^^^^^^^^^^^^^^^^^^^
  File "/home/airflow/.local/lib/python3.12/site-packages/airflow/cli/commands/task_command.py", line 256, in _run_task_by_selected_method
    return _run_raw_task(args, ti)
           ^^^^^^^^^^^^^^^^^^^^^^^
  File "/home/airflow/.local/lib/python3.12/site-packages/airflow/cli/commands/task_command.py", line 341, in _run_raw_task
    return ti._run_raw_task(
           ^^^^^^^^^^^^^^^^^
  File "/home/airflow/.local/lib/python3.12/site-packages/airflow/utils/session.py", line 97, in wrapper
    return func(*args, session=session, **kwargs)
           ^^^^^^^^^^^^^^^^^^^^^^^^^^^^^^^^^^^^^^
  File "/home/airflow/.local/lib/python3.12/site-packages/airflow/models/taskinstance.py", line 3004, in _run_raw_task
    return _run_raw_task(
           ^^^^^^^^^^^^^^
  File "/home/airflow/.local/lib/python3.12/site-packages/airflow/models/taskinstance.py", line 327, in _run_raw_task
    ti.handle_failure(e, test_mode, context, session=session)
  File "/home/airflow/.local/lib/python3.12/site-packages/airflow/utils/session.py", line 94, in wrapper
    return func(*args, **kwargs)
           ^^^^^^^^^^^^^^^^^^^^^
  File "/home/airflow/.local/lib/python3.12/site-packages/airflow/models/taskinstance.py", line 3427, in handle_failure
    _handle_failure(
  File "/home/airflow/.local/lib/python3.12/site-packages/airflow/utils/session.py", line 94, in wrapper
    return func(*args, **kwargs)
           ^^^^^^^^^^^^^^^^^^^^^
  File "/home/airflow/.local/lib/python3.12/site-packages/airflow/api_internal/internal_api_call.py", line 139, in wrapper
    return func(*args, **kwargs)
           ^^^^^^^^^^^^^^^^^^^^^
  File "/home/airflow/.local/lib/python3.12/site-packages/airflow/models/taskinstance.py", line 1243, in _handle_failure
    TaskInstance.save_to_db(failure_context["ti"], session)
  File "/home/airflow/.local/lib/python3.12/site-packages/airflow/api_internal/internal_api_call.py", line 139, in wrapper
    return func(*args, **kwargs)
           ^^^^^^^^^^^^^^^^^^^^^
  File "/home/airflow/.local/lib/python3.12/site-packages/airflow/utils/session.py", line 94, in wrapper
    return func(*args, **kwargs)
           ^^^^^^^^^^^^^^^^^^^^^
  File "/home/airflow/.local/lib/python3.12/site-packages/airflow/models/taskinstance.py", line 3399, in save_to_db
    session.flush()
  File "/home/airflow/.local/lib/python3.12/site-packages/sqlalchemy/orm/session.py", line 3449, in flush
    self._flush(objects)
  File "/home/airflow/.local/lib/python3.12/site-packages/sqlalchemy/orm/session.py", line 3588, in _flush
    with util.safe_reraise():
         ^^^^^^^^^^^^^^^^^^^
  File "/home/airflow/.local/lib/python3.12/site-packages/sqlalchemy/util/langhelpers.py", line 70, in __exit__
    compat.raise_(
  File "/home/airflow/.local/lib/python3.12/site-packages/sqlalchemy/util/compat.py", line 211, in raise_
    raise exception
  File "/home/airflow/.local/lib/python3.12/site-packages/sqlalchemy/orm/session.py", line 3549, in _flush
    flush_context.execute()
  File "/home/airflow/.local/lib/python3.12/site-packages/sqlalchemy/orm/unitofwork.py", line 456, in execute
    rec.execute(self)
  File "/home/airflow/.local/lib/python3.12/site-packages/sqlalchemy/orm/unitofwork.py", line 630, in execute
    util.preloaded.orm_persistence.save_obj(
  File "/home/airflow/.local/lib/python3.12/site-packages/sqlalchemy/orm/persistence.py", line 245, in save_obj
    _emit_insert_statements(
  File "/home/airflow/.local/lib/python3.12/site-packages/sqlalchemy/orm/persistence.py", line 1238, in _emit_insert_statements
    result = connection._execute_20(
             ^^^^^^^^^^^^^^^^^^^^^^^
  File "/home/airflow/.local/lib/python3.12/site-packages/sqlalchemy/engine/base.py", line 1710, in _execute_20
    return meth(self, args_10style, kwargs_10style, execution_options)
           ^^^^^^^^^^^^^^^^^^^^^^^^^^^^^^^^^^^^^^^^^^^^^^^^^^^^^^^^^^^
  File "/home/airflow/.local/lib/python3.12/site-packages/sqlalchemy/sql/elements.py", line 334, in _execute_on_connection
    return connection._execute_clauseelement(
           ^^^^^^^^^^^^^^^^^^^^^^^^^^^^^^^^^^
  File "/home/airflow/.local/lib/python3.12/site-packages/sqlalchemy/engine/base.py", line 1577, in _execute_clauseelement
    ret = self._execute_context(
          ^^^^^^^^^^^^^^^^^^^^^^
  File "/home/airflow/.local/lib/python3.12/site-packages/sqlalchemy/engine/base.py", line 1953, in _execute_context
    self._handle_dbapi_exception(
  File "/home/airflow/.local/lib/python3.12/site-packages/sqlalchemy/engine/base.py", line 2134, in _handle_dbapi_exception
    util.raise_(
  File "/home/airflow/.local/lib/python3.12/site-packages/sqlalchemy/util/compat.py", line 211, in raise_
    raise exception
  File "/home/airflow/.local/lib/python3.12/site-packages/sqlalchemy/engine/base.py", line 1910, in _execute_context
    self.dialect.do_execute(
  File "/home/airflow/.local/lib/python3.12/site-packages/sqlalchemy/engine/default.py", line 736, in do_execute
    cursor.execute(statement, parameters)
sqlalchemy.exc.IntegrityError: (psycopg2.errors.ForeignKeyViolation) insert or update on table "task_fail" violates foreign key constraint "task_fail_ti_fkey"
DETAIL:  Key (dag_id, task_id, run_id, map_index)=(dbt_docs_serve_dag, dbt_docs_serve, manual__2024-11-05T16:15:09.644321+00:00, -1) is not present in table "task_instance".

[SQL: INSERT INTO task_fail (task_id, dag_id, run_id, map_index, start_date, end_date, duration) VALUES (%(task_id)s, %(dag_id)s, %(run_id)s, %(map_index)s, %(start_date)s, %(end_date)s, %(duration)s) RETURNING task_fail.id]
[parameters: {'task_id': 'dbt_docs_serve', 'dag_id': 'dbt_docs_serve_dag', 'run_id': 'manual__2024-11-05T16:15:09.644321+00:00', 'map_index': -1, 'start_date': datetime.datetime(2024, 11, 5, 16, 15, 10, 965960, tzinfo=Timezone('UTC')), 'end_date': datetime.datetime(2024, 11, 5, 16, 18, 2, 889513, tzinfo=Timezone('UTC')), 'duration': 171}]
(Background on this error at: https://sqlalche.me/e/14/gkpj)
[2024-11-05T16:18:02.957+0000] {process_utils.py:80} INFO - Process psutil.Process(pid=101, status='terminated', started='16:15:10') (101) terminated with exit code None
[2024-11-05T16:18:02.958+0000] {process_utils.py:80} INFO - Process psutil.Process(pid=99, status='terminated', exitcode=1, started='16:15:10') (99) terminated with exit code 1
