[2024-11-05T19:10:53.808+0000] {local_task_job_runner.py:123} INFO - ::group::Pre task execution logs
[2024-11-05T19:10:53.868+0000] {taskinstance.py:2612} INFO - Dependencies all met for dep_context=non-requeueable deps ti=<TaskInstance: data_quality_dag.run_great_expectations scheduled__2024-11-04T00:00:00+00:00 [queued]>
[2024-11-05T19:10:53.889+0000] {taskinstance.py:2612} INFO - Dependencies all met for dep_context=requeueable deps ti=<TaskInstance: data_quality_dag.run_great_expectations scheduled__2024-11-04T00:00:00+00:00 [queued]>
[2024-11-05T19:10:53.889+0000] {taskinstance.py:2865} INFO - Starting attempt 1 of 2
[2024-11-05T19:10:53.922+0000] {taskinstance.py:2888} INFO - Executing <Task(BashOperator): run_great_expectations> on 2024-11-04 00:00:00+00:00
[2024-11-05T19:10:53.933+0000] {warnings.py:112} WARNING - /home/***/.local/lib/python3.12/site-packages/***/task/task_runner/standard_task_runner.py:70: DeprecationWarning: This process (pid=595) is multi-threaded, use of fork() may lead to deadlocks in the child.
  pid = os.fork()

[2024-11-05T19:10:53.936+0000] {standard_task_runner.py:104} INFO - Running: ['***', 'tasks', 'run', 'data_quality_dag', 'run_great_expectations', 'scheduled__2024-11-04T00:00:00+00:00', '--job-id', '135', '--raw', '--subdir', 'DAGS_FOLDER/data_quality_dag.py', '--cfg-path', '/tmp/tmpq_gfc14b']
[2024-11-05T19:10:53.938+0000] {standard_task_runner.py:72} INFO - Started process 596 to run task
[2024-11-05T19:10:53.938+0000] {standard_task_runner.py:105} INFO - Job 135: Subtask run_great_expectations
[2024-11-05T19:10:54.024+0000] {task_command.py:467} INFO - Running <TaskInstance: data_quality_dag.run_great_expectations scheduled__2024-11-04T00:00:00+00:00 [running]> on host 5183c4c0ec1d
[2024-11-05T19:10:54.183+0000] {taskinstance.py:3131} INFO - Exporting env vars: AIRFLOW_CTX_DAG_OWNER='***' AIRFLOW_CTX_DAG_ID='data_quality_dag' AIRFLOW_CTX_TASK_ID='run_great_expectations' AIRFLOW_CTX_EXECUTION_DATE='2024-11-04T00:00:00+00:00' AIRFLOW_CTX_TRY_NUMBER='1' AIRFLOW_CTX_DAG_RUN_ID='scheduled__2024-11-04T00:00:00+00:00'
[2024-11-05T19:10:54.185+0000] {taskinstance.py:731} INFO - ::endgroup::
[2024-11-05T19:10:54.350+0000] {subprocess.py:63} INFO - Tmp dir root location: /tmp
[2024-11-05T19:10:54.354+0000] {subprocess.py:75} INFO - Running command: ['/usr/bin/bash', '-c', 'great_expectations checkpoint run my_checkpoint']
[2024-11-05T19:10:54.374+0000] {subprocess.py:86} INFO - Output:
[2024-11-05T19:11:01.791+0000] {subprocess.py:93} INFO - /home/***/.local/lib/python3.12/site-packages/sqlalchemy_redshift/commands.py:31: SyntaxWarning: invalid escape sequence '\-'
[2024-11-05T19:11:01.792+0000] {subprocess.py:93} INFO -   IAM_ROLE_NAME_RE = re.compile('[A-Za-z0-9+=,.@\-_]{1,64}')  # noqa
[2024-11-05T19:11:01.792+0000] {subprocess.py:93} INFO - /home/***/.local/lib/python3.12/site-packages/sqlalchemy_redshift/commands.py:33: SyntaxWarning: invalid escape sequence '\-'
[2024-11-05T19:11:01.794+0000] {subprocess.py:93} INFO -   '[0-9]{12}:role/[A-Za-z0-9+=,.@\-_]{1,64}')  # noqa
[2024-11-05T19:11:09.751+0000] {subprocess.py:93} INFO - Error: No gx directory was found here!
[2024-11-05T19:11:09.753+0000] {subprocess.py:93} INFO -     - Please check that you are in the correct directory or have specified the correct directory.
[2024-11-05T19:11:09.754+0000] {subprocess.py:93} INFO -     - If you have never run Great Expectations in this project, please run `great_expectations init` to get started.
[2024-11-05T19:11:09.754+0000] {subprocess.py:93} INFO - 
[2024-11-05T19:11:11.197+0000] {subprocess.py:97} INFO - Command exited with return code 1
[2024-11-05T19:11:11.230+0000] {taskinstance.py:3310} ERROR - Task failed with exception
Traceback (most recent call last):
  File "/home/airflow/.local/lib/python3.12/site-packages/airflow/models/taskinstance.py", line 767, in _execute_task
    result = _execute_callable(context=context, **execute_callable_kwargs)
             ^^^^^^^^^^^^^^^^^^^^^^^^^^^^^^^^^^^^^^^^^^^^^^^^^^^^^^^^^^^^^
  File "/home/airflow/.local/lib/python3.12/site-packages/airflow/models/taskinstance.py", line 733, in _execute_callable
    return ExecutionCallableRunner(
           ^^^^^^^^^^^^^^^^^^^^^^^^
  File "/home/airflow/.local/lib/python3.12/site-packages/airflow/utils/operator_helpers.py", line 252, in run
    return self.func(*args, **kwargs)
           ^^^^^^^^^^^^^^^^^^^^^^^^^^
  File "/home/airflow/.local/lib/python3.12/site-packages/airflow/models/baseoperator.py", line 406, in wrapper
    return func(self, *args, **kwargs)
           ^^^^^^^^^^^^^^^^^^^^^^^^^^^
  File "/home/airflow/.local/lib/python3.12/site-packages/airflow/operators/bash.py", line 249, in execute
    raise AirflowException(
airflow.exceptions.AirflowException: Bash command failed. The command returned a non-zero exit code 1.
[2024-11-05T19:11:11.261+0000] {taskinstance.py:1225} INFO - Marking task as UP_FOR_RETRY. dag_id=data_quality_dag, task_id=run_great_expectations, run_id=scheduled__2024-11-04T00:00:00+00:00, execution_date=20241104T000000, start_date=20241105T191053, end_date=20241105T191111
[2024-11-05T19:11:11.308+0000] {taskinstance.py:340} INFO - ::group::Post task execution logs
[2024-11-05T19:11:11.313+0000] {standard_task_runner.py:124} ERROR - Failed to execute job 135 for task run_great_expectations (Bash command failed. The command returned a non-zero exit code 1.; 596)
Traceback (most recent call last):
  File "/home/airflow/.local/lib/python3.12/site-packages/airflow/task/task_runner/standard_task_runner.py", line 117, in _start_by_fork
    ret = args.func(args, dag=self.dag)
          ^^^^^^^^^^^^^^^^^^^^^^^^^^^^^
  File "/home/airflow/.local/lib/python3.12/site-packages/airflow/cli/cli_config.py", line 49, in command
    return func(*args, **kwargs)
           ^^^^^^^^^^^^^^^^^^^^^
  File "/home/airflow/.local/lib/python3.12/site-packages/airflow/utils/cli.py", line 115, in wrapper
    return f(*args, **kwargs)
           ^^^^^^^^^^^^^^^^^^
  File "/home/airflow/.local/lib/python3.12/site-packages/airflow/cli/commands/task_command.py", line 483, in task_run
    task_return_code = _run_task_by_selected_method(args, _dag, ti)
                       ^^^^^^^^^^^^^^^^^^^^^^^^^^^^^^^^^^^^^^^^^^^^
  File "/home/airflow/.local/lib/python3.12/site-packages/airflow/cli/commands/task_command.py", line 256, in _run_task_by_selected_method
    return _run_raw_task(args, ti)
           ^^^^^^^^^^^^^^^^^^^^^^^
  File "/home/airflow/.local/lib/python3.12/site-packages/airflow/cli/commands/task_command.py", line 341, in _run_raw_task
    return ti._run_raw_task(
           ^^^^^^^^^^^^^^^^^
  File "/home/airflow/.local/lib/python3.12/site-packages/airflow/utils/session.py", line 97, in wrapper
    return func(*args, session=session, **kwargs)
           ^^^^^^^^^^^^^^^^^^^^^^^^^^^^^^^^^^^^^^
  File "/home/airflow/.local/lib/python3.12/site-packages/airflow/models/taskinstance.py", line 3004, in _run_raw_task
    return _run_raw_task(
           ^^^^^^^^^^^^^^
  File "/home/airflow/.local/lib/python3.12/site-packages/airflow/models/taskinstance.py", line 273, in _run_raw_task
    TaskInstance._execute_task_with_callbacks(
  File "/home/airflow/.local/lib/python3.12/site-packages/airflow/models/taskinstance.py", line 3158, in _execute_task_with_callbacks
    result = self._execute_task(context, task_orig)
             ^^^^^^^^^^^^^^^^^^^^^^^^^^^^^^^^^^^^^^
  File "/home/airflow/.local/lib/python3.12/site-packages/airflow/models/taskinstance.py", line 3182, in _execute_task
    return _execute_task(self, context, task_orig)
           ^^^^^^^^^^^^^^^^^^^^^^^^^^^^^^^^^^^^^^^
  File "/home/airflow/.local/lib/python3.12/site-packages/airflow/models/taskinstance.py", line 767, in _execute_task
    result = _execute_callable(context=context, **execute_callable_kwargs)
             ^^^^^^^^^^^^^^^^^^^^^^^^^^^^^^^^^^^^^^^^^^^^^^^^^^^^^^^^^^^^^
  File "/home/airflow/.local/lib/python3.12/site-packages/airflow/models/taskinstance.py", line 733, in _execute_callable
    return ExecutionCallableRunner(
           ^^^^^^^^^^^^^^^^^^^^^^^^
  File "/home/airflow/.local/lib/python3.12/site-packages/airflow/utils/operator_helpers.py", line 252, in run
    return self.func(*args, **kwargs)
           ^^^^^^^^^^^^^^^^^^^^^^^^^^
  File "/home/airflow/.local/lib/python3.12/site-packages/airflow/models/baseoperator.py", line 406, in wrapper
    return func(self, *args, **kwargs)
           ^^^^^^^^^^^^^^^^^^^^^^^^^^^
  File "/home/airflow/.local/lib/python3.12/site-packages/airflow/operators/bash.py", line 249, in execute
    raise AirflowException(
airflow.exceptions.AirflowException: Bash command failed. The command returned a non-zero exit code 1.
[2024-11-05T19:11:11.396+0000] {local_task_job_runner.py:266} INFO - Task exited with return code 1
[2024-11-05T19:11:11.442+0000] {taskinstance.py:3900} INFO - 0 downstream tasks scheduled from follow-on schedule check
[2024-11-05T19:11:11.444+0000] {local_task_job_runner.py:245} INFO - ::endgroup::
[2024-11-05T19:19:58.651+0000] {local_task_job_runner.py:123} INFO - ::group::Pre task execution logs
[2024-11-05T19:19:58.670+0000] {taskinstance.py:2612} INFO - Dependencies all met for dep_context=non-requeueable deps ti=<TaskInstance: data_quality_dag.run_great_expectations scheduled__2024-11-04T00:00:00+00:00 [queued]>
[2024-11-05T19:19:58.680+0000] {taskinstance.py:2612} INFO - Dependencies all met for dep_context=requeueable deps ti=<TaskInstance: data_quality_dag.run_great_expectations scheduled__2024-11-04T00:00:00+00:00 [queued]>
[2024-11-05T19:19:58.680+0000] {taskinstance.py:2865} INFO - Starting attempt 1 of 2
[2024-11-05T19:19:58.696+0000] {taskinstance.py:2888} INFO - Executing <Task(BashOperator): run_great_expectations> on 2024-11-04 00:00:00+00:00
[2024-11-05T19:19:58.702+0000] {warnings.py:112} WARNING - /home/***/.local/lib/python3.12/site-packages/***/task/task_runner/standard_task_runner.py:70: DeprecationWarning: This process (pid=753) is multi-threaded, use of fork() may lead to deadlocks in the child.
  pid = os.fork()

[2024-11-05T19:19:58.703+0000] {standard_task_runner.py:72} INFO - Started process 754 to run task
[2024-11-05T19:19:58.704+0000] {standard_task_runner.py:104} INFO - Running: ['***', 'tasks', 'run', 'data_quality_dag', 'run_great_expectations', 'scheduled__2024-11-04T00:00:00+00:00', '--job-id', '138', '--raw', '--subdir', 'DAGS_FOLDER/data_quality_dag.py', '--cfg-path', '/tmp/tmp4szi8fxe']
[2024-11-05T19:19:58.705+0000] {standard_task_runner.py:105} INFO - Job 138: Subtask run_great_expectations
[2024-11-05T19:19:58.755+0000] {task_command.py:467} INFO - Running <TaskInstance: data_quality_dag.run_great_expectations scheduled__2024-11-04T00:00:00+00:00 [running]> on host 5183c4c0ec1d
[2024-11-05T19:19:58.840+0000] {taskinstance.py:3131} INFO - Exporting env vars: AIRFLOW_CTX_DAG_OWNER='***' AIRFLOW_CTX_DAG_ID='data_quality_dag' AIRFLOW_CTX_TASK_ID='run_great_expectations' AIRFLOW_CTX_EXECUTION_DATE='2024-11-04T00:00:00+00:00' AIRFLOW_CTX_TRY_NUMBER='1' AIRFLOW_CTX_DAG_RUN_ID='scheduled__2024-11-04T00:00:00+00:00'
[2024-11-05T19:19:58.841+0000] {taskinstance.py:731} INFO - ::endgroup::
[2024-11-05T19:19:58.860+0000] {subprocess.py:63} INFO - Tmp dir root location: /tmp
[2024-11-05T19:19:58.860+0000] {subprocess.py:75} INFO - Running command: ['/usr/bin/bash', '-c', 'cd /opt/dbt && great_expectations checkpoint run GX-person_checkpoint']
[2024-11-05T19:19:58.870+0000] {subprocess.py:86} INFO - Output:
[2024-11-05T19:20:04.660+0000] {subprocess.py:93} INFO - Could not find Checkpoint `GX-person_checkpoint` (or its configuration is invalid). Try running:
[2024-11-05T19:20:04.661+0000] {subprocess.py:93} INFO -   - `great_expectations checkpoint list` to verify your Checkpoint exists
[2024-11-05T19:20:04.661+0000] {subprocess.py:93} INFO -   - `great_expectations checkpoint new` to configure a new Checkpoint
[2024-11-05T19:20:05.383+0000] {subprocess.py:97} INFO - Command exited with return code 1
[2024-11-05T19:20:05.396+0000] {taskinstance.py:3310} ERROR - Task failed with exception
Traceback (most recent call last):
  File "/home/airflow/.local/lib/python3.12/site-packages/airflow/models/taskinstance.py", line 767, in _execute_task
    result = _execute_callable(context=context, **execute_callable_kwargs)
             ^^^^^^^^^^^^^^^^^^^^^^^^^^^^^^^^^^^^^^^^^^^^^^^^^^^^^^^^^^^^^
  File "/home/airflow/.local/lib/python3.12/site-packages/airflow/models/taskinstance.py", line 733, in _execute_callable
    return ExecutionCallableRunner(
           ^^^^^^^^^^^^^^^^^^^^^^^^
  File "/home/airflow/.local/lib/python3.12/site-packages/airflow/utils/operator_helpers.py", line 252, in run
    return self.func(*args, **kwargs)
           ^^^^^^^^^^^^^^^^^^^^^^^^^^
  File "/home/airflow/.local/lib/python3.12/site-packages/airflow/models/baseoperator.py", line 406, in wrapper
    return func(self, *args, **kwargs)
           ^^^^^^^^^^^^^^^^^^^^^^^^^^^
  File "/home/airflow/.local/lib/python3.12/site-packages/airflow/operators/bash.py", line 249, in execute
    raise AirflowException(
airflow.exceptions.AirflowException: Bash command failed. The command returned a non-zero exit code 1.
[2024-11-05T19:20:05.405+0000] {taskinstance.py:1225} INFO - Marking task as UP_FOR_RETRY. dag_id=data_quality_dag, task_id=run_great_expectations, run_id=scheduled__2024-11-04T00:00:00+00:00, execution_date=20241104T000000, start_date=20241105T191958, end_date=20241105T192005
[2024-11-05T19:20:05.423+0000] {taskinstance.py:340} INFO - ::group::Post task execution logs
[2024-11-05T19:20:05.424+0000] {standard_task_runner.py:124} ERROR - Failed to execute job 138 for task run_great_expectations (Bash command failed. The command returned a non-zero exit code 1.; 754)
Traceback (most recent call last):
  File "/home/airflow/.local/lib/python3.12/site-packages/airflow/task/task_runner/standard_task_runner.py", line 117, in _start_by_fork
    ret = args.func(args, dag=self.dag)
          ^^^^^^^^^^^^^^^^^^^^^^^^^^^^^
  File "/home/airflow/.local/lib/python3.12/site-packages/airflow/cli/cli_config.py", line 49, in command
    return func(*args, **kwargs)
           ^^^^^^^^^^^^^^^^^^^^^
  File "/home/airflow/.local/lib/python3.12/site-packages/airflow/utils/cli.py", line 115, in wrapper
    return f(*args, **kwargs)
           ^^^^^^^^^^^^^^^^^^
  File "/home/airflow/.local/lib/python3.12/site-packages/airflow/cli/commands/task_command.py", line 483, in task_run
    task_return_code = _run_task_by_selected_method(args, _dag, ti)
                       ^^^^^^^^^^^^^^^^^^^^^^^^^^^^^^^^^^^^^^^^^^^^
  File "/home/airflow/.local/lib/python3.12/site-packages/airflow/cli/commands/task_command.py", line 256, in _run_task_by_selected_method
    return _run_raw_task(args, ti)
           ^^^^^^^^^^^^^^^^^^^^^^^
  File "/home/airflow/.local/lib/python3.12/site-packages/airflow/cli/commands/task_command.py", line 341, in _run_raw_task
    return ti._run_raw_task(
           ^^^^^^^^^^^^^^^^^
  File "/home/airflow/.local/lib/python3.12/site-packages/airflow/utils/session.py", line 97, in wrapper
    return func(*args, session=session, **kwargs)
           ^^^^^^^^^^^^^^^^^^^^^^^^^^^^^^^^^^^^^^
  File "/home/airflow/.local/lib/python3.12/site-packages/airflow/models/taskinstance.py", line 3004, in _run_raw_task
    return _run_raw_task(
           ^^^^^^^^^^^^^^
  File "/home/airflow/.local/lib/python3.12/site-packages/airflow/models/taskinstance.py", line 273, in _run_raw_task
    TaskInstance._execute_task_with_callbacks(
  File "/home/airflow/.local/lib/python3.12/site-packages/airflow/models/taskinstance.py", line 3158, in _execute_task_with_callbacks
    result = self._execute_task(context, task_orig)
             ^^^^^^^^^^^^^^^^^^^^^^^^^^^^^^^^^^^^^^
  File "/home/airflow/.local/lib/python3.12/site-packages/airflow/models/taskinstance.py", line 3182, in _execute_task
    return _execute_task(self, context, task_orig)
           ^^^^^^^^^^^^^^^^^^^^^^^^^^^^^^^^^^^^^^^
  File "/home/airflow/.local/lib/python3.12/site-packages/airflow/models/taskinstance.py", line 767, in _execute_task
    result = _execute_callable(context=context, **execute_callable_kwargs)
             ^^^^^^^^^^^^^^^^^^^^^^^^^^^^^^^^^^^^^^^^^^^^^^^^^^^^^^^^^^^^^
  File "/home/airflow/.local/lib/python3.12/site-packages/airflow/models/taskinstance.py", line 733, in _execute_callable
    return ExecutionCallableRunner(
           ^^^^^^^^^^^^^^^^^^^^^^^^
  File "/home/airflow/.local/lib/python3.12/site-packages/airflow/utils/operator_helpers.py", line 252, in run
    return self.func(*args, **kwargs)
           ^^^^^^^^^^^^^^^^^^^^^^^^^^
  File "/home/airflow/.local/lib/python3.12/site-packages/airflow/models/baseoperator.py", line 406, in wrapper
    return func(self, *args, **kwargs)
           ^^^^^^^^^^^^^^^^^^^^^^^^^^^
  File "/home/airflow/.local/lib/python3.12/site-packages/airflow/operators/bash.py", line 249, in execute
    raise AirflowException(
airflow.exceptions.AirflowException: Bash command failed. The command returned a non-zero exit code 1.
[2024-11-05T19:20:05.464+0000] {local_task_job_runner.py:266} INFO - Task exited with return code 1
[2024-11-05T19:20:05.480+0000] {taskinstance.py:3900} INFO - 0 downstream tasks scheduled from follow-on schedule check
[2024-11-05T19:20:05.482+0000] {local_task_job_runner.py:245} INFO - ::endgroup::
