[2024-11-05T19:14:22.709+0000] {local_task_job_runner.py:123} INFO - ::group::Pre task execution logs
[2024-11-05T19:14:22.737+0000] {taskinstance.py:2612} INFO - Dependencies all met for dep_context=non-requeueable deps ti=<TaskInstance: data_quality_dag.run_great_expectations manual__2024-11-05T19:14:21.189244+00:00 [queued]>
[2024-11-05T19:14:22.751+0000] {taskinstance.py:2612} INFO - Dependencies all met for dep_context=requeueable deps ti=<TaskInstance: data_quality_dag.run_great_expectations manual__2024-11-05T19:14:21.189244+00:00 [queued]>
[2024-11-05T19:14:22.751+0000] {taskinstance.py:2865} INFO - Starting attempt 1 of 2
[2024-11-05T19:14:22.775+0000] {taskinstance.py:2888} INFO - Executing <Task(BashOperator): run_great_expectations> on 2024-11-05 19:14:21.189244+00:00
[2024-11-05T19:14:22.784+0000] {warnings.py:112} WARNING - /home/***/.local/lib/python3.12/site-packages/***/task/task_runner/standard_task_runner.py:70: DeprecationWarning: This process (pid=659) is multi-threaded, use of fork() may lead to deadlocks in the child.
  pid = os.fork()

[2024-11-05T19:14:22.790+0000] {standard_task_runner.py:72} INFO - Started process 660 to run task
[2024-11-05T19:14:22.787+0000] {standard_task_runner.py:104} INFO - Running: ['***', 'tasks', 'run', 'data_quality_dag', 'run_great_expectations', 'manual__2024-11-05T19:14:21.189244+00:00', '--job-id', '136', '--raw', '--subdir', 'DAGS_FOLDER/data_quality_dag.py', '--cfg-path', '/tmp/tmp0fweaou2']
[2024-11-05T19:14:22.791+0000] {standard_task_runner.py:105} INFO - Job 136: Subtask run_great_expectations
[2024-11-05T19:14:22.862+0000] {task_command.py:467} INFO - Running <TaskInstance: data_quality_dag.run_great_expectations manual__2024-11-05T19:14:21.189244+00:00 [running]> on host 5183c4c0ec1d
[2024-11-05T19:14:22.981+0000] {taskinstance.py:3131} INFO - Exporting env vars: AIRFLOW_CTX_DAG_OWNER='***' AIRFLOW_CTX_DAG_ID='data_quality_dag' AIRFLOW_CTX_TASK_ID='run_great_expectations' AIRFLOW_CTX_EXECUTION_DATE='2024-11-05T19:14:21.189244+00:00' AIRFLOW_CTX_TRY_NUMBER='1' AIRFLOW_CTX_DAG_RUN_ID='manual__2024-11-05T19:14:21.189244+00:00'
[2024-11-05T19:14:22.982+0000] {taskinstance.py:731} INFO - ::endgroup::
[2024-11-05T19:14:23.006+0000] {subprocess.py:63} INFO - Tmp dir root location: /tmp
[2024-11-05T19:14:23.007+0000] {subprocess.py:75} INFO - Running command: ['/usr/bin/bash', '-c', 'cd /opt/dbt && great_expectations checkpoint run GX-person_checkpoint']
[2024-11-05T19:14:23.020+0000] {subprocess.py:86} INFO - Output:
[2024-11-05T19:14:29.770+0000] {subprocess.py:93} INFO - Could not find Checkpoint `GX-person_checkpoint` (or its configuration is invalid). Try running:
[2024-11-05T19:14:29.770+0000] {subprocess.py:93} INFO -   - `great_expectations checkpoint list` to verify your Checkpoint exists
[2024-11-05T19:14:29.771+0000] {subprocess.py:93} INFO -   - `great_expectations checkpoint new` to configure a new Checkpoint
[2024-11-05T19:14:30.803+0000] {subprocess.py:97} INFO - Command exited with return code 1
[2024-11-05T19:14:30.824+0000] {taskinstance.py:3310} ERROR - Task failed with exception
Traceback (most recent call last):
  File "/home/airflow/.local/lib/python3.12/site-packages/airflow/models/taskinstance.py", line 767, in _execute_task
    result = _execute_callable(context=context, **execute_callable_kwargs)
             ^^^^^^^^^^^^^^^^^^^^^^^^^^^^^^^^^^^^^^^^^^^^^^^^^^^^^^^^^^^^^
  File "/home/airflow/.local/lib/python3.12/site-packages/airflow/models/taskinstance.py", line 733, in _execute_callable
    return ExecutionCallableRunner(
           ^^^^^^^^^^^^^^^^^^^^^^^^
  File "/home/airflow/.local/lib/python3.12/site-packages/airflow/utils/operator_helpers.py", line 252, in run
    return self.func(*args, **kwargs)
           ^^^^^^^^^^^^^^^^^^^^^^^^^^
  File "/home/airflow/.local/lib/python3.12/site-packages/airflow/models/baseoperator.py", line 406, in wrapper
    return func(self, *args, **kwargs)
           ^^^^^^^^^^^^^^^^^^^^^^^^^^^
  File "/home/airflow/.local/lib/python3.12/site-packages/airflow/operators/bash.py", line 249, in execute
    raise AirflowException(
airflow.exceptions.AirflowException: Bash command failed. The command returned a non-zero exit code 1.
[2024-11-05T19:14:30.840+0000] {taskinstance.py:1225} INFO - Marking task as UP_FOR_RETRY. dag_id=data_quality_dag, task_id=run_great_expectations, run_id=manual__2024-11-05T19:14:21.189244+00:00, execution_date=20241105T191421, start_date=20241105T191422, end_date=20241105T191430
[2024-11-05T19:14:30.874+0000] {taskinstance.py:340} INFO - ::group::Post task execution logs
[2024-11-05T19:14:30.875+0000] {standard_task_runner.py:124} ERROR - Failed to execute job 136 for task run_great_expectations (Bash command failed. The command returned a non-zero exit code 1.; 660)
Traceback (most recent call last):
  File "/home/airflow/.local/lib/python3.12/site-packages/airflow/task/task_runner/standard_task_runner.py", line 117, in _start_by_fork
    ret = args.func(args, dag=self.dag)
          ^^^^^^^^^^^^^^^^^^^^^^^^^^^^^
  File "/home/airflow/.local/lib/python3.12/site-packages/airflow/cli/cli_config.py", line 49, in command
    return func(*args, **kwargs)
           ^^^^^^^^^^^^^^^^^^^^^
  File "/home/airflow/.local/lib/python3.12/site-packages/airflow/utils/cli.py", line 115, in wrapper
    return f(*args, **kwargs)
           ^^^^^^^^^^^^^^^^^^
  File "/home/airflow/.local/lib/python3.12/site-packages/airflow/cli/commands/task_command.py", line 483, in task_run
    task_return_code = _run_task_by_selected_method(args, _dag, ti)
                       ^^^^^^^^^^^^^^^^^^^^^^^^^^^^^^^^^^^^^^^^^^^^
  File "/home/airflow/.local/lib/python3.12/site-packages/airflow/cli/commands/task_command.py", line 256, in _run_task_by_selected_method
    return _run_raw_task(args, ti)
           ^^^^^^^^^^^^^^^^^^^^^^^
  File "/home/airflow/.local/lib/python3.12/site-packages/airflow/cli/commands/task_command.py", line 341, in _run_raw_task
    return ti._run_raw_task(
           ^^^^^^^^^^^^^^^^^
  File "/home/airflow/.local/lib/python3.12/site-packages/airflow/utils/session.py", line 97, in wrapper
    return func(*args, session=session, **kwargs)
           ^^^^^^^^^^^^^^^^^^^^^^^^^^^^^^^^^^^^^^
  File "/home/airflow/.local/lib/python3.12/site-packages/airflow/models/taskinstance.py", line 3004, in _run_raw_task
    return _run_raw_task(
           ^^^^^^^^^^^^^^
  File "/home/airflow/.local/lib/python3.12/site-packages/airflow/models/taskinstance.py", line 273, in _run_raw_task
    TaskInstance._execute_task_with_callbacks(
  File "/home/airflow/.local/lib/python3.12/site-packages/airflow/models/taskinstance.py", line 3158, in _execute_task_with_callbacks
    result = self._execute_task(context, task_orig)
             ^^^^^^^^^^^^^^^^^^^^^^^^^^^^^^^^^^^^^^
  File "/home/airflow/.local/lib/python3.12/site-packages/airflow/models/taskinstance.py", line 3182, in _execute_task
    return _execute_task(self, context, task_orig)
           ^^^^^^^^^^^^^^^^^^^^^^^^^^^^^^^^^^^^^^^
  File "/home/airflow/.local/lib/python3.12/site-packages/airflow/models/taskinstance.py", line 767, in _execute_task
    result = _execute_callable(context=context, **execute_callable_kwargs)
             ^^^^^^^^^^^^^^^^^^^^^^^^^^^^^^^^^^^^^^^^^^^^^^^^^^^^^^^^^^^^^
  File "/home/airflow/.local/lib/python3.12/site-packages/airflow/models/taskinstance.py", line 733, in _execute_callable
    return ExecutionCallableRunner(
           ^^^^^^^^^^^^^^^^^^^^^^^^
  File "/home/airflow/.local/lib/python3.12/site-packages/airflow/utils/operator_helpers.py", line 252, in run
    return self.func(*args, **kwargs)
           ^^^^^^^^^^^^^^^^^^^^^^^^^^
  File "/home/airflow/.local/lib/python3.12/site-packages/airflow/models/baseoperator.py", line 406, in wrapper
    return func(self, *args, **kwargs)
           ^^^^^^^^^^^^^^^^^^^^^^^^^^^
  File "/home/airflow/.local/lib/python3.12/site-packages/airflow/operators/bash.py", line 249, in execute
    raise AirflowException(
airflow.exceptions.AirflowException: Bash command failed. The command returned a non-zero exit code 1.
[2024-11-05T19:14:30.925+0000] {local_task_job_runner.py:266} INFO - Task exited with return code 1
[2024-11-05T19:14:30.947+0000] {taskinstance.py:3900} INFO - 0 downstream tasks scheduled from follow-on schedule check
[2024-11-05T19:14:30.949+0000] {local_task_job_runner.py:245} INFO - ::endgroup::
