[2024-11-06T12:07:36.557+0000] {local_task_job_runner.py:123} INFO - ::group::Pre task execution logs
[2024-11-06T12:07:36.598+0000] {taskinstance.py:2612} INFO - Dependencies all met for dep_context=non-requeueable deps ti=<TaskInstance: dbt_project_with_ge_dag.ge_validate_obt_sales manual__2024-11-06T12:05:53.813585+00:00 [queued]>
[2024-11-06T12:07:36.620+0000] {taskinstance.py:2612} INFO - Dependencies all met for dep_context=requeueable deps ti=<TaskInstance: dbt_project_with_ge_dag.ge_validate_obt_sales manual__2024-11-06T12:05:53.813585+00:00 [queued]>
[2024-11-06T12:07:36.621+0000] {taskinstance.py:2865} INFO - Starting attempt 3 of 3
[2024-11-06T12:07:36.655+0000] {taskinstance.py:2888} INFO - Executing <Task(BashOperator): ge_validate_obt_sales> on 2024-11-06 12:05:53.813585+00:00
[2024-11-06T12:07:36.663+0000] {warnings.py:112} WARNING - /home/***/.local/lib/python3.12/site-packages/***/task/task_runner/standard_task_runner.py:70: DeprecationWarning: This process (pid=2025) is multi-threaded, use of fork() may lead to deadlocks in the child.
  pid = os.fork()

[2024-11-06T12:07:36.665+0000] {standard_task_runner.py:72} INFO - Started process 2026 to run task
[2024-11-06T12:07:36.665+0000] {standard_task_runner.py:104} INFO - Running: ['***', 'tasks', 'run', 'dbt_project_with_ge_dag', 'ge_validate_obt_sales', 'manual__2024-11-06T12:05:53.813585+00:00', '--job-id', '173', '--raw', '--subdir', 'DAGS_FOLDER/dbt_project_dag.py', '--cfg-path', '/tmp/tmpapr7dp1q']
[2024-11-06T12:07:36.668+0000] {standard_task_runner.py:105} INFO - Job 173: Subtask ge_validate_obt_sales
[2024-11-06T12:07:36.740+0000] {task_command.py:467} INFO - Running <TaskInstance: dbt_project_with_ge_dag.ge_validate_obt_sales manual__2024-11-06T12:05:53.813585+00:00 [running]> on host 9ecf534049e3
[2024-11-06T12:07:36.852+0000] {taskinstance.py:3131} INFO - Exporting env vars: AIRFLOW_CTX_DAG_OWNER='***' AIRFLOW_CTX_DAG_ID='dbt_project_with_ge_dag' AIRFLOW_CTX_TASK_ID='ge_validate_obt_sales' AIRFLOW_CTX_EXECUTION_DATE='2024-11-06T12:05:53.813585+00:00' AIRFLOW_CTX_TRY_NUMBER='3' AIRFLOW_CTX_DAG_RUN_ID='manual__2024-11-06T12:05:53.813585+00:00'
[2024-11-06T12:07:36.853+0000] {taskinstance.py:731} INFO - ::endgroup::
[2024-11-06T12:07:36.880+0000] {subprocess.py:63} INFO - Tmp dir root location: /tmp
[2024-11-06T12:07:36.881+0000] {subprocess.py:75} INFO - Running command: ['/usr/bin/bash', '-c', 'cd /opt/dbt && great_expectations checkpoint run obt_sales_checkpoint']
[2024-11-06T12:07:36.893+0000] {subprocess.py:86} INFO - Output:
[2024-11-06T12:07:44.621+0000] {subprocess.py:93} INFO - Calculating Metrics:   0%|          | 0/69 [00:00<?, ?it/s]Calculating Metrics:   0%|          | 0/69 [00:00<?, ?it/s]Calculating Metrics:   3%|▎         | 2/69 [00:00<00:00, 230.06it/s]Calculating Metrics:   3%|▎         | 2/69 [00:00<00:01, 36.15it/s] Calculating Metrics:   6%|▌         | 4/69 [00:00<00:00, 66.25it/s]Calculating Metrics:   6%|▌         | 4/69 [00:00<00:01, 38.44it/s]Calculating Metrics:   6%|▌         | 4/69 [00:00<00:01, 38.44it/s]Calculating Metrics:  25%|██▍       | 17/69 [00:00<00:01, 38.44it/s]Calculating Metrics:  25%|██▍       | 17/69 [00:00<00:01, 38.44it/s]Calculating Metrics:  83%|████████▎ | 57/69 [00:00<00:00, 263.29it/s]Calculating Metrics:  83%|████████▎ | 57/69 [00:00<00:00, 263.29it/s]Calculating Metrics:  83%|████████▎ | 57/69 [00:00<00:00, 263.29it/s]Calculating Metrics: 100%|██████████| 69/69 [00:00<00:00, 263.29it/s]Calculating Metrics: 100%|██████████| 69/69 [00:00<00:00, 263.29it/s]Calculating Metrics: 100%|██████████| 69/69 [00:00<00:00, 263.29it/s]Calculating Metrics: 100%|██████████| 69/69 [00:00<00:00, 189.48it/s]
[2024-11-06T12:07:44.831+0000] {subprocess.py:93} INFO - An unexpected Exception occurred during data docs rendering.  Because of this error, certain parts of data docs will not be rendered properly and/or may not appear altogether.  Please use the trace, included in this message, to diagnose and repair the underlying issue.  Detailed information follows:
[2024-11-06T12:07:44.832+0000] {subprocess.py:93} INFO -                 PermissionError: "[Errno 13] Permission denied: '/opt/dbt/gx/uncommitted/data_docs/local_site/expectations/obt_sales/basic.html'".  Traceback: "Traceback (most recent call last):
[2024-11-06T12:07:44.832+0000] {subprocess.py:93} INFO -   File "/home/***/.local/lib/python3.12/site-packages/great_expectations/render/renderer/site_builder.py", line 501, in build
[2024-11-06T12:07:44.833+0000] {subprocess.py:93} INFO -     self.target_store.set(
[2024-11-06T12:07:44.833+0000] {subprocess.py:93} INFO -   File "/home/***/.local/lib/python3.12/site-packages/great_expectations/data_context/store/html_site_store.py", line 269, in set
[2024-11-06T12:07:44.834+0000] {subprocess.py:93} INFO -     return self.store_backends[type(key.resource_identifier)].set(
[2024-11-06T12:07:44.834+0000] {subprocess.py:93} INFO -            ^^^^^^^^^^^^^^^^^^^^^^^^^^^^^^^^^^^^^^^^^^^^^^^^^^^^^^^
[2024-11-06T12:07:44.835+0000] {subprocess.py:93} INFO -   File "/home/***/.local/lib/python3.12/site-packages/great_expectations/data_context/store/_store_backend.py", line 134, in set
[2024-11-06T12:07:44.835+0000] {subprocess.py:93} INFO -     return self._set(key, value, **kwargs)
[2024-11-06T12:07:44.836+0000] {subprocess.py:93} INFO -            ^^^^^^^^^^^^^^^^^^^^^^^^^^^^^^^
[2024-11-06T12:07:44.836+0000] {subprocess.py:93} INFO -   File "/home/***/.local/lib/python3.12/site-packages/great_expectations/data_context/store/tuple_store_backend.py", line 330, in _set
[2024-11-06T12:07:44.837+0000] {subprocess.py:93} INFO -     with open(filepath, "wb") as outfile:
[2024-11-06T12:07:44.837+0000] {subprocess.py:93} INFO -          ^^^^^^^^^^^^^^^^^^^^
[2024-11-06T12:07:44.838+0000] {subprocess.py:93} INFO - PermissionError: [Errno 13] Permission denied: '/opt/dbt/gx/uncommitted/data_docs/local_site/expectations/obt_sales/basic.html'
[2024-11-06T12:07:44.838+0000] {subprocess.py:93} INFO - ".
[2024-11-06T12:07:44.956+0000] {subprocess.py:93} INFO - An unexpected Exception occurred during data docs rendering.  Because of this error, certain parts of data docs will not be rendered properly and/or may not appear altogether.  Please use the trace, included in this message, to diagnose and repair the underlying issue.  Detailed information follows:
[2024-11-06T12:07:44.956+0000] {subprocess.py:93} INFO -                 PermissionError: "[Errno 13] Permission denied: '/opt/dbt/gx/uncommitted/data_docs/local_site/validations/obt_sales/basic/20241106-120743-obt_sales-checkpoint'".  Traceback: "Traceback (most recent call last):
[2024-11-06T12:07:44.957+0000] {subprocess.py:93} INFO -   File "/home/***/.local/lib/python3.12/site-packages/great_expectations/render/renderer/site_builder.py", line 501, in build
[2024-11-06T12:07:44.957+0000] {subprocess.py:93} INFO -     self.target_store.set(
[2024-11-06T12:07:44.958+0000] {subprocess.py:93} INFO -   File "/home/***/.local/lib/python3.12/site-packages/great_expectations/data_context/store/html_site_store.py", line 269, in set
[2024-11-06T12:07:44.958+0000] {subprocess.py:93} INFO -     return self.store_backends[type(key.resource_identifier)].set(
[2024-11-06T12:07:44.958+0000] {subprocess.py:93} INFO -            ^^^^^^^^^^^^^^^^^^^^^^^^^^^^^^^^^^^^^^^^^^^^^^^^^^^^^^^
[2024-11-06T12:07:44.959+0000] {subprocess.py:93} INFO -   File "/home/***/.local/lib/python3.12/site-packages/great_expectations/data_context/store/_store_backend.py", line 134, in set
[2024-11-06T12:07:44.959+0000] {subprocess.py:93} INFO -     return self._set(key, value, **kwargs)
[2024-11-06T12:07:44.960+0000] {subprocess.py:93} INFO -            ^^^^^^^^^^^^^^^^^^^^^^^^^^^^^^^
[2024-11-06T12:07:44.960+0000] {subprocess.py:93} INFO -   File "/home/***/.local/lib/python3.12/site-packages/great_expectations/data_context/store/tuple_store_backend.py", line 329, in _set
[2024-11-06T12:07:44.961+0000] {subprocess.py:93} INFO -     os.makedirs(str(path), exist_ok=True)  # noqa: PTH103
[2024-11-06T12:07:44.962+0000] {subprocess.py:93} INFO -     ^^^^^^^^^^^^^^^^^^^^^^^^^^^^^^^^^^^^^
[2024-11-06T12:07:44.963+0000] {subprocess.py:93} INFO -   File "<frozen os>", line 215, in makedirs
[2024-11-06T12:07:44.963+0000] {subprocess.py:93} INFO -   File "<frozen os>", line 225, in makedirs
[2024-11-06T12:07:44.964+0000] {subprocess.py:93} INFO - PermissionError: [Errno 13] Permission denied: '/opt/dbt/gx/uncommitted/data_docs/local_site/validations/obt_sales/basic/20241106-120743-obt_sales-checkpoint'
[2024-11-06T12:07:44.964+0000] {subprocess.py:93} INFO - ".
[2024-11-06T12:07:44.971+0000] {subprocess.py:93} INFO - Error running action with name update_data_docs
[2024-11-06T12:07:44.972+0000] {subprocess.py:93} INFO - Traceback (most recent call last):
[2024-11-06T12:07:44.972+0000] {subprocess.py:93} INFO -   File "/home/***/.local/lib/python3.12/site-packages/great_expectations/validation_operators/validation_operators.py", line 476, in _run_actions
[2024-11-06T12:07:44.973+0000] {subprocess.py:93} INFO -     action_result = self.actions[name].run(
[2024-11-06T12:07:44.973+0000] {subprocess.py:93} INFO -                     ^^^^^^^^^^^^^^^^^^^^^^^
[2024-11-06T12:07:44.973+0000] {subprocess.py:93} INFO -   File "/home/***/.local/lib/python3.12/site-packages/great_expectations/checkpoint/actions.py", line 101, in run
[2024-11-06T12:07:44.974+0000] {subprocess.py:93} INFO -     return self._run(
[2024-11-06T12:07:44.974+0000] {subprocess.py:93} INFO -            ^^^^^^^^^^
[2024-11-06T12:07:44.974+0000] {subprocess.py:93} INFO -   File "/home/***/.local/lib/python3.12/site-packages/great_expectations/checkpoint/actions.py", line 1190, in _run
[2024-11-06T12:07:44.975+0000] {subprocess.py:93} INFO -     self.data_context.build_data_docs(
[2024-11-06T12:07:44.975+0000] {subprocess.py:93} INFO -   File "/home/***/.local/lib/python3.12/site-packages/great_expectations/core/usage_statistics/usage_statistics.py", line 266, in usage_statistics_wrapped_method
[2024-11-06T12:07:44.975+0000] {subprocess.py:93} INFO -     result = func(*args, **kwargs)
[2024-11-06T12:07:44.976+0000] {subprocess.py:93} INFO -              ^^^^^^^^^^^^^^^^^^^^^
[2024-11-06T12:07:44.976+0000] {subprocess.py:93} INFO -   File "/home/***/.local/lib/python3.12/site-packages/great_expectations/data_context/data_context/abstract_data_context.py", line 5318, in build_data_docs
[2024-11-06T12:07:44.976+0000] {subprocess.py:93} INFO -     return self._build_data_docs(
[2024-11-06T12:07:44.977+0000] {subprocess.py:93} INFO -            ^^^^^^^^^^^^^^^^^^^^^^
[2024-11-06T12:07:44.977+0000] {subprocess.py:93} INFO -   File "/home/***/.local/lib/python3.12/site-packages/great_expectations/data_context/data_context/abstract_data_context.py", line 5365, in _build_data_docs
[2024-11-06T12:07:44.978+0000] {subprocess.py:93} INFO -     index_page_resource_identifier_tuple = site_builder.build(
[2024-11-06T12:07:44.978+0000] {subprocess.py:93} INFO -                                            ^^^^^^^^^^^^^^^^^^^
[2024-11-06T12:07:44.979+0000] {subprocess.py:93} INFO -   File "/home/***/.local/lib/python3.12/site-packages/great_expectations/render/renderer/site_builder.py", line 329, in build
[2024-11-06T12:07:44.979+0000] {subprocess.py:93} INFO -     self.target_store.copy_static_assets()
[2024-11-06T12:07:44.980+0000] {subprocess.py:93} INFO -   File "/home/***/.local/lib/python3.12/site-packages/great_expectations/data_context/store/html_site_store.py", line 412, in copy_static_assets
[2024-11-06T12:07:44.980+0000] {subprocess.py:93} INFO -     self.copy_static_assets(new_source_dir)
[2024-11-06T12:07:44.981+0000] {subprocess.py:93} INFO -   File "/home/***/.local/lib/python3.12/site-packages/great_expectations/data_context/store/html_site_store.py", line 441, in copy_static_assets
[2024-11-06T12:07:44.981+0000] {subprocess.py:93} INFO -     self.store_backends["static_assets"].set(
[2024-11-06T12:07:44.982+0000] {subprocess.py:93} INFO -   File "/home/***/.local/lib/python3.12/site-packages/great_expectations/data_context/store/_store_backend.py", line 134, in set
[2024-11-06T12:07:44.983+0000] {subprocess.py:93} INFO -     return self._set(key, value, **kwargs)
[2024-11-06T12:07:44.983+0000] {subprocess.py:93} INFO -            ^^^^^^^^^^^^^^^^^^^^^^^^^^^^^^^
[2024-11-06T12:07:44.984+0000] {subprocess.py:93} INFO -   File "/home/***/.local/lib/python3.12/site-packages/great_expectations/data_context/store/tuple_store_backend.py", line 330, in _set
[2024-11-06T12:07:44.984+0000] {subprocess.py:93} INFO -     with open(filepath, "wb") as outfile:
[2024-11-06T12:07:44.985+0000] {subprocess.py:93} INFO -          ^^^^^^^^^^^^^^^^^^^^
[2024-11-06T12:07:44.985+0000] {subprocess.py:93} INFO - PermissionError: [Errno 13] Permission denied: '/opt/dbt/gx/uncommitted/data_docs/local_site/static/styles/data_docs_default_styles.css'
[2024-11-06T12:07:44.985+0000] {subprocess.py:93} INFO - [Errno 13] Permission denied: '/opt/dbt/gx/uncommitted/data_docs/local_site/static/styles/data_docs_default_styles.css'
[2024-11-06T12:07:45.793+0000] {subprocess.py:97} INFO - Command exited with return code 1
[2024-11-06T12:07:45.806+0000] {taskinstance.py:3310} ERROR - Task failed with exception
Traceback (most recent call last):
  File "/home/airflow/.local/lib/python3.12/site-packages/airflow/models/taskinstance.py", line 767, in _execute_task
    result = _execute_callable(context=context, **execute_callable_kwargs)
             ^^^^^^^^^^^^^^^^^^^^^^^^^^^^^^^^^^^^^^^^^^^^^^^^^^^^^^^^^^^^^
  File "/home/airflow/.local/lib/python3.12/site-packages/airflow/models/taskinstance.py", line 733, in _execute_callable
    return ExecutionCallableRunner(
           ^^^^^^^^^^^^^^^^^^^^^^^^
  File "/home/airflow/.local/lib/python3.12/site-packages/airflow/utils/operator_helpers.py", line 252, in run
    return self.func(*args, **kwargs)
           ^^^^^^^^^^^^^^^^^^^^^^^^^^
  File "/home/airflow/.local/lib/python3.12/site-packages/airflow/models/baseoperator.py", line 406, in wrapper
    return func(self, *args, **kwargs)
           ^^^^^^^^^^^^^^^^^^^^^^^^^^^
  File "/home/airflow/.local/lib/python3.12/site-packages/airflow/operators/bash.py", line 249, in execute
    raise AirflowException(
airflow.exceptions.AirflowException: Bash command failed. The command returned a non-zero exit code 1.
[2024-11-06T12:07:45.813+0000] {taskinstance.py:1225} INFO - Marking task as FAILED. dag_id=dbt_project_with_ge_dag, task_id=ge_validate_obt_sales, run_id=manual__2024-11-06T12:05:53.813585+00:00, execution_date=20241106T120553, start_date=20241106T120736, end_date=20241106T120745
[2024-11-06T12:07:45.828+0000] {taskinstance.py:340} INFO - ::group::Post task execution logs
[2024-11-06T12:07:45.828+0000] {standard_task_runner.py:124} ERROR - Failed to execute job 173 for task ge_validate_obt_sales (Bash command failed. The command returned a non-zero exit code 1.; 2026)
Traceback (most recent call last):
  File "/home/airflow/.local/lib/python3.12/site-packages/airflow/task/task_runner/standard_task_runner.py", line 117, in _start_by_fork
    ret = args.func(args, dag=self.dag)
          ^^^^^^^^^^^^^^^^^^^^^^^^^^^^^
  File "/home/airflow/.local/lib/python3.12/site-packages/airflow/cli/cli_config.py", line 49, in command
    return func(*args, **kwargs)
           ^^^^^^^^^^^^^^^^^^^^^
  File "/home/airflow/.local/lib/python3.12/site-packages/airflow/utils/cli.py", line 115, in wrapper
    return f(*args, **kwargs)
           ^^^^^^^^^^^^^^^^^^
  File "/home/airflow/.local/lib/python3.12/site-packages/airflow/cli/commands/task_command.py", line 483, in task_run
    task_return_code = _run_task_by_selected_method(args, _dag, ti)
                       ^^^^^^^^^^^^^^^^^^^^^^^^^^^^^^^^^^^^^^^^^^^^
  File "/home/airflow/.local/lib/python3.12/site-packages/airflow/cli/commands/task_command.py", line 256, in _run_task_by_selected_method
    return _run_raw_task(args, ti)
           ^^^^^^^^^^^^^^^^^^^^^^^
  File "/home/airflow/.local/lib/python3.12/site-packages/airflow/cli/commands/task_command.py", line 341, in _run_raw_task
    return ti._run_raw_task(
           ^^^^^^^^^^^^^^^^^
  File "/home/airflow/.local/lib/python3.12/site-packages/airflow/utils/session.py", line 97, in wrapper
    return func(*args, session=session, **kwargs)
           ^^^^^^^^^^^^^^^^^^^^^^^^^^^^^^^^^^^^^^
  File "/home/airflow/.local/lib/python3.12/site-packages/airflow/models/taskinstance.py", line 3004, in _run_raw_task
    return _run_raw_task(
           ^^^^^^^^^^^^^^
  File "/home/airflow/.local/lib/python3.12/site-packages/airflow/models/taskinstance.py", line 273, in _run_raw_task
    TaskInstance._execute_task_with_callbacks(
  File "/home/airflow/.local/lib/python3.12/site-packages/airflow/models/taskinstance.py", line 3158, in _execute_task_with_callbacks
    result = self._execute_task(context, task_orig)
             ^^^^^^^^^^^^^^^^^^^^^^^^^^^^^^^^^^^^^^
  File "/home/airflow/.local/lib/python3.12/site-packages/airflow/models/taskinstance.py", line 3182, in _execute_task
    return _execute_task(self, context, task_orig)
           ^^^^^^^^^^^^^^^^^^^^^^^^^^^^^^^^^^^^^^^
  File "/home/airflow/.local/lib/python3.12/site-packages/airflow/models/taskinstance.py", line 767, in _execute_task
    result = _execute_callable(context=context, **execute_callable_kwargs)
             ^^^^^^^^^^^^^^^^^^^^^^^^^^^^^^^^^^^^^^^^^^^^^^^^^^^^^^^^^^^^^
  File "/home/airflow/.local/lib/python3.12/site-packages/airflow/models/taskinstance.py", line 733, in _execute_callable
    return ExecutionCallableRunner(
           ^^^^^^^^^^^^^^^^^^^^^^^^
  File "/home/airflow/.local/lib/python3.12/site-packages/airflow/utils/operator_helpers.py", line 252, in run
    return self.func(*args, **kwargs)
           ^^^^^^^^^^^^^^^^^^^^^^^^^^
  File "/home/airflow/.local/lib/python3.12/site-packages/airflow/models/baseoperator.py", line 406, in wrapper
    return func(self, *args, **kwargs)
           ^^^^^^^^^^^^^^^^^^^^^^^^^^^
  File "/home/airflow/.local/lib/python3.12/site-packages/airflow/operators/bash.py", line 249, in execute
    raise AirflowException(
airflow.exceptions.AirflowException: Bash command failed. The command returned a non-zero exit code 1.
[2024-11-06T12:07:45.844+0000] {local_task_job_runner.py:266} INFO - Task exited with return code 1
[2024-11-06T12:07:45.868+0000] {taskinstance.py:3900} INFO - 0 downstream tasks scheduled from follow-on schedule check
[2024-11-06T12:07:45.873+0000] {local_task_job_runner.py:245} INFO - ::endgroup::
