[2024-11-06T12:03:57.547+0000] {local_task_job_runner.py:123} INFO - ::group::Pre task execution logs
[2024-11-06T12:03:57.580+0000] {taskinstance.py:2612} INFO - Dependencies all met for dep_context=non-requeueable deps ti=<TaskInstance: dbt_project_with_ge_dag.ge_validate_obt_sales scheduled__2024-11-05T00:00:00+00:00 [queued]>
[2024-11-06T12:03:57.602+0000] {taskinstance.py:2612} INFO - Dependencies all met for dep_context=requeueable deps ti=<TaskInstance: dbt_project_with_ge_dag.ge_validate_obt_sales scheduled__2024-11-05T00:00:00+00:00 [queued]>
[2024-11-06T12:03:57.603+0000] {taskinstance.py:2865} INFO - Starting attempt 2 of 3
[2024-11-06T12:03:57.628+0000] {taskinstance.py:2888} INFO - Executing <Task(BashOperator): ge_validate_obt_sales> on 2024-11-05 00:00:00+00:00
[2024-11-06T12:03:57.640+0000] {standard_task_runner.py:104} INFO - Running: ['***', 'tasks', 'run', 'dbt_project_with_ge_dag', 'ge_validate_obt_sales', 'scheduled__2024-11-05T00:00:00+00:00', '--job-id', '166', '--raw', '--subdir', 'DAGS_FOLDER/dbt_project_dag.py', '--cfg-path', '/tmp/tmpuf0rxcv7']
[2024-11-06T12:03:57.637+0000] {warnings.py:112} WARNING - /home/***/.local/lib/python3.12/site-packages/***/task/task_runner/standard_task_runner.py:70: DeprecationWarning: This process (pid=1862) is multi-threaded, use of fork() may lead to deadlocks in the child.
  pid = os.fork()

[2024-11-06T12:03:57.642+0000] {standard_task_runner.py:105} INFO - Job 166: Subtask ge_validate_obt_sales
[2024-11-06T12:03:57.642+0000] {standard_task_runner.py:72} INFO - Started process 1863 to run task
[2024-11-06T12:03:57.765+0000] {task_command.py:467} INFO - Running <TaskInstance: dbt_project_with_ge_dag.ge_validate_obt_sales scheduled__2024-11-05T00:00:00+00:00 [running]> on host 9ecf534049e3
[2024-11-06T12:03:57.960+0000] {taskinstance.py:3131} INFO - Exporting env vars: AIRFLOW_CTX_DAG_OWNER='***' AIRFLOW_CTX_DAG_ID='dbt_project_with_ge_dag' AIRFLOW_CTX_TASK_ID='ge_validate_obt_sales' AIRFLOW_CTX_EXECUTION_DATE='2024-11-05T00:00:00+00:00' AIRFLOW_CTX_TRY_NUMBER='2' AIRFLOW_CTX_DAG_RUN_ID='scheduled__2024-11-05T00:00:00+00:00'
[2024-11-06T12:03:57.962+0000] {taskinstance.py:731} INFO - ::endgroup::
[2024-11-06T12:03:58.013+0000] {subprocess.py:63} INFO - Tmp dir root location: /tmp
[2024-11-06T12:03:58.014+0000] {subprocess.py:75} INFO - Running command: ['/usr/bin/bash', '-c', 'cd /opt/dbt && great_expectations checkpoint run obt_sales_checkpoint']
[2024-11-06T12:03:58.032+0000] {subprocess.py:86} INFO - Output:
[2024-11-06T12:04:16.802+0000] {subprocess.py:93} INFO - Calculating Metrics:   0%|          | 0/69 [00:00<?, ?it/s]Calculating Metrics:   0%|          | 0/69 [00:00<?, ?it/s]Calculating Metrics:   3%|▎         | 2/69 [00:00<00:00, 121.63it/s]Calculating Metrics:   3%|▎         | 2/69 [00:00<00:03, 18.49it/s] Calculating Metrics:   3%|▎         | 2/69 [00:00<00:03, 18.49it/s]Calculating Metrics:   6%|▌         | 4/69 [00:00<00:03, 18.49it/s]Calculating Metrics:   6%|▌         | 4/69 [00:00<00:03, 18.49it/s]Calculating Metrics:  25%|██▍       | 17/69 [00:00<00:00, 92.03it/s]Calculating Metrics:  25%|██▍       | 17/69 [00:00<00:00, 92.03it/s]Calculating Metrics:  25%|██▍       | 17/69 [00:00<00:00, 92.03it/s]Calculating Metrics:  83%|████████▎ | 57/69 [00:00<00:00, 151.55it/s]Calculating Metrics:  83%|████████▎ | 57/69 [00:00<00:00, 151.55it/s]Calculating Metrics:  83%|████████▎ | 57/69 [00:00<00:00, 151.55it/s]Calculating Metrics: 100%|██████████| 69/69 [00:00<00:00, 151.55it/s]Calculating Metrics: 100%|██████████| 69/69 [00:00<00:00, 151.55it/s]Calculating Metrics: 100%|██████████| 69/69 [00:00<00:00, 151.55it/s]Calculating Metrics: 100%|██████████| 69/69 [00:00<00:00, 126.93it/s]
[2024-11-06T12:04:16.948+0000] {subprocess.py:93} INFO - Error running action with name store_validation_result
[2024-11-06T12:04:16.950+0000] {subprocess.py:93} INFO - Traceback (most recent call last):
[2024-11-06T12:04:16.950+0000] {subprocess.py:93} INFO -   File "/home/***/.local/lib/python3.12/site-packages/great_expectations/validation_operators/validation_operators.py", line 476, in _run_actions
[2024-11-06T12:04:16.951+0000] {subprocess.py:93} INFO -     action_result = self.actions[name].run(
[2024-11-06T12:04:16.951+0000] {subprocess.py:93} INFO -                     ^^^^^^^^^^^^^^^^^^^^^^^
[2024-11-06T12:04:16.951+0000] {subprocess.py:93} INFO -   File "/home/***/.local/lib/python3.12/site-packages/great_expectations/checkpoint/actions.py", line 101, in run
[2024-11-06T12:04:16.952+0000] {subprocess.py:93} INFO -     return self._run(
[2024-11-06T12:04:16.953+0000] {subprocess.py:93} INFO -            ^^^^^^^^^^
[2024-11-06T12:04:16.954+0000] {subprocess.py:93} INFO -   File "/home/***/.local/lib/python3.12/site-packages/great_expectations/checkpoint/actions.py", line 898, in _run
[2024-11-06T12:04:16.955+0000] {subprocess.py:93} INFO -     run_return_value = self._basic_run(
[2024-11-06T12:04:16.955+0000] {subprocess.py:93} INFO -                        ^^^^^^^^^^^^^^^^
[2024-11-06T12:04:16.956+0000] {subprocess.py:93} INFO -   File "/home/***/.local/lib/python3.12/site-packages/great_expectations/checkpoint/actions.py", line 942, in _basic_run
[2024-11-06T12:04:16.956+0000] {subprocess.py:93} INFO -     return self.target_store.set(
[2024-11-06T12:04:16.956+0000] {subprocess.py:93} INFO -            ^^^^^^^^^^^^^^^^^^^^^^
[2024-11-06T12:04:16.958+0000] {subprocess.py:93} INFO -   File "/home/***/.local/lib/python3.12/site-packages/great_expectations/data_context/store/store.py", line 226, in set
[2024-11-06T12:04:16.959+0000] {subprocess.py:93} INFO -     return self._store_backend.set(
[2024-11-06T12:04:16.959+0000] {subprocess.py:93} INFO -            ^^^^^^^^^^^^^^^^^^^^^^^^
[2024-11-06T12:04:16.960+0000] {subprocess.py:93} INFO -   File "/home/***/.local/lib/python3.12/site-packages/great_expectations/data_context/store/_store_backend.py", line 134, in set
[2024-11-06T12:04:16.961+0000] {subprocess.py:93} INFO -     return self._set(key, value, **kwargs)
[2024-11-06T12:04:16.962+0000] {subprocess.py:93} INFO -            ^^^^^^^^^^^^^^^^^^^^^^^^^^^^^^^
[2024-11-06T12:04:16.963+0000] {subprocess.py:93} INFO -   File "/home/***/.local/lib/python3.12/site-packages/great_expectations/data_context/store/tuple_store_backend.py", line 329, in _set
[2024-11-06T12:04:16.963+0000] {subprocess.py:93} INFO -     os.makedirs(str(path), exist_ok=True)  # noqa: PTH103
[2024-11-06T12:04:16.964+0000] {subprocess.py:93} INFO -     ^^^^^^^^^^^^^^^^^^^^^^^^^^^^^^^^^^^^^
[2024-11-06T12:04:16.964+0000] {subprocess.py:93} INFO -   File "<frozen os>", line 215, in makedirs
[2024-11-06T12:04:16.965+0000] {subprocess.py:93} INFO -   File "<frozen os>", line 225, in makedirs
[2024-11-06T12:04:16.965+0000] {subprocess.py:93} INFO - PermissionError: [Errno 13] Permission denied: '/opt/dbt/gx/uncommitted/validations/obt_sales/basic/20241106-120415-obt_sales-checkpoint'
[2024-11-06T12:04:16.966+0000] {subprocess.py:93} INFO - [Errno 13] Permission denied: '/opt/dbt/gx/uncommitted/validations/obt_sales/basic/20241106-120415-obt_sales-checkpoint'
[2024-11-06T12:04:21.466+0000] {subprocess.py:97} INFO - Command exited with return code 1
[2024-11-06T12:04:21.526+0000] {taskinstance.py:3310} ERROR - Task failed with exception
Traceback (most recent call last):
  File "/home/airflow/.local/lib/python3.12/site-packages/airflow/models/taskinstance.py", line 767, in _execute_task
    result = _execute_callable(context=context, **execute_callable_kwargs)
             ^^^^^^^^^^^^^^^^^^^^^^^^^^^^^^^^^^^^^^^^^^^^^^^^^^^^^^^^^^^^^
  File "/home/airflow/.local/lib/python3.12/site-packages/airflow/models/taskinstance.py", line 733, in _execute_callable
    return ExecutionCallableRunner(
           ^^^^^^^^^^^^^^^^^^^^^^^^
  File "/home/airflow/.local/lib/python3.12/site-packages/airflow/utils/operator_helpers.py", line 252, in run
    return self.func(*args, **kwargs)
           ^^^^^^^^^^^^^^^^^^^^^^^^^^
  File "/home/airflow/.local/lib/python3.12/site-packages/airflow/models/baseoperator.py", line 406, in wrapper
    return func(self, *args, **kwargs)
           ^^^^^^^^^^^^^^^^^^^^^^^^^^^
  File "/home/airflow/.local/lib/python3.12/site-packages/airflow/operators/bash.py", line 249, in execute
    raise AirflowException(
airflow.exceptions.AirflowException: Bash command failed. The command returned a non-zero exit code 1.
[2024-11-06T12:04:21.574+0000] {taskinstance.py:1225} INFO - Marking task as UP_FOR_RETRY. dag_id=dbt_project_with_ge_dag, task_id=ge_validate_obt_sales, run_id=scheduled__2024-11-05T00:00:00+00:00, execution_date=20241105T000000, start_date=20241106T120357, end_date=20241106T120421
[2024-11-06T12:04:21.618+0000] {taskinstance.py:340} INFO - ::group::Post task execution logs
[2024-11-06T12:04:21.619+0000] {standard_task_runner.py:124} ERROR - Failed to execute job 166 for task ge_validate_obt_sales (Bash command failed. The command returned a non-zero exit code 1.; 1863)
Traceback (most recent call last):
  File "/home/airflow/.local/lib/python3.12/site-packages/airflow/task/task_runner/standard_task_runner.py", line 117, in _start_by_fork
    ret = args.func(args, dag=self.dag)
          ^^^^^^^^^^^^^^^^^^^^^^^^^^^^^
  File "/home/airflow/.local/lib/python3.12/site-packages/airflow/cli/cli_config.py", line 49, in command
    return func(*args, **kwargs)
           ^^^^^^^^^^^^^^^^^^^^^
  File "/home/airflow/.local/lib/python3.12/site-packages/airflow/utils/cli.py", line 115, in wrapper
    return f(*args, **kwargs)
           ^^^^^^^^^^^^^^^^^^
  File "/home/airflow/.local/lib/python3.12/site-packages/airflow/cli/commands/task_command.py", line 483, in task_run
    task_return_code = _run_task_by_selected_method(args, _dag, ti)
                       ^^^^^^^^^^^^^^^^^^^^^^^^^^^^^^^^^^^^^^^^^^^^
  File "/home/airflow/.local/lib/python3.12/site-packages/airflow/cli/commands/task_command.py", line 256, in _run_task_by_selected_method
    return _run_raw_task(args, ti)
           ^^^^^^^^^^^^^^^^^^^^^^^
  File "/home/airflow/.local/lib/python3.12/site-packages/airflow/cli/commands/task_command.py", line 341, in _run_raw_task
    return ti._run_raw_task(
           ^^^^^^^^^^^^^^^^^
  File "/home/airflow/.local/lib/python3.12/site-packages/airflow/utils/session.py", line 97, in wrapper
    return func(*args, session=session, **kwargs)
           ^^^^^^^^^^^^^^^^^^^^^^^^^^^^^^^^^^^^^^
  File "/home/airflow/.local/lib/python3.12/site-packages/airflow/models/taskinstance.py", line 3004, in _run_raw_task
    return _run_raw_task(
           ^^^^^^^^^^^^^^
  File "/home/airflow/.local/lib/python3.12/site-packages/airflow/models/taskinstance.py", line 273, in _run_raw_task
    TaskInstance._execute_task_with_callbacks(
  File "/home/airflow/.local/lib/python3.12/site-packages/airflow/models/taskinstance.py", line 3158, in _execute_task_with_callbacks
    result = self._execute_task(context, task_orig)
             ^^^^^^^^^^^^^^^^^^^^^^^^^^^^^^^^^^^^^^
  File "/home/airflow/.local/lib/python3.12/site-packages/airflow/models/taskinstance.py", line 3182, in _execute_task
    return _execute_task(self, context, task_orig)
           ^^^^^^^^^^^^^^^^^^^^^^^^^^^^^^^^^^^^^^^
  File "/home/airflow/.local/lib/python3.12/site-packages/airflow/models/taskinstance.py", line 767, in _execute_task
    result = _execute_callable(context=context, **execute_callable_kwargs)
             ^^^^^^^^^^^^^^^^^^^^^^^^^^^^^^^^^^^^^^^^^^^^^^^^^^^^^^^^^^^^^
  File "/home/airflow/.local/lib/python3.12/site-packages/airflow/models/taskinstance.py", line 733, in _execute_callable
    return ExecutionCallableRunner(
           ^^^^^^^^^^^^^^^^^^^^^^^^
  File "/home/airflow/.local/lib/python3.12/site-packages/airflow/utils/operator_helpers.py", line 252, in run
    return self.func(*args, **kwargs)
           ^^^^^^^^^^^^^^^^^^^^^^^^^^
  File "/home/airflow/.local/lib/python3.12/site-packages/airflow/models/baseoperator.py", line 406, in wrapper
    return func(self, *args, **kwargs)
           ^^^^^^^^^^^^^^^^^^^^^^^^^^^
  File "/home/airflow/.local/lib/python3.12/site-packages/airflow/operators/bash.py", line 249, in execute
    raise AirflowException(
airflow.exceptions.AirflowException: Bash command failed. The command returned a non-zero exit code 1.
[2024-11-06T12:04:21.662+0000] {local_task_job_runner.py:266} INFO - Task exited with return code 1
[2024-11-06T12:04:21.716+0000] {taskinstance.py:3900} INFO - 0 downstream tasks scheduled from follow-on schedule check
[2024-11-06T12:04:21.733+0000] {local_task_job_runner.py:245} INFO - ::endgroup::
[2024-11-06T12:09:11.413+0000] {local_task_job_runner.py:123} INFO - ::group::Pre task execution logs
[2024-11-06T12:09:11.434+0000] {taskinstance.py:2612} INFO - Dependencies all met for dep_context=non-requeueable deps ti=<TaskInstance: dbt_project_with_ge_dag.ge_validate_obt_sales scheduled__2024-11-05T00:00:00+00:00 [queued]>
[2024-11-06T12:09:11.444+0000] {taskinstance.py:2612} INFO - Dependencies all met for dep_context=requeueable deps ti=<TaskInstance: dbt_project_with_ge_dag.ge_validate_obt_sales scheduled__2024-11-05T00:00:00+00:00 [queued]>
[2024-11-06T12:09:11.445+0000] {taskinstance.py:2865} INFO - Starting attempt 2 of 3
[2024-11-06T12:09:11.463+0000] {taskinstance.py:2888} INFO - Executing <Task(BashOperator): ge_validate_obt_sales> on 2024-11-05 00:00:00+00:00
[2024-11-06T12:09:11.470+0000] {warnings.py:112} WARNING - /home/***/.local/lib/python3.12/site-packages/***/task/task_runner/standard_task_runner.py:70: DeprecationWarning: This process (pid=2129) is multi-threaded, use of fork() may lead to deadlocks in the child.
  pid = os.fork()

[2024-11-06T12:09:11.471+0000] {standard_task_runner.py:72} INFO - Started process 2130 to run task
[2024-11-06T12:09:11.472+0000] {standard_task_runner.py:104} INFO - Running: ['***', 'tasks', 'run', 'dbt_project_with_ge_dag', 'ge_validate_obt_sales', 'scheduled__2024-11-05T00:00:00+00:00', '--job-id', '178', '--raw', '--subdir', 'DAGS_FOLDER/dbt_project_dag.py', '--cfg-path', '/tmp/tmpw_a1yy1d']
[2024-11-06T12:09:11.474+0000] {standard_task_runner.py:105} INFO - Job 178: Subtask ge_validate_obt_sales
[2024-11-06T12:09:11.529+0000] {task_command.py:467} INFO - Running <TaskInstance: dbt_project_with_ge_dag.ge_validate_obt_sales scheduled__2024-11-05T00:00:00+00:00 [running]> on host 9ecf534049e3
[2024-11-06T12:09:11.618+0000] {taskinstance.py:3131} INFO - Exporting env vars: AIRFLOW_CTX_DAG_OWNER='***' AIRFLOW_CTX_DAG_ID='dbt_project_with_ge_dag' AIRFLOW_CTX_TASK_ID='ge_validate_obt_sales' AIRFLOW_CTX_EXECUTION_DATE='2024-11-05T00:00:00+00:00' AIRFLOW_CTX_TRY_NUMBER='2' AIRFLOW_CTX_DAG_RUN_ID='scheduled__2024-11-05T00:00:00+00:00'
[2024-11-06T12:09:11.619+0000] {taskinstance.py:731} INFO - ::endgroup::
[2024-11-06T12:09:11.638+0000] {subprocess.py:63} INFO - Tmp dir root location: /tmp
[2024-11-06T12:09:11.639+0000] {subprocess.py:75} INFO - Running command: ['/usr/bin/bash', '-c', 'cd /opt/dbt && great_expectations checkpoint run obt_sales_checkpoint']
[2024-11-06T12:09:11.653+0000] {subprocess.py:86} INFO - Output:
[2024-11-06T12:09:19.364+0000] {subprocess.py:93} INFO - Calculating Metrics:   0%|          | 0/69 [00:00<?, ?it/s]Calculating Metrics:   0%|          | 0/69 [00:00<?, ?it/s]Calculating Metrics:   3%|▎         | 2/69 [00:00<00:00, 228.11it/s]Calculating Metrics:   3%|▎         | 2/69 [00:00<00:01, 34.54it/s] Calculating Metrics:   6%|▌         | 4/69 [00:00<00:01, 64.49it/s]Calculating Metrics:   6%|▌         | 4/69 [00:00<00:01, 36.65it/s]Calculating Metrics:   6%|▌         | 4/69 [00:00<00:01, 36.65it/s]Calculating Metrics:  25%|██▍       | 17/69 [00:00<00:01, 36.65it/s]Calculating Metrics:  25%|██▍       | 17/69 [00:00<00:01, 36.65it/s]Calculating Metrics:  83%|████████▎ | 57/69 [00:00<00:00, 286.26it/s]Calculating Metrics:  83%|████████▎ | 57/69 [00:00<00:00, 286.26it/s]Calculating Metrics:  83%|████████▎ | 57/69 [00:00<00:00, 286.26it/s]Calculating Metrics: 100%|██████████| 69/69 [00:00<00:00, 286.26it/s]Calculating Metrics: 100%|██████████| 69/69 [00:00<00:00, 286.26it/s]Calculating Metrics: 100%|██████████| 69/69 [00:00<00:00, 286.26it/s]Calculating Metrics: 100%|██████████| 69/69 [00:00<00:00, 238.78it/s]
[2024-11-06T12:09:19.569+0000] {subprocess.py:93} INFO - An unexpected Exception occurred during data docs rendering.  Because of this error, certain parts of data docs will not be rendered properly and/or may not appear altogether.  Please use the trace, included in this message, to diagnose and repair the underlying issue.  Detailed information follows:
[2024-11-06T12:09:19.569+0000] {subprocess.py:93} INFO -                 PermissionError: "[Errno 13] Permission denied: '/opt/dbt/gx/uncommitted/data_docs/local_site/expectations/obt_sales/basic.html'".  Traceback: "Traceback (most recent call last):
[2024-11-06T12:09:19.569+0000] {subprocess.py:93} INFO -   File "/home/***/.local/lib/python3.12/site-packages/great_expectations/render/renderer/site_builder.py", line 501, in build
[2024-11-06T12:09:19.570+0000] {subprocess.py:93} INFO -     self.target_store.set(
[2024-11-06T12:09:19.570+0000] {subprocess.py:93} INFO -   File "/home/***/.local/lib/python3.12/site-packages/great_expectations/data_context/store/html_site_store.py", line 269, in set
[2024-11-06T12:09:19.571+0000] {subprocess.py:93} INFO -     return self.store_backends[type(key.resource_identifier)].set(
[2024-11-06T12:09:19.571+0000] {subprocess.py:93} INFO -            ^^^^^^^^^^^^^^^^^^^^^^^^^^^^^^^^^^^^^^^^^^^^^^^^^^^^^^^
[2024-11-06T12:09:19.572+0000] {subprocess.py:93} INFO -   File "/home/***/.local/lib/python3.12/site-packages/great_expectations/data_context/store/_store_backend.py", line 134, in set
[2024-11-06T12:09:19.573+0000] {subprocess.py:93} INFO -     return self._set(key, value, **kwargs)
[2024-11-06T12:09:19.574+0000] {subprocess.py:93} INFO -            ^^^^^^^^^^^^^^^^^^^^^^^^^^^^^^^
[2024-11-06T12:09:19.575+0000] {subprocess.py:93} INFO -   File "/home/***/.local/lib/python3.12/site-packages/great_expectations/data_context/store/tuple_store_backend.py", line 330, in _set
[2024-11-06T12:09:19.575+0000] {subprocess.py:93} INFO -     with open(filepath, "wb") as outfile:
[2024-11-06T12:09:19.576+0000] {subprocess.py:93} INFO -          ^^^^^^^^^^^^^^^^^^^^
[2024-11-06T12:09:19.576+0000] {subprocess.py:93} INFO - PermissionError: [Errno 13] Permission denied: '/opt/dbt/gx/uncommitted/data_docs/local_site/expectations/obt_sales/basic.html'
[2024-11-06T12:09:19.576+0000] {subprocess.py:93} INFO - ".
[2024-11-06T12:09:19.713+0000] {subprocess.py:93} INFO - An unexpected Exception occurred during data docs rendering.  Because of this error, certain parts of data docs will not be rendered properly and/or may not appear altogether.  Please use the trace, included in this message, to diagnose and repair the underlying issue.  Detailed information follows:
[2024-11-06T12:09:19.713+0000] {subprocess.py:93} INFO -                 PermissionError: "[Errno 13] Permission denied: '/opt/dbt/gx/uncommitted/data_docs/local_site/validations/obt_sales/basic/20241106-120918-obt_sales-checkpoint'".  Traceback: "Traceback (most recent call last):
[2024-11-06T12:09:19.714+0000] {subprocess.py:93} INFO -   File "/home/***/.local/lib/python3.12/site-packages/great_expectations/render/renderer/site_builder.py", line 501, in build
[2024-11-06T12:09:19.714+0000] {subprocess.py:93} INFO -     self.target_store.set(
[2024-11-06T12:09:19.714+0000] {subprocess.py:93} INFO -   File "/home/***/.local/lib/python3.12/site-packages/great_expectations/data_context/store/html_site_store.py", line 269, in set
[2024-11-06T12:09:19.715+0000] {subprocess.py:93} INFO -     return self.store_backends[type(key.resource_identifier)].set(
[2024-11-06T12:09:19.715+0000] {subprocess.py:93} INFO -            ^^^^^^^^^^^^^^^^^^^^^^^^^^^^^^^^^^^^^^^^^^^^^^^^^^^^^^^
[2024-11-06T12:09:19.716+0000] {subprocess.py:93} INFO -   File "/home/***/.local/lib/python3.12/site-packages/great_expectations/data_context/store/_store_backend.py", line 134, in set
[2024-11-06T12:09:19.716+0000] {subprocess.py:93} INFO -     return self._set(key, value, **kwargs)
[2024-11-06T12:09:19.716+0000] {subprocess.py:93} INFO -            ^^^^^^^^^^^^^^^^^^^^^^^^^^^^^^^
[2024-11-06T12:09:19.717+0000] {subprocess.py:93} INFO -   File "/home/***/.local/lib/python3.12/site-packages/great_expectations/data_context/store/tuple_store_backend.py", line 329, in _set
[2024-11-06T12:09:19.717+0000] {subprocess.py:93} INFO -     os.makedirs(str(path), exist_ok=True)  # noqa: PTH103
[2024-11-06T12:09:19.718+0000] {subprocess.py:93} INFO -     ^^^^^^^^^^^^^^^^^^^^^^^^^^^^^^^^^^^^^
[2024-11-06T12:09:19.718+0000] {subprocess.py:93} INFO -   File "<frozen os>", line 215, in makedirs
[2024-11-06T12:09:19.718+0000] {subprocess.py:93} INFO -   File "<frozen os>", line 225, in makedirs
[2024-11-06T12:09:19.719+0000] {subprocess.py:93} INFO - PermissionError: [Errno 13] Permission denied: '/opt/dbt/gx/uncommitted/data_docs/local_site/validations/obt_sales/basic/20241106-120918-obt_sales-checkpoint'
[2024-11-06T12:09:19.719+0000] {subprocess.py:93} INFO - ".
[2024-11-06T12:09:19.732+0000] {subprocess.py:93} INFO - Error running action with name update_data_docs
[2024-11-06T12:09:19.733+0000] {subprocess.py:93} INFO - Traceback (most recent call last):
[2024-11-06T12:09:19.734+0000] {subprocess.py:93} INFO -   File "/home/***/.local/lib/python3.12/site-packages/great_expectations/validation_operators/validation_operators.py", line 476, in _run_actions
[2024-11-06T12:09:19.734+0000] {subprocess.py:93} INFO -     action_result = self.actions[name].run(
[2024-11-06T12:09:19.735+0000] {subprocess.py:93} INFO -                     ^^^^^^^^^^^^^^^^^^^^^^^
[2024-11-06T12:09:19.735+0000] {subprocess.py:93} INFO -   File "/home/***/.local/lib/python3.12/site-packages/great_expectations/checkpoint/actions.py", line 101, in run
[2024-11-06T12:09:19.735+0000] {subprocess.py:93} INFO -     return self._run(
[2024-11-06T12:09:19.736+0000] {subprocess.py:93} INFO -            ^^^^^^^^^^
[2024-11-06T12:09:19.736+0000] {subprocess.py:93} INFO -   File "/home/***/.local/lib/python3.12/site-packages/great_expectations/checkpoint/actions.py", line 1190, in _run
[2024-11-06T12:09:19.737+0000] {subprocess.py:93} INFO -     self.data_context.build_data_docs(
[2024-11-06T12:09:19.737+0000] {subprocess.py:93} INFO -   File "/home/***/.local/lib/python3.12/site-packages/great_expectations/core/usage_statistics/usage_statistics.py", line 266, in usage_statistics_wrapped_method
[2024-11-06T12:09:19.737+0000] {subprocess.py:93} INFO -     result = func(*args, **kwargs)
[2024-11-06T12:09:19.738+0000] {subprocess.py:93} INFO -              ^^^^^^^^^^^^^^^^^^^^^
[2024-11-06T12:09:19.738+0000] {subprocess.py:93} INFO -   File "/home/***/.local/lib/python3.12/site-packages/great_expectations/data_context/data_context/abstract_data_context.py", line 5318, in build_data_docs
[2024-11-06T12:09:19.739+0000] {subprocess.py:93} INFO -     return self._build_data_docs(
[2024-11-06T12:09:19.740+0000] {subprocess.py:93} INFO -            ^^^^^^^^^^^^^^^^^^^^^^
[2024-11-06T12:09:19.741+0000] {subprocess.py:93} INFO -   File "/home/***/.local/lib/python3.12/site-packages/great_expectations/data_context/data_context/abstract_data_context.py", line 5365, in _build_data_docs
[2024-11-06T12:09:19.741+0000] {subprocess.py:93} INFO -     index_page_resource_identifier_tuple = site_builder.build(
[2024-11-06T12:09:19.742+0000] {subprocess.py:93} INFO -                                            ^^^^^^^^^^^^^^^^^^^
[2024-11-06T12:09:19.742+0000] {subprocess.py:93} INFO -   File "/home/***/.local/lib/python3.12/site-packages/great_expectations/render/renderer/site_builder.py", line 329, in build
[2024-11-06T12:09:19.743+0000] {subprocess.py:93} INFO -     self.target_store.copy_static_assets()
[2024-11-06T12:09:19.743+0000] {subprocess.py:93} INFO -   File "/home/***/.local/lib/python3.12/site-packages/great_expectations/data_context/store/html_site_store.py", line 412, in copy_static_assets
[2024-11-06T12:09:19.744+0000] {subprocess.py:93} INFO -     self.copy_static_assets(new_source_dir)
[2024-11-06T12:09:19.744+0000] {subprocess.py:93} INFO -   File "/home/***/.local/lib/python3.12/site-packages/great_expectations/data_context/store/html_site_store.py", line 441, in copy_static_assets
[2024-11-06T12:09:19.745+0000] {subprocess.py:93} INFO -     self.store_backends["static_assets"].set(
[2024-11-06T12:09:19.745+0000] {subprocess.py:93} INFO -   File "/home/***/.local/lib/python3.12/site-packages/great_expectations/data_context/store/_store_backend.py", line 134, in set
[2024-11-06T12:09:19.746+0000] {subprocess.py:93} INFO -     return self._set(key, value, **kwargs)
[2024-11-06T12:09:19.746+0000] {subprocess.py:93} INFO -            ^^^^^^^^^^^^^^^^^^^^^^^^^^^^^^^
[2024-11-06T12:09:19.746+0000] {subprocess.py:93} INFO -   File "/home/***/.local/lib/python3.12/site-packages/great_expectations/data_context/store/tuple_store_backend.py", line 330, in _set
[2024-11-06T12:09:19.747+0000] {subprocess.py:93} INFO -     with open(filepath, "wb") as outfile:
[2024-11-06T12:09:19.747+0000] {subprocess.py:93} INFO -          ^^^^^^^^^^^^^^^^^^^^
[2024-11-06T12:09:19.747+0000] {subprocess.py:93} INFO - PermissionError: [Errno 13] Permission denied: '/opt/dbt/gx/uncommitted/data_docs/local_site/static/styles/data_docs_default_styles.css'
[2024-11-06T12:09:19.748+0000] {subprocess.py:93} INFO - [Errno 13] Permission denied: '/opt/dbt/gx/uncommitted/data_docs/local_site/static/styles/data_docs_default_styles.css'
[2024-11-06T12:09:20.763+0000] {subprocess.py:97} INFO - Command exited with return code 1
[2024-11-06T12:09:20.782+0000] {taskinstance.py:3310} ERROR - Task failed with exception
Traceback (most recent call last):
  File "/home/airflow/.local/lib/python3.12/site-packages/airflow/models/taskinstance.py", line 767, in _execute_task
    result = _execute_callable(context=context, **execute_callable_kwargs)
             ^^^^^^^^^^^^^^^^^^^^^^^^^^^^^^^^^^^^^^^^^^^^^^^^^^^^^^^^^^^^^
  File "/home/airflow/.local/lib/python3.12/site-packages/airflow/models/taskinstance.py", line 733, in _execute_callable
    return ExecutionCallableRunner(
           ^^^^^^^^^^^^^^^^^^^^^^^^
  File "/home/airflow/.local/lib/python3.12/site-packages/airflow/utils/operator_helpers.py", line 252, in run
    return self.func(*args, **kwargs)
           ^^^^^^^^^^^^^^^^^^^^^^^^^^
  File "/home/airflow/.local/lib/python3.12/site-packages/airflow/models/baseoperator.py", line 406, in wrapper
    return func(self, *args, **kwargs)
           ^^^^^^^^^^^^^^^^^^^^^^^^^^^
  File "/home/airflow/.local/lib/python3.12/site-packages/airflow/operators/bash.py", line 249, in execute
    raise AirflowException(
airflow.exceptions.AirflowException: Bash command failed. The command returned a non-zero exit code 1.
[2024-11-06T12:09:20.798+0000] {taskinstance.py:1225} INFO - Marking task as UP_FOR_RETRY. dag_id=dbt_project_with_ge_dag, task_id=ge_validate_obt_sales, run_id=scheduled__2024-11-05T00:00:00+00:00, execution_date=20241105T000000, start_date=20241106T120911, end_date=20241106T120920
[2024-11-06T12:09:20.829+0000] {taskinstance.py:340} INFO - ::group::Post task execution logs
[2024-11-06T12:09:20.830+0000] {standard_task_runner.py:124} ERROR - Failed to execute job 178 for task ge_validate_obt_sales (Bash command failed. The command returned a non-zero exit code 1.; 2130)
Traceback (most recent call last):
  File "/home/airflow/.local/lib/python3.12/site-packages/airflow/task/task_runner/standard_task_runner.py", line 117, in _start_by_fork
    ret = args.func(args, dag=self.dag)
          ^^^^^^^^^^^^^^^^^^^^^^^^^^^^^
  File "/home/airflow/.local/lib/python3.12/site-packages/airflow/cli/cli_config.py", line 49, in command
    return func(*args, **kwargs)
           ^^^^^^^^^^^^^^^^^^^^^
  File "/home/airflow/.local/lib/python3.12/site-packages/airflow/utils/cli.py", line 115, in wrapper
    return f(*args, **kwargs)
           ^^^^^^^^^^^^^^^^^^
  File "/home/airflow/.local/lib/python3.12/site-packages/airflow/cli/commands/task_command.py", line 483, in task_run
    task_return_code = _run_task_by_selected_method(args, _dag, ti)
                       ^^^^^^^^^^^^^^^^^^^^^^^^^^^^^^^^^^^^^^^^^^^^
  File "/home/airflow/.local/lib/python3.12/site-packages/airflow/cli/commands/task_command.py", line 256, in _run_task_by_selected_method
    return _run_raw_task(args, ti)
           ^^^^^^^^^^^^^^^^^^^^^^^
  File "/home/airflow/.local/lib/python3.12/site-packages/airflow/cli/commands/task_command.py", line 341, in _run_raw_task
    return ti._run_raw_task(
           ^^^^^^^^^^^^^^^^^
  File "/home/airflow/.local/lib/python3.12/site-packages/airflow/utils/session.py", line 97, in wrapper
    return func(*args, session=session, **kwargs)
           ^^^^^^^^^^^^^^^^^^^^^^^^^^^^^^^^^^^^^^
  File "/home/airflow/.local/lib/python3.12/site-packages/airflow/models/taskinstance.py", line 3004, in _run_raw_task
    return _run_raw_task(
           ^^^^^^^^^^^^^^
  File "/home/airflow/.local/lib/python3.12/site-packages/airflow/models/taskinstance.py", line 273, in _run_raw_task
    TaskInstance._execute_task_with_callbacks(
  File "/home/airflow/.local/lib/python3.12/site-packages/airflow/models/taskinstance.py", line 3158, in _execute_task_with_callbacks
    result = self._execute_task(context, task_orig)
             ^^^^^^^^^^^^^^^^^^^^^^^^^^^^^^^^^^^^^^
  File "/home/airflow/.local/lib/python3.12/site-packages/airflow/models/taskinstance.py", line 3182, in _execute_task
    return _execute_task(self, context, task_orig)
           ^^^^^^^^^^^^^^^^^^^^^^^^^^^^^^^^^^^^^^^
  File "/home/airflow/.local/lib/python3.12/site-packages/airflow/models/taskinstance.py", line 767, in _execute_task
    result = _execute_callable(context=context, **execute_callable_kwargs)
             ^^^^^^^^^^^^^^^^^^^^^^^^^^^^^^^^^^^^^^^^^^^^^^^^^^^^^^^^^^^^^
  File "/home/airflow/.local/lib/python3.12/site-packages/airflow/models/taskinstance.py", line 733, in _execute_callable
    return ExecutionCallableRunner(
           ^^^^^^^^^^^^^^^^^^^^^^^^
  File "/home/airflow/.local/lib/python3.12/site-packages/airflow/utils/operator_helpers.py", line 252, in run
    return self.func(*args, **kwargs)
           ^^^^^^^^^^^^^^^^^^^^^^^^^^
  File "/home/airflow/.local/lib/python3.12/site-packages/airflow/models/baseoperator.py", line 406, in wrapper
    return func(self, *args, **kwargs)
           ^^^^^^^^^^^^^^^^^^^^^^^^^^^
  File "/home/airflow/.local/lib/python3.12/site-packages/airflow/operators/bash.py", line 249, in execute
    raise AirflowException(
airflow.exceptions.AirflowException: Bash command failed. The command returned a non-zero exit code 1.
[2024-11-06T12:09:20.865+0000] {local_task_job_runner.py:266} INFO - Task exited with return code 1
[2024-11-06T12:09:20.895+0000] {taskinstance.py:3900} INFO - 0 downstream tasks scheduled from follow-on schedule check
[2024-11-06T12:09:20.897+0000] {local_task_job_runner.py:245} INFO - ::endgroup::
[2024-11-06T12:23:46.984+0000] {local_task_job_runner.py:123} INFO - ::group::Pre task execution logs
[2024-11-06T12:23:47.036+0000] {taskinstance.py:2612} INFO - Dependencies all met for dep_context=non-requeueable deps ti=<TaskInstance: dbt_project_with_ge_dag.ge_validate_obt_sales scheduled__2024-11-05T00:00:00+00:00 [queued]>
[2024-11-06T12:23:47.060+0000] {taskinstance.py:2612} INFO - Dependencies all met for dep_context=requeueable deps ti=<TaskInstance: dbt_project_with_ge_dag.ge_validate_obt_sales scheduled__2024-11-05T00:00:00+00:00 [queued]>
[2024-11-06T12:23:47.060+0000] {taskinstance.py:2865} INFO - Starting attempt 2 of 3
[2024-11-06T12:23:47.097+0000] {taskinstance.py:2888} INFO - Executing <Task(BashOperator): ge_validate_obt_sales> on 2024-11-05 00:00:00+00:00
[2024-11-06T12:23:47.108+0000] {warnings.py:112} WARNING - /home/***/.local/lib/python3.12/site-packages/***/task/task_runner/standard_task_runner.py:70: DeprecationWarning: This process (pid=2414) is multi-threaded, use of fork() may lead to deadlocks in the child.
  pid = os.fork()

[2024-11-06T12:23:47.110+0000] {standard_task_runner.py:104} INFO - Running: ['***', 'tasks', 'run', 'dbt_project_with_ge_dag', 'ge_validate_obt_sales', 'scheduled__2024-11-05T00:00:00+00:00', '--job-id', '184', '--raw', '--subdir', 'DAGS_FOLDER/dbt_project_dag.py', '--cfg-path', '/tmp/tmp3s_5ky1t']
[2024-11-06T12:23:47.112+0000] {standard_task_runner.py:72} INFO - Started process 2415 to run task
[2024-11-06T12:23:47.112+0000] {standard_task_runner.py:105} INFO - Job 184: Subtask ge_validate_obt_sales
[2024-11-06T12:23:47.213+0000] {task_command.py:467} INFO - Running <TaskInstance: dbt_project_with_ge_dag.ge_validate_obt_sales scheduled__2024-11-05T00:00:00+00:00 [running]> on host 9ecf534049e3
[2024-11-06T12:23:47.409+0000] {taskinstance.py:3131} INFO - Exporting env vars: AIRFLOW_CTX_DAG_OWNER='***' AIRFLOW_CTX_DAG_ID='dbt_project_with_ge_dag' AIRFLOW_CTX_TASK_ID='ge_validate_obt_sales' AIRFLOW_CTX_EXECUTION_DATE='2024-11-05T00:00:00+00:00' AIRFLOW_CTX_TRY_NUMBER='2' AIRFLOW_CTX_DAG_RUN_ID='scheduled__2024-11-05T00:00:00+00:00'
[2024-11-06T12:23:47.411+0000] {taskinstance.py:731} INFO - ::endgroup::
[2024-11-06T12:23:47.447+0000] {subprocess.py:63} INFO - Tmp dir root location: /tmp
[2024-11-06T12:23:47.448+0000] {subprocess.py:75} INFO - Running command: ['/usr/bin/bash', '-c', 'cd /opt/dbt && great_expectations checkpoint run obt_sales_checkpoint']
[2024-11-06T12:23:47.462+0000] {subprocess.py:86} INFO - Output:
[2024-11-06T12:23:55.513+0000] {subprocess.py:93} INFO - Calculating Metrics:   0%|          | 0/69 [00:00<?, ?it/s]Calculating Metrics:   0%|          | 0/69 [00:00<?, ?it/s]Calculating Metrics:   3%|▎         | 2/69 [00:00<00:00, 249.16it/s]Calculating Metrics:   3%|▎         | 2/69 [00:00<00:01, 33.66it/s] Calculating Metrics:   6%|▌         | 4/69 [00:00<00:01, 62.91it/s]Calculating Metrics:   6%|▌         | 4/69 [00:00<00:02, 32.01it/s]Calculating Metrics:   6%|▌         | 4/69 [00:00<00:02, 32.01it/s]Calculating Metrics:  25%|██▍       | 17/69 [00:00<00:01, 32.01it/s]Calculating Metrics:  25%|██▍       | 17/69 [00:00<00:01, 32.01it/s]Calculating Metrics:  83%|████████▎ | 57/69 [00:00<00:00, 233.17it/s]Calculating Metrics:  83%|████████▎ | 57/69 [00:00<00:00, 233.17it/s]Calculating Metrics:  83%|████████▎ | 57/69 [00:00<00:00, 233.17it/s]Calculating Metrics: 100%|██████████| 69/69 [00:00<00:00, 233.17it/s]Calculating Metrics: 100%|██████████| 69/69 [00:00<00:00, 233.17it/s]Calculating Metrics: 100%|██████████| 69/69 [00:00<00:00, 233.17it/s]Calculating Metrics: 100%|██████████| 69/69 [00:00<00:00, 200.87it/s]
[2024-11-06T12:23:55.750+0000] {subprocess.py:93} INFO - An unexpected Exception occurred during data docs rendering.  Because of this error, certain parts of data docs will not be rendered properly and/or may not appear altogether.  Please use the trace, included in this message, to diagnose and repair the underlying issue.  Detailed information follows:
[2024-11-06T12:23:55.751+0000] {subprocess.py:93} INFO -                 PermissionError: "[Errno 13] Permission denied: '/opt/dbt/gx/uncommitted/data_docs/local_site/expectations/obt_sales/basic.html'".  Traceback: "Traceback (most recent call last):
[2024-11-06T12:23:55.751+0000] {subprocess.py:93} INFO -   File "/home/***/.local/lib/python3.12/site-packages/great_expectations/render/renderer/site_builder.py", line 501, in build
[2024-11-06T12:23:55.751+0000] {subprocess.py:93} INFO -     self.target_store.set(
[2024-11-06T12:23:55.752+0000] {subprocess.py:93} INFO -   File "/home/***/.local/lib/python3.12/site-packages/great_expectations/data_context/store/html_site_store.py", line 269, in set
[2024-11-06T12:23:55.752+0000] {subprocess.py:93} INFO -     return self.store_backends[type(key.resource_identifier)].set(
[2024-11-06T12:23:55.752+0000] {subprocess.py:93} INFO -            ^^^^^^^^^^^^^^^^^^^^^^^^^^^^^^^^^^^^^^^^^^^^^^^^^^^^^^^
[2024-11-06T12:23:55.752+0000] {subprocess.py:93} INFO -   File "/home/***/.local/lib/python3.12/site-packages/great_expectations/data_context/store/_store_backend.py", line 134, in set
[2024-11-06T12:23:55.753+0000] {subprocess.py:93} INFO -     return self._set(key, value, **kwargs)
[2024-11-06T12:23:55.753+0000] {subprocess.py:93} INFO -            ^^^^^^^^^^^^^^^^^^^^^^^^^^^^^^^
[2024-11-06T12:23:55.753+0000] {subprocess.py:93} INFO -   File "/home/***/.local/lib/python3.12/site-packages/great_expectations/data_context/store/tuple_store_backend.py", line 330, in _set
[2024-11-06T12:23:55.753+0000] {subprocess.py:93} INFO -     with open(filepath, "wb") as outfile:
[2024-11-06T12:23:55.753+0000] {subprocess.py:93} INFO -          ^^^^^^^^^^^^^^^^^^^^
[2024-11-06T12:23:55.754+0000] {subprocess.py:93} INFO - PermissionError: [Errno 13] Permission denied: '/opt/dbt/gx/uncommitted/data_docs/local_site/expectations/obt_sales/basic.html'
[2024-11-06T12:23:55.754+0000] {subprocess.py:93} INFO - ".
[2024-11-06T12:23:55.892+0000] {subprocess.py:93} INFO - An unexpected Exception occurred during data docs rendering.  Because of this error, certain parts of data docs will not be rendered properly and/or may not appear altogether.  Please use the trace, included in this message, to diagnose and repair the underlying issue.  Detailed information follows:
[2024-11-06T12:23:55.892+0000] {subprocess.py:93} INFO -                 PermissionError: "[Errno 13] Permission denied: '/opt/dbt/gx/uncommitted/data_docs/local_site/validations/obt_sales/basic/20241106-122354-obt_sales-checkpoint'".  Traceback: "Traceback (most recent call last):
[2024-11-06T12:23:55.893+0000] {subprocess.py:93} INFO -   File "/home/***/.local/lib/python3.12/site-packages/great_expectations/render/renderer/site_builder.py", line 501, in build
[2024-11-06T12:23:55.893+0000] {subprocess.py:93} INFO -     self.target_store.set(
[2024-11-06T12:23:55.894+0000] {subprocess.py:93} INFO -   File "/home/***/.local/lib/python3.12/site-packages/great_expectations/data_context/store/html_site_store.py", line 269, in set
[2024-11-06T12:23:55.894+0000] {subprocess.py:93} INFO -     return self.store_backends[type(key.resource_identifier)].set(
[2024-11-06T12:23:55.896+0000] {subprocess.py:93} INFO -            ^^^^^^^^^^^^^^^^^^^^^^^^^^^^^^^^^^^^^^^^^^^^^^^^^^^^^^^
[2024-11-06T12:23:55.896+0000] {subprocess.py:93} INFO -   File "/home/***/.local/lib/python3.12/site-packages/great_expectations/data_context/store/_store_backend.py", line 134, in set
[2024-11-06T12:23:55.898+0000] {subprocess.py:93} INFO -     return self._set(key, value, **kwargs)
[2024-11-06T12:23:55.898+0000] {subprocess.py:93} INFO -            ^^^^^^^^^^^^^^^^^^^^^^^^^^^^^^^
[2024-11-06T12:23:55.898+0000] {subprocess.py:93} INFO -   File "/home/***/.local/lib/python3.12/site-packages/great_expectations/data_context/store/tuple_store_backend.py", line 329, in _set
[2024-11-06T12:23:55.898+0000] {subprocess.py:93} INFO -     os.makedirs(str(path), exist_ok=True)  # noqa: PTH103
[2024-11-06T12:23:55.899+0000] {subprocess.py:93} INFO -     ^^^^^^^^^^^^^^^^^^^^^^^^^^^^^^^^^^^^^
[2024-11-06T12:23:55.899+0000] {subprocess.py:93} INFO -   File "<frozen os>", line 215, in makedirs
[2024-11-06T12:23:55.899+0000] {subprocess.py:93} INFO -   File "<frozen os>", line 225, in makedirs
[2024-11-06T12:23:55.899+0000] {subprocess.py:93} INFO - PermissionError: [Errno 13] Permission denied: '/opt/dbt/gx/uncommitted/data_docs/local_site/validations/obt_sales/basic/20241106-122354-obt_sales-checkpoint'
[2024-11-06T12:23:55.899+0000] {subprocess.py:93} INFO - ".
[2024-11-06T12:23:55.908+0000] {subprocess.py:93} INFO - Error running action with name update_data_docs
[2024-11-06T12:23:55.908+0000] {subprocess.py:93} INFO - Traceback (most recent call last):
[2024-11-06T12:23:55.909+0000] {subprocess.py:93} INFO -   File "/home/***/.local/lib/python3.12/site-packages/great_expectations/validation_operators/validation_operators.py", line 476, in _run_actions
[2024-11-06T12:23:55.909+0000] {subprocess.py:93} INFO -     action_result = self.actions[name].run(
[2024-11-06T12:23:55.909+0000] {subprocess.py:93} INFO -                     ^^^^^^^^^^^^^^^^^^^^^^^
[2024-11-06T12:23:55.909+0000] {subprocess.py:93} INFO -   File "/home/***/.local/lib/python3.12/site-packages/great_expectations/checkpoint/actions.py", line 101, in run
[2024-11-06T12:23:55.910+0000] {subprocess.py:93} INFO -     return self._run(
[2024-11-06T12:23:55.910+0000] {subprocess.py:93} INFO -            ^^^^^^^^^^
[2024-11-06T12:23:55.910+0000] {subprocess.py:93} INFO -   File "/home/***/.local/lib/python3.12/site-packages/great_expectations/checkpoint/actions.py", line 1190, in _run
[2024-11-06T12:23:55.911+0000] {subprocess.py:93} INFO -     self.data_context.build_data_docs(
[2024-11-06T12:23:55.911+0000] {subprocess.py:93} INFO -   File "/home/***/.local/lib/python3.12/site-packages/great_expectations/core/usage_statistics/usage_statistics.py", line 266, in usage_statistics_wrapped_method
[2024-11-06T12:23:55.911+0000] {subprocess.py:93} INFO -     result = func(*args, **kwargs)
[2024-11-06T12:23:55.911+0000] {subprocess.py:93} INFO -              ^^^^^^^^^^^^^^^^^^^^^
[2024-11-06T12:23:55.911+0000] {subprocess.py:93} INFO -   File "/home/***/.local/lib/python3.12/site-packages/great_expectations/data_context/data_context/abstract_data_context.py", line 5318, in build_data_docs
[2024-11-06T12:23:55.912+0000] {subprocess.py:93} INFO -     return self._build_data_docs(
[2024-11-06T12:23:55.912+0000] {subprocess.py:93} INFO -            ^^^^^^^^^^^^^^^^^^^^^^
[2024-11-06T12:23:55.912+0000] {subprocess.py:93} INFO -   File "/home/***/.local/lib/python3.12/site-packages/great_expectations/data_context/data_context/abstract_data_context.py", line 5365, in _build_data_docs
[2024-11-06T12:23:55.912+0000] {subprocess.py:93} INFO -     index_page_resource_identifier_tuple = site_builder.build(
[2024-11-06T12:23:55.913+0000] {subprocess.py:93} INFO -                                            ^^^^^^^^^^^^^^^^^^^
[2024-11-06T12:23:55.913+0000] {subprocess.py:93} INFO -   File "/home/***/.local/lib/python3.12/site-packages/great_expectations/render/renderer/site_builder.py", line 329, in build
[2024-11-06T12:23:55.913+0000] {subprocess.py:93} INFO -     self.target_store.copy_static_assets()
[2024-11-06T12:23:55.913+0000] {subprocess.py:93} INFO -   File "/home/***/.local/lib/python3.12/site-packages/great_expectations/data_context/store/html_site_store.py", line 412, in copy_static_assets
[2024-11-06T12:23:55.914+0000] {subprocess.py:93} INFO -     self.copy_static_assets(new_source_dir)
[2024-11-06T12:23:55.914+0000] {subprocess.py:93} INFO -   File "/home/***/.local/lib/python3.12/site-packages/great_expectations/data_context/store/html_site_store.py", line 441, in copy_static_assets
[2024-11-06T12:23:55.914+0000] {subprocess.py:93} INFO -     self.store_backends["static_assets"].set(
[2024-11-06T12:23:55.914+0000] {subprocess.py:93} INFO -   File "/home/***/.local/lib/python3.12/site-packages/great_expectations/data_context/store/_store_backend.py", line 134, in set
[2024-11-06T12:23:55.915+0000] {subprocess.py:93} INFO -     return self._set(key, value, **kwargs)
[2024-11-06T12:23:55.915+0000] {subprocess.py:93} INFO -            ^^^^^^^^^^^^^^^^^^^^^^^^^^^^^^^
[2024-11-06T12:23:55.915+0000] {subprocess.py:93} INFO -   File "/home/***/.local/lib/python3.12/site-packages/great_expectations/data_context/store/tuple_store_backend.py", line 330, in _set
[2024-11-06T12:23:55.915+0000] {subprocess.py:93} INFO -     with open(filepath, "wb") as outfile:
[2024-11-06T12:23:55.915+0000] {subprocess.py:93} INFO -          ^^^^^^^^^^^^^^^^^^^^
[2024-11-06T12:23:55.916+0000] {subprocess.py:93} INFO - PermissionError: [Errno 13] Permission denied: '/opt/dbt/gx/uncommitted/data_docs/local_site/static/styles/data_docs_default_styles.css'
[2024-11-06T12:23:55.916+0000] {subprocess.py:93} INFO - [Errno 13] Permission denied: '/opt/dbt/gx/uncommitted/data_docs/local_site/static/styles/data_docs_default_styles.css'
[2024-11-06T12:23:56.887+0000] {subprocess.py:97} INFO - Command exited with return code 1
[2024-11-06T12:23:56.903+0000] {taskinstance.py:3310} ERROR - Task failed with exception
Traceback (most recent call last):
  File "/home/airflow/.local/lib/python3.12/site-packages/airflow/models/taskinstance.py", line 767, in _execute_task
    result = _execute_callable(context=context, **execute_callable_kwargs)
             ^^^^^^^^^^^^^^^^^^^^^^^^^^^^^^^^^^^^^^^^^^^^^^^^^^^^^^^^^^^^^
  File "/home/airflow/.local/lib/python3.12/site-packages/airflow/models/taskinstance.py", line 733, in _execute_callable
    return ExecutionCallableRunner(
           ^^^^^^^^^^^^^^^^^^^^^^^^
  File "/home/airflow/.local/lib/python3.12/site-packages/airflow/utils/operator_helpers.py", line 252, in run
    return self.func(*args, **kwargs)
           ^^^^^^^^^^^^^^^^^^^^^^^^^^
  File "/home/airflow/.local/lib/python3.12/site-packages/airflow/models/baseoperator.py", line 406, in wrapper
    return func(self, *args, **kwargs)
           ^^^^^^^^^^^^^^^^^^^^^^^^^^^
  File "/home/airflow/.local/lib/python3.12/site-packages/airflow/operators/bash.py", line 249, in execute
    raise AirflowException(
airflow.exceptions.AirflowException: Bash command failed. The command returned a non-zero exit code 1.
[2024-11-06T12:23:56.911+0000] {taskinstance.py:1225} INFO - Marking task as UP_FOR_RETRY. dag_id=dbt_project_with_ge_dag, task_id=ge_validate_obt_sales, run_id=scheduled__2024-11-05T00:00:00+00:00, execution_date=20241105T000000, start_date=20241106T122347, end_date=20241106T122356
[2024-11-06T12:23:56.932+0000] {taskinstance.py:340} INFO - ::group::Post task execution logs
[2024-11-06T12:23:56.933+0000] {standard_task_runner.py:124} ERROR - Failed to execute job 184 for task ge_validate_obt_sales (Bash command failed. The command returned a non-zero exit code 1.; 2415)
Traceback (most recent call last):
  File "/home/airflow/.local/lib/python3.12/site-packages/airflow/task/task_runner/standard_task_runner.py", line 117, in _start_by_fork
    ret = args.func(args, dag=self.dag)
          ^^^^^^^^^^^^^^^^^^^^^^^^^^^^^
  File "/home/airflow/.local/lib/python3.12/site-packages/airflow/cli/cli_config.py", line 49, in command
    return func(*args, **kwargs)
           ^^^^^^^^^^^^^^^^^^^^^
  File "/home/airflow/.local/lib/python3.12/site-packages/airflow/utils/cli.py", line 115, in wrapper
    return f(*args, **kwargs)
           ^^^^^^^^^^^^^^^^^^
  File "/home/airflow/.local/lib/python3.12/site-packages/airflow/cli/commands/task_command.py", line 483, in task_run
    task_return_code = _run_task_by_selected_method(args, _dag, ti)
                       ^^^^^^^^^^^^^^^^^^^^^^^^^^^^^^^^^^^^^^^^^^^^
  File "/home/airflow/.local/lib/python3.12/site-packages/airflow/cli/commands/task_command.py", line 256, in _run_task_by_selected_method
    return _run_raw_task(args, ti)
           ^^^^^^^^^^^^^^^^^^^^^^^
  File "/home/airflow/.local/lib/python3.12/site-packages/airflow/cli/commands/task_command.py", line 341, in _run_raw_task
    return ti._run_raw_task(
           ^^^^^^^^^^^^^^^^^
  File "/home/airflow/.local/lib/python3.12/site-packages/airflow/utils/session.py", line 97, in wrapper
    return func(*args, session=session, **kwargs)
           ^^^^^^^^^^^^^^^^^^^^^^^^^^^^^^^^^^^^^^
  File "/home/airflow/.local/lib/python3.12/site-packages/airflow/models/taskinstance.py", line 3004, in _run_raw_task
    return _run_raw_task(
           ^^^^^^^^^^^^^^
  File "/home/airflow/.local/lib/python3.12/site-packages/airflow/models/taskinstance.py", line 273, in _run_raw_task
    TaskInstance._execute_task_with_callbacks(
  File "/home/airflow/.local/lib/python3.12/site-packages/airflow/models/taskinstance.py", line 3158, in _execute_task_with_callbacks
    result = self._execute_task(context, task_orig)
             ^^^^^^^^^^^^^^^^^^^^^^^^^^^^^^^^^^^^^^
  File "/home/airflow/.local/lib/python3.12/site-packages/airflow/models/taskinstance.py", line 3182, in _execute_task
    return _execute_task(self, context, task_orig)
           ^^^^^^^^^^^^^^^^^^^^^^^^^^^^^^^^^^^^^^^
  File "/home/airflow/.local/lib/python3.12/site-packages/airflow/models/taskinstance.py", line 767, in _execute_task
    result = _execute_callable(context=context, **execute_callable_kwargs)
             ^^^^^^^^^^^^^^^^^^^^^^^^^^^^^^^^^^^^^^^^^^^^^^^^^^^^^^^^^^^^^
  File "/home/airflow/.local/lib/python3.12/site-packages/airflow/models/taskinstance.py", line 733, in _execute_callable
    return ExecutionCallableRunner(
           ^^^^^^^^^^^^^^^^^^^^^^^^
  File "/home/airflow/.local/lib/python3.12/site-packages/airflow/utils/operator_helpers.py", line 252, in run
    return self.func(*args, **kwargs)
           ^^^^^^^^^^^^^^^^^^^^^^^^^^
  File "/home/airflow/.local/lib/python3.12/site-packages/airflow/models/baseoperator.py", line 406, in wrapper
    return func(self, *args, **kwargs)
           ^^^^^^^^^^^^^^^^^^^^^^^^^^^
  File "/home/airflow/.local/lib/python3.12/site-packages/airflow/operators/bash.py", line 249, in execute
    raise AirflowException(
airflow.exceptions.AirflowException: Bash command failed. The command returned a non-zero exit code 1.
[2024-11-06T12:23:56.973+0000] {local_task_job_runner.py:266} INFO - Task exited with return code 1
[2024-11-06T12:23:57.002+0000] {taskinstance.py:3900} INFO - 0 downstream tasks scheduled from follow-on schedule check
[2024-11-06T12:23:57.004+0000] {local_task_job_runner.py:245} INFO - ::endgroup::
