[2024-11-06T12:04:27.462+0000] {local_task_job_runner.py:123} INFO - ::group::Pre task execution logs
[2024-11-06T12:04:27.486+0000] {taskinstance.py:2612} INFO - Dependencies all met for dep_context=non-requeueable deps ti=<TaskInstance: dbt_project_with_ge_dag.ge_validate_obt_sales scheduled__2024-11-05T00:00:00+00:00 [queued]>
[2024-11-06T12:04:27.497+0000] {taskinstance.py:2612} INFO - Dependencies all met for dep_context=requeueable deps ti=<TaskInstance: dbt_project_with_ge_dag.ge_validate_obt_sales scheduled__2024-11-05T00:00:00+00:00 [queued]>
[2024-11-06T12:04:27.497+0000] {taskinstance.py:2865} INFO - Starting attempt 3 of 3
[2024-11-06T12:04:27.516+0000] {taskinstance.py:2888} INFO - Executing <Task(BashOperator): ge_validate_obt_sales> on 2024-11-05 00:00:00+00:00
[2024-11-06T12:04:27.525+0000] {warnings.py:112} WARNING - /home/***/.local/lib/python3.12/site-packages/***/task/task_runner/standard_task_runner.py:70: DeprecationWarning: This process (pid=1882) is multi-threaded, use of fork() may lead to deadlocks in the child.
  pid = os.fork()

[2024-11-06T12:04:27.527+0000] {standard_task_runner.py:72} INFO - Started process 1883 to run task
[2024-11-06T12:04:27.528+0000] {standard_task_runner.py:104} INFO - Running: ['***', 'tasks', 'run', 'dbt_project_with_ge_dag', 'ge_validate_obt_sales', 'scheduled__2024-11-05T00:00:00+00:00', '--job-id', '167', '--raw', '--subdir', 'DAGS_FOLDER/dbt_project_dag.py', '--cfg-path', '/tmp/tmp7erz_nzy']
[2024-11-06T12:04:27.529+0000] {standard_task_runner.py:105} INFO - Job 167: Subtask ge_validate_obt_sales
[2024-11-06T12:04:27.603+0000] {task_command.py:467} INFO - Running <TaskInstance: dbt_project_with_ge_dag.ge_validate_obt_sales scheduled__2024-11-05T00:00:00+00:00 [running]> on host 9ecf534049e3
[2024-11-06T12:04:27.737+0000] {taskinstance.py:3131} INFO - Exporting env vars: AIRFLOW_CTX_DAG_OWNER='***' AIRFLOW_CTX_DAG_ID='dbt_project_with_ge_dag' AIRFLOW_CTX_TASK_ID='ge_validate_obt_sales' AIRFLOW_CTX_EXECUTION_DATE='2024-11-05T00:00:00+00:00' AIRFLOW_CTX_TRY_NUMBER='3' AIRFLOW_CTX_DAG_RUN_ID='scheduled__2024-11-05T00:00:00+00:00'
[2024-11-06T12:04:27.738+0000] {taskinstance.py:731} INFO - ::endgroup::
[2024-11-06T12:04:27.782+0000] {subprocess.py:63} INFO - Tmp dir root location: /tmp
[2024-11-06T12:04:27.784+0000] {subprocess.py:75} INFO - Running command: ['/usr/bin/bash', '-c', 'cd /opt/dbt && great_expectations checkpoint run obt_sales_checkpoint']
[2024-11-06T12:04:27.803+0000] {subprocess.py:86} INFO - Output:
[2024-11-06T12:04:40.074+0000] {subprocess.py:93} INFO - Calculating Metrics:   0%|          | 0/69 [00:00<?, ?it/s]Calculating Metrics:   0%|          | 0/69 [00:00<?, ?it/s]Calculating Metrics:   3%|▎         | 2/69 [00:00<00:00, 239.20it/s]Calculating Metrics:   3%|▎         | 2/69 [00:00<00:01, 37.66it/s] Calculating Metrics:   6%|▌         | 4/69 [00:00<00:00, 69.95it/s]Calculating Metrics:   6%|▌         | 4/69 [00:00<00:01, 40.85it/s]Calculating Metrics:  25%|██▍       | 17/69 [00:00<00:00, 161.77it/s]Calculating Metrics:  25%|██▍       | 17/69 [00:00<00:00, 161.77it/s]Calculating Metrics:  25%|██▍       | 17/69 [00:00<00:00, 161.77it/s]Calculating Metrics:  83%|████████▎ | 57/69 [00:00<00:00, 161.77it/s]Calculating Metrics:  83%|████████▎ | 57/69 [00:00<00:00, 276.86it/s]Calculating Metrics:  83%|████████▎ | 57/69 [00:00<00:00, 276.86it/s]Calculating Metrics: 100%|██████████| 69/69 [00:00<00:00, 276.86it/s]Calculating Metrics: 100%|██████████| 69/69 [00:00<00:00, 276.86it/s]Calculating Metrics: 100%|██████████| 69/69 [00:00<00:00, 276.86it/s]Calculating Metrics: 100%|██████████| 69/69 [00:00<00:00, 266.72it/s]
[2024-11-06T12:04:40.134+0000] {subprocess.py:93} INFO - Error running action with name store_validation_result
[2024-11-06T12:04:40.135+0000] {subprocess.py:93} INFO - Traceback (most recent call last):
[2024-11-06T12:04:40.135+0000] {subprocess.py:93} INFO -   File "/home/***/.local/lib/python3.12/site-packages/great_expectations/validation_operators/validation_operators.py", line 476, in _run_actions
[2024-11-06T12:04:40.136+0000] {subprocess.py:93} INFO -     action_result = self.actions[name].run(
[2024-11-06T12:04:40.137+0000] {subprocess.py:93} INFO -                     ^^^^^^^^^^^^^^^^^^^^^^^
[2024-11-06T12:04:40.137+0000] {subprocess.py:93} INFO -   File "/home/***/.local/lib/python3.12/site-packages/great_expectations/checkpoint/actions.py", line 101, in run
[2024-11-06T12:04:40.138+0000] {subprocess.py:93} INFO -     return self._run(
[2024-11-06T12:04:40.138+0000] {subprocess.py:93} INFO -            ^^^^^^^^^^
[2024-11-06T12:04:40.139+0000] {subprocess.py:93} INFO -   File "/home/***/.local/lib/python3.12/site-packages/great_expectations/checkpoint/actions.py", line 898, in _run
[2024-11-06T12:04:40.139+0000] {subprocess.py:93} INFO -     run_return_value = self._basic_run(
[2024-11-06T12:04:40.139+0000] {subprocess.py:93} INFO -                        ^^^^^^^^^^^^^^^^
[2024-11-06T12:04:40.140+0000] {subprocess.py:93} INFO -   File "/home/***/.local/lib/python3.12/site-packages/great_expectations/checkpoint/actions.py", line 942, in _basic_run
[2024-11-06T12:04:40.140+0000] {subprocess.py:93} INFO -     return self.target_store.set(
[2024-11-06T12:04:40.141+0000] {subprocess.py:93} INFO -            ^^^^^^^^^^^^^^^^^^^^^^
[2024-11-06T12:04:40.141+0000] {subprocess.py:93} INFO -   File "/home/***/.local/lib/python3.12/site-packages/great_expectations/data_context/store/store.py", line 226, in set
[2024-11-06T12:04:40.142+0000] {subprocess.py:93} INFO -     return self._store_backend.set(
[2024-11-06T12:04:40.142+0000] {subprocess.py:93} INFO -            ^^^^^^^^^^^^^^^^^^^^^^^^
[2024-11-06T12:04:40.143+0000] {subprocess.py:93} INFO -   File "/home/***/.local/lib/python3.12/site-packages/great_expectations/data_context/store/_store_backend.py", line 134, in set
[2024-11-06T12:04:40.144+0000] {subprocess.py:93} INFO -     return self._set(key, value, **kwargs)
[2024-11-06T12:04:40.144+0000] {subprocess.py:93} INFO -            ^^^^^^^^^^^^^^^^^^^^^^^^^^^^^^^
[2024-11-06T12:04:40.145+0000] {subprocess.py:93} INFO -   File "/home/***/.local/lib/python3.12/site-packages/great_expectations/data_context/store/tuple_store_backend.py", line 329, in _set
[2024-11-06T12:04:40.145+0000] {subprocess.py:93} INFO -     os.makedirs(str(path), exist_ok=True)  # noqa: PTH103
[2024-11-06T12:04:40.146+0000] {subprocess.py:93} INFO -     ^^^^^^^^^^^^^^^^^^^^^^^^^^^^^^^^^^^^^
[2024-11-06T12:04:40.146+0000] {subprocess.py:93} INFO -   File "<frozen os>", line 215, in makedirs
[2024-11-06T12:04:40.147+0000] {subprocess.py:93} INFO -   File "<frozen os>", line 225, in makedirs
[2024-11-06T12:04:40.148+0000] {subprocess.py:93} INFO - PermissionError: [Errno 13] Permission denied: '/opt/dbt/gx/uncommitted/validations/obt_sales/basic/20241106-120439-obt_sales-checkpoint'
[2024-11-06T12:04:40.148+0000] {subprocess.py:93} INFO - [Errno 13] Permission denied: '/opt/dbt/gx/uncommitted/validations/obt_sales/basic/20241106-120439-obt_sales-checkpoint'
[2024-11-06T12:04:40.954+0000] {subprocess.py:97} INFO - Command exited with return code 1
[2024-11-06T12:04:40.967+0000] {taskinstance.py:3310} ERROR - Task failed with exception
Traceback (most recent call last):
  File "/home/airflow/.local/lib/python3.12/site-packages/airflow/models/taskinstance.py", line 767, in _execute_task
    result = _execute_callable(context=context, **execute_callable_kwargs)
             ^^^^^^^^^^^^^^^^^^^^^^^^^^^^^^^^^^^^^^^^^^^^^^^^^^^^^^^^^^^^^
  File "/home/airflow/.local/lib/python3.12/site-packages/airflow/models/taskinstance.py", line 733, in _execute_callable
    return ExecutionCallableRunner(
           ^^^^^^^^^^^^^^^^^^^^^^^^
  File "/home/airflow/.local/lib/python3.12/site-packages/airflow/utils/operator_helpers.py", line 252, in run
    return self.func(*args, **kwargs)
           ^^^^^^^^^^^^^^^^^^^^^^^^^^
  File "/home/airflow/.local/lib/python3.12/site-packages/airflow/models/baseoperator.py", line 406, in wrapper
    return func(self, *args, **kwargs)
           ^^^^^^^^^^^^^^^^^^^^^^^^^^^
  File "/home/airflow/.local/lib/python3.12/site-packages/airflow/operators/bash.py", line 249, in execute
    raise AirflowException(
airflow.exceptions.AirflowException: Bash command failed. The command returned a non-zero exit code 1.
[2024-11-06T12:04:40.972+0000] {taskinstance.py:1225} INFO - Marking task as FAILED. dag_id=dbt_project_with_ge_dag, task_id=ge_validate_obt_sales, run_id=scheduled__2024-11-05T00:00:00+00:00, execution_date=20241105T000000, start_date=20241106T120427, end_date=20241106T120440
[2024-11-06T12:04:40.994+0000] {taskinstance.py:340} INFO - ::group::Post task execution logs
[2024-11-06T12:04:40.995+0000] {standard_task_runner.py:124} ERROR - Failed to execute job 167 for task ge_validate_obt_sales (Bash command failed. The command returned a non-zero exit code 1.; 1883)
Traceback (most recent call last):
  File "/home/airflow/.local/lib/python3.12/site-packages/airflow/task/task_runner/standard_task_runner.py", line 117, in _start_by_fork
    ret = args.func(args, dag=self.dag)
          ^^^^^^^^^^^^^^^^^^^^^^^^^^^^^
  File "/home/airflow/.local/lib/python3.12/site-packages/airflow/cli/cli_config.py", line 49, in command
    return func(*args, **kwargs)
           ^^^^^^^^^^^^^^^^^^^^^
  File "/home/airflow/.local/lib/python3.12/site-packages/airflow/utils/cli.py", line 115, in wrapper
    return f(*args, **kwargs)
           ^^^^^^^^^^^^^^^^^^
  File "/home/airflow/.local/lib/python3.12/site-packages/airflow/cli/commands/task_command.py", line 483, in task_run
    task_return_code = _run_task_by_selected_method(args, _dag, ti)
                       ^^^^^^^^^^^^^^^^^^^^^^^^^^^^^^^^^^^^^^^^^^^^
  File "/home/airflow/.local/lib/python3.12/site-packages/airflow/cli/commands/task_command.py", line 256, in _run_task_by_selected_method
    return _run_raw_task(args, ti)
           ^^^^^^^^^^^^^^^^^^^^^^^
  File "/home/airflow/.local/lib/python3.12/site-packages/airflow/cli/commands/task_command.py", line 341, in _run_raw_task
    return ti._run_raw_task(
           ^^^^^^^^^^^^^^^^^
  File "/home/airflow/.local/lib/python3.12/site-packages/airflow/utils/session.py", line 97, in wrapper
    return func(*args, session=session, **kwargs)
           ^^^^^^^^^^^^^^^^^^^^^^^^^^^^^^^^^^^^^^
  File "/home/airflow/.local/lib/python3.12/site-packages/airflow/models/taskinstance.py", line 3004, in _run_raw_task
    return _run_raw_task(
           ^^^^^^^^^^^^^^
  File "/home/airflow/.local/lib/python3.12/site-packages/airflow/models/taskinstance.py", line 273, in _run_raw_task
    TaskInstance._execute_task_with_callbacks(
  File "/home/airflow/.local/lib/python3.12/site-packages/airflow/models/taskinstance.py", line 3158, in _execute_task_with_callbacks
    result = self._execute_task(context, task_orig)
             ^^^^^^^^^^^^^^^^^^^^^^^^^^^^^^^^^^^^^^
  File "/home/airflow/.local/lib/python3.12/site-packages/airflow/models/taskinstance.py", line 3182, in _execute_task
    return _execute_task(self, context, task_orig)
           ^^^^^^^^^^^^^^^^^^^^^^^^^^^^^^^^^^^^^^^
  File "/home/airflow/.local/lib/python3.12/site-packages/airflow/models/taskinstance.py", line 767, in _execute_task
    result = _execute_callable(context=context, **execute_callable_kwargs)
             ^^^^^^^^^^^^^^^^^^^^^^^^^^^^^^^^^^^^^^^^^^^^^^^^^^^^^^^^^^^^^
  File "/home/airflow/.local/lib/python3.12/site-packages/airflow/models/taskinstance.py", line 733, in _execute_callable
    return ExecutionCallableRunner(
           ^^^^^^^^^^^^^^^^^^^^^^^^
  File "/home/airflow/.local/lib/python3.12/site-packages/airflow/utils/operator_helpers.py", line 252, in run
    return self.func(*args, **kwargs)
           ^^^^^^^^^^^^^^^^^^^^^^^^^^
  File "/home/airflow/.local/lib/python3.12/site-packages/airflow/models/baseoperator.py", line 406, in wrapper
    return func(self, *args, **kwargs)
           ^^^^^^^^^^^^^^^^^^^^^^^^^^^
  File "/home/airflow/.local/lib/python3.12/site-packages/airflow/operators/bash.py", line 249, in execute
    raise AirflowException(
airflow.exceptions.AirflowException: Bash command failed. The command returned a non-zero exit code 1.
[2024-11-06T12:04:41.041+0000] {local_task_job_runner.py:266} INFO - Task exited with return code 1
[2024-11-06T12:04:41.070+0000] {taskinstance.py:3900} INFO - 0 downstream tasks scheduled from follow-on schedule check
[2024-11-06T12:04:41.075+0000] {local_task_job_runner.py:245} INFO - ::endgroup::
[2024-11-06T12:09:26.676+0000] {local_task_job_runner.py:123} INFO - ::group::Pre task execution logs
[2024-11-06T12:09:26.696+0000] {taskinstance.py:2612} INFO - Dependencies all met for dep_context=non-requeueable deps ti=<TaskInstance: dbt_project_with_ge_dag.ge_validate_obt_sales scheduled__2024-11-05T00:00:00+00:00 [queued]>
[2024-11-06T12:09:26.708+0000] {taskinstance.py:2612} INFO - Dependencies all met for dep_context=requeueable deps ti=<TaskInstance: dbt_project_with_ge_dag.ge_validate_obt_sales scheduled__2024-11-05T00:00:00+00:00 [queued]>
[2024-11-06T12:09:26.708+0000] {taskinstance.py:2865} INFO - Starting attempt 3 of 3
[2024-11-06T12:09:26.726+0000] {taskinstance.py:2888} INFO - Executing <Task(BashOperator): ge_validate_obt_sales> on 2024-11-05 00:00:00+00:00
[2024-11-06T12:09:26.732+0000] {warnings.py:112} WARNING - /home/***/.local/lib/python3.12/site-packages/***/task/task_runner/standard_task_runner.py:70: DeprecationWarning: This process (pid=2150) is multi-threaded, use of fork() may lead to deadlocks in the child.
  pid = os.fork()

[2024-11-06T12:09:26.735+0000] {standard_task_runner.py:72} INFO - Started process 2151 to run task
[2024-11-06T12:09:26.735+0000] {standard_task_runner.py:104} INFO - Running: ['***', 'tasks', 'run', 'dbt_project_with_ge_dag', 'ge_validate_obt_sales', 'scheduled__2024-11-05T00:00:00+00:00', '--job-id', '179', '--raw', '--subdir', 'DAGS_FOLDER/dbt_project_dag.py', '--cfg-path', '/tmp/tmp64wzv0ny']
[2024-11-06T12:09:26.736+0000] {standard_task_runner.py:105} INFO - Job 179: Subtask ge_validate_obt_sales
[2024-11-06T12:09:26.789+0000] {task_command.py:467} INFO - Running <TaskInstance: dbt_project_with_ge_dag.ge_validate_obt_sales scheduled__2024-11-05T00:00:00+00:00 [running]> on host 9ecf534049e3
[2024-11-06T12:09:26.878+0000] {taskinstance.py:3131} INFO - Exporting env vars: AIRFLOW_CTX_DAG_OWNER='***' AIRFLOW_CTX_DAG_ID='dbt_project_with_ge_dag' AIRFLOW_CTX_TASK_ID='ge_validate_obt_sales' AIRFLOW_CTX_EXECUTION_DATE='2024-11-05T00:00:00+00:00' AIRFLOW_CTX_TRY_NUMBER='3' AIRFLOW_CTX_DAG_RUN_ID='scheduled__2024-11-05T00:00:00+00:00'
[2024-11-06T12:09:26.879+0000] {taskinstance.py:731} INFO - ::endgroup::
[2024-11-06T12:09:26.897+0000] {subprocess.py:63} INFO - Tmp dir root location: /tmp
[2024-11-06T12:09:26.898+0000] {subprocess.py:75} INFO - Running command: ['/usr/bin/bash', '-c', 'cd /opt/dbt && great_expectations checkpoint run obt_sales_checkpoint']
[2024-11-06T12:09:26.910+0000] {subprocess.py:86} INFO - Output:
[2024-11-06T12:09:33.663+0000] {subprocess.py:93} INFO - Calculating Metrics:   0%|          | 0/69 [00:00<?, ?it/s]Calculating Metrics:   0%|          | 0/69 [00:00<?, ?it/s]Calculating Metrics:   3%|▎         | 2/69 [00:00<00:00, 254.63it/s]Calculating Metrics:   3%|▎         | 2/69 [00:00<00:01, 36.14it/s] Calculating Metrics:   6%|▌         | 4/69 [00:00<00:00, 67.31it/s]Calculating Metrics:   6%|▌         | 4/69 [00:00<00:01, 37.86it/s]Calculating Metrics:   6%|▌         | 4/69 [00:00<00:01, 37.86it/s]Calculating Metrics:  25%|██▍       | 17/69 [00:00<00:01, 37.86it/s]Calculating Metrics:  25%|██▍       | 17/69 [00:00<00:01, 37.86it/s]Calculating Metrics:  83%|████████▎ | 57/69 [00:00<00:00, 289.86it/s]Calculating Metrics:  83%|████████▎ | 57/69 [00:00<00:00, 289.86it/s]Calculating Metrics:  83%|████████▎ | 57/69 [00:00<00:00, 289.86it/s]Calculating Metrics: 100%|██████████| 69/69 [00:00<00:00, 289.86it/s]Calculating Metrics: 100%|██████████| 69/69 [00:00<00:00, 289.86it/s]Calculating Metrics: 100%|██████████| 69/69 [00:00<00:00, 289.86it/s]Calculating Metrics: 100%|██████████| 69/69 [00:00<00:00, 244.00it/s]
[2024-11-06T12:09:33.877+0000] {subprocess.py:93} INFO - An unexpected Exception occurred during data docs rendering.  Because of this error, certain parts of data docs will not be rendered properly and/or may not appear altogether.  Please use the trace, included in this message, to diagnose and repair the underlying issue.  Detailed information follows:
[2024-11-06T12:09:33.879+0000] {subprocess.py:93} INFO -                 PermissionError: "[Errno 13] Permission denied: '/opt/dbt/gx/uncommitted/data_docs/local_site/expectations/obt_sales/basic.html'".  Traceback: "Traceback (most recent call last):
[2024-11-06T12:09:33.880+0000] {subprocess.py:93} INFO -   File "/home/***/.local/lib/python3.12/site-packages/great_expectations/render/renderer/site_builder.py", line 501, in build
[2024-11-06T12:09:33.881+0000] {subprocess.py:93} INFO -     self.target_store.set(
[2024-11-06T12:09:33.881+0000] {subprocess.py:93} INFO -   File "/home/***/.local/lib/python3.12/site-packages/great_expectations/data_context/store/html_site_store.py", line 269, in set
[2024-11-06T12:09:33.882+0000] {subprocess.py:93} INFO -     return self.store_backends[type(key.resource_identifier)].set(
[2024-11-06T12:09:33.882+0000] {subprocess.py:93} INFO -            ^^^^^^^^^^^^^^^^^^^^^^^^^^^^^^^^^^^^^^^^^^^^^^^^^^^^^^^
[2024-11-06T12:09:33.883+0000] {subprocess.py:93} INFO -   File "/home/***/.local/lib/python3.12/site-packages/great_expectations/data_context/store/_store_backend.py", line 134, in set
[2024-11-06T12:09:33.883+0000] {subprocess.py:93} INFO -     return self._set(key, value, **kwargs)
[2024-11-06T12:09:33.883+0000] {subprocess.py:93} INFO -            ^^^^^^^^^^^^^^^^^^^^^^^^^^^^^^^
[2024-11-06T12:09:33.884+0000] {subprocess.py:93} INFO -   File "/home/***/.local/lib/python3.12/site-packages/great_expectations/data_context/store/tuple_store_backend.py", line 330, in _set
[2024-11-06T12:09:33.884+0000] {subprocess.py:93} INFO -     with open(filepath, "wb") as outfile:
[2024-11-06T12:09:33.885+0000] {subprocess.py:93} INFO -          ^^^^^^^^^^^^^^^^^^^^
[2024-11-06T12:09:33.885+0000] {subprocess.py:93} INFO - PermissionError: [Errno 13] Permission denied: '/opt/dbt/gx/uncommitted/data_docs/local_site/expectations/obt_sales/basic.html'
[2024-11-06T12:09:33.886+0000] {subprocess.py:93} INFO - ".
[2024-11-06T12:09:34.007+0000] {subprocess.py:93} INFO - An unexpected Exception occurred during data docs rendering.  Because of this error, certain parts of data docs will not be rendered properly and/or may not appear altogether.  Please use the trace, included in this message, to diagnose and repair the underlying issue.  Detailed information follows:
[2024-11-06T12:09:34.007+0000] {subprocess.py:93} INFO -                 PermissionError: "[Errno 13] Permission denied: '/opt/dbt/gx/uncommitted/data_docs/local_site/validations/obt_sales/basic/20241106-120933-obt_sales-checkpoint'".  Traceback: "Traceback (most recent call last):
[2024-11-06T12:09:34.008+0000] {subprocess.py:93} INFO -   File "/home/***/.local/lib/python3.12/site-packages/great_expectations/render/renderer/site_builder.py", line 501, in build
[2024-11-06T12:09:34.008+0000] {subprocess.py:93} INFO -     self.target_store.set(
[2024-11-06T12:09:34.009+0000] {subprocess.py:93} INFO -   File "/home/***/.local/lib/python3.12/site-packages/great_expectations/data_context/store/html_site_store.py", line 269, in set
[2024-11-06T12:09:34.009+0000] {subprocess.py:93} INFO -     return self.store_backends[type(key.resource_identifier)].set(
[2024-11-06T12:09:34.009+0000] {subprocess.py:93} INFO -            ^^^^^^^^^^^^^^^^^^^^^^^^^^^^^^^^^^^^^^^^^^^^^^^^^^^^^^^
[2024-11-06T12:09:34.010+0000] {subprocess.py:93} INFO -   File "/home/***/.local/lib/python3.12/site-packages/great_expectations/data_context/store/_store_backend.py", line 134, in set
[2024-11-06T12:09:34.011+0000] {subprocess.py:93} INFO -     return self._set(key, value, **kwargs)
[2024-11-06T12:09:34.012+0000] {subprocess.py:93} INFO -            ^^^^^^^^^^^^^^^^^^^^^^^^^^^^^^^
[2024-11-06T12:09:34.014+0000] {subprocess.py:93} INFO -   File "/home/***/.local/lib/python3.12/site-packages/great_expectations/data_context/store/tuple_store_backend.py", line 329, in _set
[2024-11-06T12:09:34.015+0000] {subprocess.py:93} INFO -     os.makedirs(str(path), exist_ok=True)  # noqa: PTH103
[2024-11-06T12:09:34.015+0000] {subprocess.py:93} INFO -     ^^^^^^^^^^^^^^^^^^^^^^^^^^^^^^^^^^^^^
[2024-11-06T12:09:34.016+0000] {subprocess.py:93} INFO -   File "<frozen os>", line 215, in makedirs
[2024-11-06T12:09:34.017+0000] {subprocess.py:93} INFO -   File "<frozen os>", line 225, in makedirs
[2024-11-06T12:09:34.017+0000] {subprocess.py:93} INFO - PermissionError: [Errno 13] Permission denied: '/opt/dbt/gx/uncommitted/data_docs/local_site/validations/obt_sales/basic/20241106-120933-obt_sales-checkpoint'
[2024-11-06T12:09:34.017+0000] {subprocess.py:93} INFO - ".
[2024-11-06T12:09:34.024+0000] {subprocess.py:93} INFO - Error running action with name update_data_docs
[2024-11-06T12:09:34.024+0000] {subprocess.py:93} INFO - Traceback (most recent call last):
[2024-11-06T12:09:34.024+0000] {subprocess.py:93} INFO -   File "/home/***/.local/lib/python3.12/site-packages/great_expectations/validation_operators/validation_operators.py", line 476, in _run_actions
[2024-11-06T12:09:34.025+0000] {subprocess.py:93} INFO -     action_result = self.actions[name].run(
[2024-11-06T12:09:34.025+0000] {subprocess.py:93} INFO -                     ^^^^^^^^^^^^^^^^^^^^^^^
[2024-11-06T12:09:34.025+0000] {subprocess.py:93} INFO -   File "/home/***/.local/lib/python3.12/site-packages/great_expectations/checkpoint/actions.py", line 101, in run
[2024-11-06T12:09:34.026+0000] {subprocess.py:93} INFO -     return self._run(
[2024-11-06T12:09:34.026+0000] {subprocess.py:93} INFO -            ^^^^^^^^^^
[2024-11-06T12:09:34.026+0000] {subprocess.py:93} INFO -   File "/home/***/.local/lib/python3.12/site-packages/great_expectations/checkpoint/actions.py", line 1190, in _run
[2024-11-06T12:09:34.027+0000] {subprocess.py:93} INFO -     self.data_context.build_data_docs(
[2024-11-06T12:09:34.028+0000] {subprocess.py:93} INFO -   File "/home/***/.local/lib/python3.12/site-packages/great_expectations/core/usage_statistics/usage_statistics.py", line 266, in usage_statistics_wrapped_method
[2024-11-06T12:09:34.029+0000] {subprocess.py:93} INFO -     result = func(*args, **kwargs)
[2024-11-06T12:09:34.030+0000] {subprocess.py:93} INFO -              ^^^^^^^^^^^^^^^^^^^^^
[2024-11-06T12:09:34.031+0000] {subprocess.py:93} INFO -   File "/home/***/.local/lib/python3.12/site-packages/great_expectations/data_context/data_context/abstract_data_context.py", line 5318, in build_data_docs
[2024-11-06T12:09:34.031+0000] {subprocess.py:93} INFO -     return self._build_data_docs(
[2024-11-06T12:09:34.032+0000] {subprocess.py:93} INFO -            ^^^^^^^^^^^^^^^^^^^^^^
[2024-11-06T12:09:34.033+0000] {subprocess.py:93} INFO -   File "/home/***/.local/lib/python3.12/site-packages/great_expectations/data_context/data_context/abstract_data_context.py", line 5365, in _build_data_docs
[2024-11-06T12:09:34.034+0000] {subprocess.py:93} INFO -     index_page_resource_identifier_tuple = site_builder.build(
[2024-11-06T12:09:34.035+0000] {subprocess.py:93} INFO -                                            ^^^^^^^^^^^^^^^^^^^
[2024-11-06T12:09:34.035+0000] {subprocess.py:93} INFO -   File "/home/***/.local/lib/python3.12/site-packages/great_expectations/render/renderer/site_builder.py", line 329, in build
[2024-11-06T12:09:34.036+0000] {subprocess.py:93} INFO -     self.target_store.copy_static_assets()
[2024-11-06T12:09:34.037+0000] {subprocess.py:93} INFO -   File "/home/***/.local/lib/python3.12/site-packages/great_expectations/data_context/store/html_site_store.py", line 412, in copy_static_assets
[2024-11-06T12:09:34.037+0000] {subprocess.py:93} INFO -     self.copy_static_assets(new_source_dir)
[2024-11-06T12:09:34.038+0000] {subprocess.py:93} INFO -   File "/home/***/.local/lib/python3.12/site-packages/great_expectations/data_context/store/html_site_store.py", line 441, in copy_static_assets
[2024-11-06T12:09:34.038+0000] {subprocess.py:93} INFO -     self.store_backends["static_assets"].set(
[2024-11-06T12:09:34.039+0000] {subprocess.py:93} INFO -   File "/home/***/.local/lib/python3.12/site-packages/great_expectations/data_context/store/_store_backend.py", line 134, in set
[2024-11-06T12:09:34.039+0000] {subprocess.py:93} INFO -     return self._set(key, value, **kwargs)
[2024-11-06T12:09:34.040+0000] {subprocess.py:93} INFO -            ^^^^^^^^^^^^^^^^^^^^^^^^^^^^^^^
[2024-11-06T12:09:34.040+0000] {subprocess.py:93} INFO -   File "/home/***/.local/lib/python3.12/site-packages/great_expectations/data_context/store/tuple_store_backend.py", line 330, in _set
[2024-11-06T12:09:34.041+0000] {subprocess.py:93} INFO -     with open(filepath, "wb") as outfile:
[2024-11-06T12:09:34.041+0000] {subprocess.py:93} INFO -          ^^^^^^^^^^^^^^^^^^^^
[2024-11-06T12:09:34.042+0000] {subprocess.py:93} INFO - PermissionError: [Errno 13] Permission denied: '/opt/dbt/gx/uncommitted/data_docs/local_site/static/styles/data_docs_default_styles.css'
[2024-11-06T12:09:34.042+0000] {subprocess.py:93} INFO - [Errno 13] Permission denied: '/opt/dbt/gx/uncommitted/data_docs/local_site/static/styles/data_docs_default_styles.css'
[2024-11-06T12:09:34.901+0000] {subprocess.py:97} INFO - Command exited with return code 1
[2024-11-06T12:09:34.917+0000] {taskinstance.py:3310} ERROR - Task failed with exception
Traceback (most recent call last):
  File "/home/airflow/.local/lib/python3.12/site-packages/airflow/models/taskinstance.py", line 767, in _execute_task
    result = _execute_callable(context=context, **execute_callable_kwargs)
             ^^^^^^^^^^^^^^^^^^^^^^^^^^^^^^^^^^^^^^^^^^^^^^^^^^^^^^^^^^^^^
  File "/home/airflow/.local/lib/python3.12/site-packages/airflow/models/taskinstance.py", line 733, in _execute_callable
    return ExecutionCallableRunner(
           ^^^^^^^^^^^^^^^^^^^^^^^^
  File "/home/airflow/.local/lib/python3.12/site-packages/airflow/utils/operator_helpers.py", line 252, in run
    return self.func(*args, **kwargs)
           ^^^^^^^^^^^^^^^^^^^^^^^^^^
  File "/home/airflow/.local/lib/python3.12/site-packages/airflow/models/baseoperator.py", line 406, in wrapper
    return func(self, *args, **kwargs)
           ^^^^^^^^^^^^^^^^^^^^^^^^^^^
  File "/home/airflow/.local/lib/python3.12/site-packages/airflow/operators/bash.py", line 249, in execute
    raise AirflowException(
airflow.exceptions.AirflowException: Bash command failed. The command returned a non-zero exit code 1.
[2024-11-06T12:09:34.924+0000] {taskinstance.py:1225} INFO - Marking task as FAILED. dag_id=dbt_project_with_ge_dag, task_id=ge_validate_obt_sales, run_id=scheduled__2024-11-05T00:00:00+00:00, execution_date=20241105T000000, start_date=20241106T120926, end_date=20241106T120934
[2024-11-06T12:09:34.940+0000] {taskinstance.py:340} INFO - ::group::Post task execution logs
[2024-11-06T12:09:34.941+0000] {standard_task_runner.py:124} ERROR - Failed to execute job 179 for task ge_validate_obt_sales (Bash command failed. The command returned a non-zero exit code 1.; 2151)
Traceback (most recent call last):
  File "/home/airflow/.local/lib/python3.12/site-packages/airflow/task/task_runner/standard_task_runner.py", line 117, in _start_by_fork
    ret = args.func(args, dag=self.dag)
          ^^^^^^^^^^^^^^^^^^^^^^^^^^^^^
  File "/home/airflow/.local/lib/python3.12/site-packages/airflow/cli/cli_config.py", line 49, in command
    return func(*args, **kwargs)
           ^^^^^^^^^^^^^^^^^^^^^
  File "/home/airflow/.local/lib/python3.12/site-packages/airflow/utils/cli.py", line 115, in wrapper
    return f(*args, **kwargs)
           ^^^^^^^^^^^^^^^^^^
  File "/home/airflow/.local/lib/python3.12/site-packages/airflow/cli/commands/task_command.py", line 483, in task_run
    task_return_code = _run_task_by_selected_method(args, _dag, ti)
                       ^^^^^^^^^^^^^^^^^^^^^^^^^^^^^^^^^^^^^^^^^^^^
  File "/home/airflow/.local/lib/python3.12/site-packages/airflow/cli/commands/task_command.py", line 256, in _run_task_by_selected_method
    return _run_raw_task(args, ti)
           ^^^^^^^^^^^^^^^^^^^^^^^
  File "/home/airflow/.local/lib/python3.12/site-packages/airflow/cli/commands/task_command.py", line 341, in _run_raw_task
    return ti._run_raw_task(
           ^^^^^^^^^^^^^^^^^
  File "/home/airflow/.local/lib/python3.12/site-packages/airflow/utils/session.py", line 97, in wrapper
    return func(*args, session=session, **kwargs)
           ^^^^^^^^^^^^^^^^^^^^^^^^^^^^^^^^^^^^^^
  File "/home/airflow/.local/lib/python3.12/site-packages/airflow/models/taskinstance.py", line 3004, in _run_raw_task
    return _run_raw_task(
           ^^^^^^^^^^^^^^
  File "/home/airflow/.local/lib/python3.12/site-packages/airflow/models/taskinstance.py", line 273, in _run_raw_task
    TaskInstance._execute_task_with_callbacks(
  File "/home/airflow/.local/lib/python3.12/site-packages/airflow/models/taskinstance.py", line 3158, in _execute_task_with_callbacks
    result = self._execute_task(context, task_orig)
             ^^^^^^^^^^^^^^^^^^^^^^^^^^^^^^^^^^^^^^
  File "/home/airflow/.local/lib/python3.12/site-packages/airflow/models/taskinstance.py", line 3182, in _execute_task
    return _execute_task(self, context, task_orig)
           ^^^^^^^^^^^^^^^^^^^^^^^^^^^^^^^^^^^^^^^
  File "/home/airflow/.local/lib/python3.12/site-packages/airflow/models/taskinstance.py", line 767, in _execute_task
    result = _execute_callable(context=context, **execute_callable_kwargs)
             ^^^^^^^^^^^^^^^^^^^^^^^^^^^^^^^^^^^^^^^^^^^^^^^^^^^^^^^^^^^^^
  File "/home/airflow/.local/lib/python3.12/site-packages/airflow/models/taskinstance.py", line 733, in _execute_callable
    return ExecutionCallableRunner(
           ^^^^^^^^^^^^^^^^^^^^^^^^
  File "/home/airflow/.local/lib/python3.12/site-packages/airflow/utils/operator_helpers.py", line 252, in run
    return self.func(*args, **kwargs)
           ^^^^^^^^^^^^^^^^^^^^^^^^^^
  File "/home/airflow/.local/lib/python3.12/site-packages/airflow/models/baseoperator.py", line 406, in wrapper
    return func(self, *args, **kwargs)
           ^^^^^^^^^^^^^^^^^^^^^^^^^^^
  File "/home/airflow/.local/lib/python3.12/site-packages/airflow/operators/bash.py", line 249, in execute
    raise AirflowException(
airflow.exceptions.AirflowException: Bash command failed. The command returned a non-zero exit code 1.
[2024-11-06T12:09:34.979+0000] {local_task_job_runner.py:266} INFO - Task exited with return code 1
[2024-11-06T12:09:35.001+0000] {taskinstance.py:3900} INFO - 0 downstream tasks scheduled from follow-on schedule check
[2024-11-06T12:09:35.005+0000] {local_task_job_runner.py:245} INFO - ::endgroup::
[2024-11-06T12:24:03.587+0000] {local_task_job_runner.py:123} INFO - ::group::Pre task execution logs
[2024-11-06T12:24:03.614+0000] {taskinstance.py:2612} INFO - Dependencies all met for dep_context=non-requeueable deps ti=<TaskInstance: dbt_project_with_ge_dag.ge_validate_obt_sales scheduled__2024-11-05T00:00:00+00:00 [queued]>
[2024-11-06T12:24:03.631+0000] {taskinstance.py:2612} INFO - Dependencies all met for dep_context=requeueable deps ti=<TaskInstance: dbt_project_with_ge_dag.ge_validate_obt_sales scheduled__2024-11-05T00:00:00+00:00 [queued]>
[2024-11-06T12:24:03.632+0000] {taskinstance.py:2865} INFO - Starting attempt 3 of 3
[2024-11-06T12:24:03.655+0000] {taskinstance.py:2888} INFO - Executing <Task(BashOperator): ge_validate_obt_sales> on 2024-11-05 00:00:00+00:00
[2024-11-06T12:24:03.665+0000] {warnings.py:112} WARNING - /home/***/.local/lib/python3.12/site-packages/***/task/task_runner/standard_task_runner.py:70: DeprecationWarning: This process (pid=2428) is multi-threaded, use of fork() may lead to deadlocks in the child.
  pid = os.fork()

[2024-11-06T12:24:03.667+0000] {standard_task_runner.py:72} INFO - Started process 2429 to run task
[2024-11-06T12:24:03.668+0000] {standard_task_runner.py:104} INFO - Running: ['***', 'tasks', 'run', 'dbt_project_with_ge_dag', 'ge_validate_obt_sales', 'scheduled__2024-11-05T00:00:00+00:00', '--job-id', '185', '--raw', '--subdir', 'DAGS_FOLDER/dbt_project_dag.py', '--cfg-path', '/tmp/tmp40_yhc_w']
[2024-11-06T12:24:03.669+0000] {standard_task_runner.py:105} INFO - Job 185: Subtask ge_validate_obt_sales
[2024-11-06T12:24:03.741+0000] {task_command.py:467} INFO - Running <TaskInstance: dbt_project_with_ge_dag.ge_validate_obt_sales scheduled__2024-11-05T00:00:00+00:00 [running]> on host 9ecf534049e3
[2024-11-06T12:24:03.863+0000] {taskinstance.py:3131} INFO - Exporting env vars: AIRFLOW_CTX_DAG_OWNER='***' AIRFLOW_CTX_DAG_ID='dbt_project_with_ge_dag' AIRFLOW_CTX_TASK_ID='ge_validate_obt_sales' AIRFLOW_CTX_EXECUTION_DATE='2024-11-05T00:00:00+00:00' AIRFLOW_CTX_TRY_NUMBER='3' AIRFLOW_CTX_DAG_RUN_ID='scheduled__2024-11-05T00:00:00+00:00'
[2024-11-06T12:24:03.864+0000] {taskinstance.py:731} INFO - ::endgroup::
[2024-11-06T12:24:03.887+0000] {subprocess.py:63} INFO - Tmp dir root location: /tmp
[2024-11-06T12:24:03.888+0000] {subprocess.py:75} INFO - Running command: ['/usr/bin/bash', '-c', 'cd /opt/dbt && great_expectations checkpoint run obt_sales_checkpoint']
[2024-11-06T12:24:03.900+0000] {subprocess.py:86} INFO - Output:
[2024-11-06T12:24:13.457+0000] {subprocess.py:93} INFO - Calculating Metrics:   0%|          | 0/69 [00:00<?, ?it/s]Calculating Metrics:   0%|          | 0/69 [00:00<?, ?it/s]Calculating Metrics:   3%|▎         | 2/69 [00:00<00:00, 107.77it/s]Calculating Metrics:   3%|▎         | 2/69 [00:00<00:02, 23.94it/s] Calculating Metrics:   6%|▌         | 4/69 [00:00<00:01, 45.50it/s]Calculating Metrics:   6%|▌         | 4/69 [00:00<00:02, 27.31it/s]Calculating Metrics:   6%|▌         | 4/69 [00:00<00:02, 27.31it/s]Calculating Metrics:  25%|██▍       | 17/69 [00:00<00:01, 27.31it/s]Calculating Metrics:  25%|██▍       | 17/69 [00:00<00:01, 27.31it/s]Calculating Metrics:  83%|████████▎ | 57/69 [00:00<00:00, 229.80it/s]Calculating Metrics:  83%|████████▎ | 57/69 [00:00<00:00, 229.80it/s]Calculating Metrics:  83%|████████▎ | 57/69 [00:00<00:00, 229.80it/s]Calculating Metrics: 100%|██████████| 69/69 [00:00<00:00, 229.80it/s]Calculating Metrics: 100%|██████████| 69/69 [00:00<00:00, 229.80it/s]Calculating Metrics: 100%|██████████| 69/69 [00:00<00:00, 229.80it/s]Calculating Metrics: 100%|██████████| 69/69 [00:00<00:00, 193.63it/s]
[2024-11-06T12:24:13.700+0000] {subprocess.py:93} INFO - An unexpected Exception occurred during data docs rendering.  Because of this error, certain parts of data docs will not be rendered properly and/or may not appear altogether.  Please use the trace, included in this message, to diagnose and repair the underlying issue.  Detailed information follows:
[2024-11-06T12:24:13.700+0000] {subprocess.py:93} INFO -                 PermissionError: "[Errno 13] Permission denied: '/opt/dbt/gx/uncommitted/data_docs/local_site/expectations/obt_sales/basic.html'".  Traceback: "Traceback (most recent call last):
[2024-11-06T12:24:13.700+0000] {subprocess.py:93} INFO -   File "/home/***/.local/lib/python3.12/site-packages/great_expectations/render/renderer/site_builder.py", line 501, in build
[2024-11-06T12:24:13.701+0000] {subprocess.py:93} INFO -     self.target_store.set(
[2024-11-06T12:24:13.701+0000] {subprocess.py:93} INFO -   File "/home/***/.local/lib/python3.12/site-packages/great_expectations/data_context/store/html_site_store.py", line 269, in set
[2024-11-06T12:24:13.702+0000] {subprocess.py:93} INFO -     return self.store_backends[type(key.resource_identifier)].set(
[2024-11-06T12:24:13.702+0000] {subprocess.py:93} INFO -            ^^^^^^^^^^^^^^^^^^^^^^^^^^^^^^^^^^^^^^^^^^^^^^^^^^^^^^^
[2024-11-06T12:24:13.702+0000] {subprocess.py:93} INFO -   File "/home/***/.local/lib/python3.12/site-packages/great_expectations/data_context/store/_store_backend.py", line 134, in set
[2024-11-06T12:24:13.703+0000] {subprocess.py:93} INFO -     return self._set(key, value, **kwargs)
[2024-11-06T12:24:13.703+0000] {subprocess.py:93} INFO -            ^^^^^^^^^^^^^^^^^^^^^^^^^^^^^^^
[2024-11-06T12:24:13.704+0000] {subprocess.py:93} INFO -   File "/home/***/.local/lib/python3.12/site-packages/great_expectations/data_context/store/tuple_store_backend.py", line 330, in _set
[2024-11-06T12:24:13.704+0000] {subprocess.py:93} INFO -     with open(filepath, "wb") as outfile:
[2024-11-06T12:24:13.704+0000] {subprocess.py:93} INFO -          ^^^^^^^^^^^^^^^^^^^^
[2024-11-06T12:24:13.704+0000] {subprocess.py:93} INFO - PermissionError: [Errno 13] Permission denied: '/opt/dbt/gx/uncommitted/data_docs/local_site/expectations/obt_sales/basic.html'
[2024-11-06T12:24:13.705+0000] {subprocess.py:93} INFO - ".
[2024-11-06T12:24:13.848+0000] {subprocess.py:93} INFO - An unexpected Exception occurred during data docs rendering.  Because of this error, certain parts of data docs will not be rendered properly and/or may not appear altogether.  Please use the trace, included in this message, to diagnose and repair the underlying issue.  Detailed information follows:
[2024-11-06T12:24:13.849+0000] {subprocess.py:93} INFO -                 PermissionError: "[Errno 13] Permission denied: '/opt/dbt/gx/uncommitted/data_docs/local_site/validations/obt_sales/basic/20241106-122412-obt_sales-checkpoint'".  Traceback: "Traceback (most recent call last):
[2024-11-06T12:24:13.850+0000] {subprocess.py:93} INFO -   File "/home/***/.local/lib/python3.12/site-packages/great_expectations/render/renderer/site_builder.py", line 501, in build
[2024-11-06T12:24:13.850+0000] {subprocess.py:93} INFO -     self.target_store.set(
[2024-11-06T12:24:13.851+0000] {subprocess.py:93} INFO -   File "/home/***/.local/lib/python3.12/site-packages/great_expectations/data_context/store/html_site_store.py", line 269, in set
[2024-11-06T12:24:13.851+0000] {subprocess.py:93} INFO -     return self.store_backends[type(key.resource_identifier)].set(
[2024-11-06T12:24:13.851+0000] {subprocess.py:93} INFO -            ^^^^^^^^^^^^^^^^^^^^^^^^^^^^^^^^^^^^^^^^^^^^^^^^^^^^^^^
[2024-11-06T12:24:13.852+0000] {subprocess.py:93} INFO -   File "/home/***/.local/lib/python3.12/site-packages/great_expectations/data_context/store/_store_backend.py", line 134, in set
[2024-11-06T12:24:13.852+0000] {subprocess.py:93} INFO -     return self._set(key, value, **kwargs)
[2024-11-06T12:24:13.852+0000] {subprocess.py:93} INFO -            ^^^^^^^^^^^^^^^^^^^^^^^^^^^^^^^
[2024-11-06T12:24:13.852+0000] {subprocess.py:93} INFO -   File "/home/***/.local/lib/python3.12/site-packages/great_expectations/data_context/store/tuple_store_backend.py", line 329, in _set
[2024-11-06T12:24:13.853+0000] {subprocess.py:93} INFO -     os.makedirs(str(path), exist_ok=True)  # noqa: PTH103
[2024-11-06T12:24:13.853+0000] {subprocess.py:93} INFO -     ^^^^^^^^^^^^^^^^^^^^^^^^^^^^^^^^^^^^^
[2024-11-06T12:24:13.853+0000] {subprocess.py:93} INFO -   File "<frozen os>", line 215, in makedirs
[2024-11-06T12:24:13.853+0000] {subprocess.py:93} INFO -   File "<frozen os>", line 225, in makedirs
[2024-11-06T12:24:13.854+0000] {subprocess.py:93} INFO - PermissionError: [Errno 13] Permission denied: '/opt/dbt/gx/uncommitted/data_docs/local_site/validations/obt_sales/basic/20241106-122412-obt_sales-checkpoint'
[2024-11-06T12:24:13.854+0000] {subprocess.py:93} INFO - ".
[2024-11-06T12:24:13.864+0000] {subprocess.py:93} INFO - Error running action with name update_data_docs
[2024-11-06T12:24:13.865+0000] {subprocess.py:93} INFO - Traceback (most recent call last):
[2024-11-06T12:24:13.865+0000] {subprocess.py:93} INFO -   File "/home/***/.local/lib/python3.12/site-packages/great_expectations/validation_operators/validation_operators.py", line 476, in _run_actions
[2024-11-06T12:24:13.866+0000] {subprocess.py:93} INFO -     action_result = self.actions[name].run(
[2024-11-06T12:24:13.866+0000] {subprocess.py:93} INFO -                     ^^^^^^^^^^^^^^^^^^^^^^^
[2024-11-06T12:24:13.866+0000] {subprocess.py:93} INFO -   File "/home/***/.local/lib/python3.12/site-packages/great_expectations/checkpoint/actions.py", line 101, in run
[2024-11-06T12:24:13.867+0000] {subprocess.py:93} INFO -     return self._run(
[2024-11-06T12:24:13.867+0000] {subprocess.py:93} INFO -            ^^^^^^^^^^
[2024-11-06T12:24:13.868+0000] {subprocess.py:93} INFO -   File "/home/***/.local/lib/python3.12/site-packages/great_expectations/checkpoint/actions.py", line 1190, in _run
[2024-11-06T12:24:13.869+0000] {subprocess.py:93} INFO -     self.data_context.build_data_docs(
[2024-11-06T12:24:13.869+0000] {subprocess.py:93} INFO -   File "/home/***/.local/lib/python3.12/site-packages/great_expectations/core/usage_statistics/usage_statistics.py", line 266, in usage_statistics_wrapped_method
[2024-11-06T12:24:13.870+0000] {subprocess.py:93} INFO -     result = func(*args, **kwargs)
[2024-11-06T12:24:13.870+0000] {subprocess.py:93} INFO -              ^^^^^^^^^^^^^^^^^^^^^
[2024-11-06T12:24:13.871+0000] {subprocess.py:93} INFO -   File "/home/***/.local/lib/python3.12/site-packages/great_expectations/data_context/data_context/abstract_data_context.py", line 5318, in build_data_docs
[2024-11-06T12:24:13.871+0000] {subprocess.py:93} INFO -     return self._build_data_docs(
[2024-11-06T12:24:13.872+0000] {subprocess.py:93} INFO -            ^^^^^^^^^^^^^^^^^^^^^^
[2024-11-06T12:24:13.872+0000] {subprocess.py:93} INFO -   File "/home/***/.local/lib/python3.12/site-packages/great_expectations/data_context/data_context/abstract_data_context.py", line 5365, in _build_data_docs
[2024-11-06T12:24:13.873+0000] {subprocess.py:93} INFO -     index_page_resource_identifier_tuple = site_builder.build(
[2024-11-06T12:24:13.873+0000] {subprocess.py:93} INFO -                                            ^^^^^^^^^^^^^^^^^^^
[2024-11-06T12:24:13.873+0000] {subprocess.py:93} INFO -   File "/home/***/.local/lib/python3.12/site-packages/great_expectations/render/renderer/site_builder.py", line 329, in build
[2024-11-06T12:24:13.874+0000] {subprocess.py:93} INFO -     self.target_store.copy_static_assets()
[2024-11-06T12:24:13.875+0000] {subprocess.py:93} INFO -   File "/home/***/.local/lib/python3.12/site-packages/great_expectations/data_context/store/html_site_store.py", line 412, in copy_static_assets
[2024-11-06T12:24:13.876+0000] {subprocess.py:93} INFO -     self.copy_static_assets(new_source_dir)
[2024-11-06T12:24:13.876+0000] {subprocess.py:93} INFO -   File "/home/***/.local/lib/python3.12/site-packages/great_expectations/data_context/store/html_site_store.py", line 441, in copy_static_assets
[2024-11-06T12:24:13.877+0000] {subprocess.py:93} INFO -     self.store_backends["static_assets"].set(
[2024-11-06T12:24:13.878+0000] {subprocess.py:93} INFO -   File "/home/***/.local/lib/python3.12/site-packages/great_expectations/data_context/store/_store_backend.py", line 134, in set
[2024-11-06T12:24:13.878+0000] {subprocess.py:93} INFO -     return self._set(key, value, **kwargs)
[2024-11-06T12:24:13.879+0000] {subprocess.py:93} INFO -            ^^^^^^^^^^^^^^^^^^^^^^^^^^^^^^^
[2024-11-06T12:24:13.879+0000] {subprocess.py:93} INFO -   File "/home/***/.local/lib/python3.12/site-packages/great_expectations/data_context/store/tuple_store_backend.py", line 330, in _set
[2024-11-06T12:24:13.881+0000] {subprocess.py:93} INFO -     with open(filepath, "wb") as outfile:
[2024-11-06T12:24:13.881+0000] {subprocess.py:93} INFO -          ^^^^^^^^^^^^^^^^^^^^
[2024-11-06T12:24:13.882+0000] {subprocess.py:93} INFO - PermissionError: [Errno 13] Permission denied: '/opt/dbt/gx/uncommitted/data_docs/local_site/static/styles/data_docs_default_styles.css'
[2024-11-06T12:24:13.882+0000] {subprocess.py:93} INFO - [Errno 13] Permission denied: '/opt/dbt/gx/uncommitted/data_docs/local_site/static/styles/data_docs_default_styles.css'
[2024-11-06T12:24:14.760+0000] {subprocess.py:97} INFO - Command exited with return code 1
[2024-11-06T12:24:14.779+0000] {taskinstance.py:3310} ERROR - Task failed with exception
Traceback (most recent call last):
  File "/home/airflow/.local/lib/python3.12/site-packages/airflow/models/taskinstance.py", line 767, in _execute_task
    result = _execute_callable(context=context, **execute_callable_kwargs)
             ^^^^^^^^^^^^^^^^^^^^^^^^^^^^^^^^^^^^^^^^^^^^^^^^^^^^^^^^^^^^^
  File "/home/airflow/.local/lib/python3.12/site-packages/airflow/models/taskinstance.py", line 733, in _execute_callable
    return ExecutionCallableRunner(
           ^^^^^^^^^^^^^^^^^^^^^^^^
  File "/home/airflow/.local/lib/python3.12/site-packages/airflow/utils/operator_helpers.py", line 252, in run
    return self.func(*args, **kwargs)
           ^^^^^^^^^^^^^^^^^^^^^^^^^^
  File "/home/airflow/.local/lib/python3.12/site-packages/airflow/models/baseoperator.py", line 406, in wrapper
    return func(self, *args, **kwargs)
           ^^^^^^^^^^^^^^^^^^^^^^^^^^^
  File "/home/airflow/.local/lib/python3.12/site-packages/airflow/operators/bash.py", line 249, in execute
    raise AirflowException(
airflow.exceptions.AirflowException: Bash command failed. The command returned a non-zero exit code 1.
[2024-11-06T12:24:14.784+0000] {taskinstance.py:1225} INFO - Marking task as FAILED. dag_id=dbt_project_with_ge_dag, task_id=ge_validate_obt_sales, run_id=scheduled__2024-11-05T00:00:00+00:00, execution_date=20241105T000000, start_date=20241106T122403, end_date=20241106T122414
[2024-11-06T12:24:14.803+0000] {taskinstance.py:340} INFO - ::group::Post task execution logs
[2024-11-06T12:24:14.803+0000] {standard_task_runner.py:124} ERROR - Failed to execute job 185 for task ge_validate_obt_sales (Bash command failed. The command returned a non-zero exit code 1.; 2429)
Traceback (most recent call last):
  File "/home/airflow/.local/lib/python3.12/site-packages/airflow/task/task_runner/standard_task_runner.py", line 117, in _start_by_fork
    ret = args.func(args, dag=self.dag)
          ^^^^^^^^^^^^^^^^^^^^^^^^^^^^^
  File "/home/airflow/.local/lib/python3.12/site-packages/airflow/cli/cli_config.py", line 49, in command
    return func(*args, **kwargs)
           ^^^^^^^^^^^^^^^^^^^^^
  File "/home/airflow/.local/lib/python3.12/site-packages/airflow/utils/cli.py", line 115, in wrapper
    return f(*args, **kwargs)
           ^^^^^^^^^^^^^^^^^^
  File "/home/airflow/.local/lib/python3.12/site-packages/airflow/cli/commands/task_command.py", line 483, in task_run
    task_return_code = _run_task_by_selected_method(args, _dag, ti)
                       ^^^^^^^^^^^^^^^^^^^^^^^^^^^^^^^^^^^^^^^^^^^^
  File "/home/airflow/.local/lib/python3.12/site-packages/airflow/cli/commands/task_command.py", line 256, in _run_task_by_selected_method
    return _run_raw_task(args, ti)
           ^^^^^^^^^^^^^^^^^^^^^^^
  File "/home/airflow/.local/lib/python3.12/site-packages/airflow/cli/commands/task_command.py", line 341, in _run_raw_task
    return ti._run_raw_task(
           ^^^^^^^^^^^^^^^^^
  File "/home/airflow/.local/lib/python3.12/site-packages/airflow/utils/session.py", line 97, in wrapper
    return func(*args, session=session, **kwargs)
           ^^^^^^^^^^^^^^^^^^^^^^^^^^^^^^^^^^^^^^
  File "/home/airflow/.local/lib/python3.12/site-packages/airflow/models/taskinstance.py", line 3004, in _run_raw_task
    return _run_raw_task(
           ^^^^^^^^^^^^^^
  File "/home/airflow/.local/lib/python3.12/site-packages/airflow/models/taskinstance.py", line 273, in _run_raw_task
    TaskInstance._execute_task_with_callbacks(
  File "/home/airflow/.local/lib/python3.12/site-packages/airflow/models/taskinstance.py", line 3158, in _execute_task_with_callbacks
    result = self._execute_task(context, task_orig)
             ^^^^^^^^^^^^^^^^^^^^^^^^^^^^^^^^^^^^^^
  File "/home/airflow/.local/lib/python3.12/site-packages/airflow/models/taskinstance.py", line 3182, in _execute_task
    return _execute_task(self, context, task_orig)
           ^^^^^^^^^^^^^^^^^^^^^^^^^^^^^^^^^^^^^^^
  File "/home/airflow/.local/lib/python3.12/site-packages/airflow/models/taskinstance.py", line 767, in _execute_task
    result = _execute_callable(context=context, **execute_callable_kwargs)
             ^^^^^^^^^^^^^^^^^^^^^^^^^^^^^^^^^^^^^^^^^^^^^^^^^^^^^^^^^^^^^
  File "/home/airflow/.local/lib/python3.12/site-packages/airflow/models/taskinstance.py", line 733, in _execute_callable
    return ExecutionCallableRunner(
           ^^^^^^^^^^^^^^^^^^^^^^^^
  File "/home/airflow/.local/lib/python3.12/site-packages/airflow/utils/operator_helpers.py", line 252, in run
    return self.func(*args, **kwargs)
           ^^^^^^^^^^^^^^^^^^^^^^^^^^
  File "/home/airflow/.local/lib/python3.12/site-packages/airflow/models/baseoperator.py", line 406, in wrapper
    return func(self, *args, **kwargs)
           ^^^^^^^^^^^^^^^^^^^^^^^^^^^
  File "/home/airflow/.local/lib/python3.12/site-packages/airflow/operators/bash.py", line 249, in execute
    raise AirflowException(
airflow.exceptions.AirflowException: Bash command failed. The command returned a non-zero exit code 1.
[2024-11-06T12:24:14.846+0000] {local_task_job_runner.py:266} INFO - Task exited with return code 1
[2024-11-06T12:24:14.882+0000] {taskinstance.py:3900} INFO - 0 downstream tasks scheduled from follow-on schedule check
[2024-11-06T12:24:14.887+0000] {local_task_job_runner.py:245} INFO - ::endgroup::
