[2024-11-05T12:51:58.171+0000] {local_task_job_runner.py:123} INFO - ::group::Pre task execution logs
[2024-11-05T12:51:58.427+0000] {taskinstance.py:2612} INFO - Dependencies all met for dep_context=non-requeueable deps ti=<TaskInstance: dbt_workflow_orchestration.transform.sales.seed.adventureworks.salesorderdetail scheduled__2024-11-04T00:00:00+00:00 [queued]>
[2024-11-05T12:51:58.559+0000] {taskinstance.py:2612} INFO - Dependencies all met for dep_context=requeueable deps ti=<TaskInstance: dbt_workflow_orchestration.transform.sales.seed.adventureworks.salesorderdetail scheduled__2024-11-04T00:00:00+00:00 [queued]>
[2024-11-05T12:51:58.560+0000] {taskinstance.py:2865} INFO - Starting attempt 1 of 2
[2024-11-05T12:51:58.663+0000] {taskinstance.py:2888} INFO - Executing <Task(DbtSeedBashOperator): transform.sales.seed.adventureworks.salesorderdetail> on 2024-11-04 00:00:00+00:00
[2024-11-05T12:51:58.688+0000] {warnings.py:112} WARNING - /home/***/.local/lib/python3.12/site-packages/***/task/task_runner/standard_task_runner.py:70: DeprecationWarning: This process (pid=221) is multi-threaded, use of fork() may lead to deadlocks in the child.
  pid = os.fork()

[2024-11-05T12:51:58.708+0000] {standard_task_runner.py:72} INFO - Started process 259 to run task
[2024-11-05T12:51:58.711+0000] {standard_task_runner.py:104} INFO - Running: ['***', 'tasks', 'run', 'dbt_workflow_orchestration', 'transform.sales.seed.adventureworks.salesorderdetail', 'scheduled__2024-11-04T00:00:00+00:00', '--job-id', '26', '--raw', '--subdir', 'DAGS_FOLDER/dbt_orchestration.py', '--cfg-path', '/tmp/tmplowjpf6w']
[2024-11-05T12:51:58.714+0000] {standard_task_runner.py:105} INFO - Job 26: Subtask transform.sales.seed.adventureworks.salesorderdetail
[2024-11-05T12:51:59.618+0000] {task_command.py:467} INFO - Running <TaskInstance: dbt_workflow_orchestration.transform.sales.seed.adventureworks.salesorderdetail scheduled__2024-11-04T00:00:00+00:00 [running]> on host e36b82c08833
[2024-11-05T12:52:35.463+0000] {taskinstance.py:3131} INFO - Exporting env vars: AIRFLOW_CTX_DAG_OWNER='***' AIRFLOW_CTX_DAG_ID='dbt_workflow_orchestration' AIRFLOW_CTX_TASK_ID='transform.sales.seed.adventureworks.salesorderdetail' AIRFLOW_CTX_EXECUTION_DATE='2024-11-04T00:00:00+00:00' AIRFLOW_CTX_TRY_NUMBER='1' AIRFLOW_CTX_DAG_RUN_ID='scheduled__2024-11-04T00:00:00+00:00'
[2024-11-05T12:52:35.470+0000] {taskinstance.py:731} INFO - ::endgroup::
[2024-11-05T12:52:35.704+0000] {subprocess.py:63} INFO - Tmp dir root location: /tmp
[2024-11-05T12:52:35.708+0000] {subprocess.py:75} INFO - Running command: ['/usr/bin/bash', '-c', 'dbt --no-write-json seed --project-dir /opt/dbt --profiles-dir /opt/dbt --target dev --select salesorderdetail']
[2024-11-05T12:52:35.742+0000] {subprocess.py:86} INFO - Output:
[2024-11-05T12:52:38.470+0000] {job.py:229} INFO - Heartbeat recovered after 41.19 seconds
[2024-11-05T12:53:18.041+0000] {job.py:229} INFO - Heartbeat recovered after 33.48 seconds
[2024-11-05T12:53:51.827+0000] {subprocess.py:93} INFO - [0m12:53:51  Running with dbt=1.8.2
[2024-11-05T12:53:51.966+0000] {subprocess.py:93} INFO - [0m12:53:51  Encountered an error:
[2024-11-05T12:53:51.969+0000] {subprocess.py:93} INFO - Runtime Error
[2024-11-05T12:53:51.973+0000] {subprocess.py:93} INFO -   The profile 'adventureworks' does not have a target named 'dev'. The valid target names for this profile are:
[2024-11-05T12:53:51.974+0000] {subprocess.py:93} INFO -    - postgres
[2024-11-05T12:53:54.681+0000] {subprocess.py:97} INFO - Command exited with return code 2
[2024-11-05T12:53:54.905+0000] {taskinstance.py:3310} ERROR - Task failed with exception
Traceback (most recent call last):
  File "/home/airflow/.local/lib/python3.12/site-packages/airflow/models/taskinstance.py", line 767, in _execute_task
    result = _execute_callable(context=context, **execute_callable_kwargs)
             ^^^^^^^^^^^^^^^^^^^^^^^^^^^^^^^^^^^^^^^^^^^^^^^^^^^^^^^^^^^^^
  File "/home/airflow/.local/lib/python3.12/site-packages/airflow/models/taskinstance.py", line 733, in _execute_callable
    return ExecutionCallableRunner(
           ^^^^^^^^^^^^^^^^^^^^^^^^
  File "/home/airflow/.local/lib/python3.12/site-packages/airflow/utils/operator_helpers.py", line 252, in run
    return self.func(*args, **kwargs)
           ^^^^^^^^^^^^^^^^^^^^^^^^^^
  File "/home/airflow/.local/lib/python3.12/site-packages/airflow/models/baseoperator.py", line 406, in wrapper
    return func(self, *args, **kwargs)
           ^^^^^^^^^^^^^^^^^^^^^^^^^^^
  File "/home/airflow/.local/lib/python3.12/site-packages/airflow/operators/bash.py", line 249, in execute
    raise AirflowException(
airflow.exceptions.AirflowException: Bash command failed. The command returned a non-zero exit code 2.
[2024-11-05T12:53:54.992+0000] {taskinstance.py:1225} INFO - Marking task as UP_FOR_RETRY. dag_id=dbt_workflow_orchestration, task_id=transform.sales.seed.adventureworks.salesorderdetail, run_id=scheduled__2024-11-04T00:00:00+00:00, execution_date=20241104T000000, start_date=20241105T125158, end_date=20241105T125354
[2024-11-05T12:53:55.102+0000] {taskinstance.py:340} INFO - ::group::Post task execution logs
[2024-11-05T12:53:55.107+0000] {standard_task_runner.py:124} ERROR - Failed to execute job 26 for task transform.sales.seed.adventureworks.salesorderdetail (Bash command failed. The command returned a non-zero exit code 2.; 259)
Traceback (most recent call last):
  File "/home/airflow/.local/lib/python3.12/site-packages/airflow/task/task_runner/standard_task_runner.py", line 117, in _start_by_fork
    ret = args.func(args, dag=self.dag)
          ^^^^^^^^^^^^^^^^^^^^^^^^^^^^^
  File "/home/airflow/.local/lib/python3.12/site-packages/airflow/cli/cli_config.py", line 49, in command
    return func(*args, **kwargs)
           ^^^^^^^^^^^^^^^^^^^^^
  File "/home/airflow/.local/lib/python3.12/site-packages/airflow/utils/cli.py", line 115, in wrapper
    return f(*args, **kwargs)
           ^^^^^^^^^^^^^^^^^^
  File "/home/airflow/.local/lib/python3.12/site-packages/airflow/cli/commands/task_command.py", line 483, in task_run
    task_return_code = _run_task_by_selected_method(args, _dag, ti)
                       ^^^^^^^^^^^^^^^^^^^^^^^^^^^^^^^^^^^^^^^^^^^^
  File "/home/airflow/.local/lib/python3.12/site-packages/airflow/cli/commands/task_command.py", line 256, in _run_task_by_selected_method
    return _run_raw_task(args, ti)
           ^^^^^^^^^^^^^^^^^^^^^^^
  File "/home/airflow/.local/lib/python3.12/site-packages/airflow/cli/commands/task_command.py", line 341, in _run_raw_task
    return ti._run_raw_task(
           ^^^^^^^^^^^^^^^^^
  File "/home/airflow/.local/lib/python3.12/site-packages/airflow/utils/session.py", line 97, in wrapper
    return func(*args, session=session, **kwargs)
           ^^^^^^^^^^^^^^^^^^^^^^^^^^^^^^^^^^^^^^
  File "/home/airflow/.local/lib/python3.12/site-packages/airflow/models/taskinstance.py", line 3004, in _run_raw_task
    return _run_raw_task(
           ^^^^^^^^^^^^^^
  File "/home/airflow/.local/lib/python3.12/site-packages/airflow/models/taskinstance.py", line 273, in _run_raw_task
    TaskInstance._execute_task_with_callbacks(
  File "/home/airflow/.local/lib/python3.12/site-packages/airflow/models/taskinstance.py", line 3158, in _execute_task_with_callbacks
    result = self._execute_task(context, task_orig)
             ^^^^^^^^^^^^^^^^^^^^^^^^^^^^^^^^^^^^^^
  File "/home/airflow/.local/lib/python3.12/site-packages/airflow/models/taskinstance.py", line 3182, in _execute_task
    return _execute_task(self, context, task_orig)
           ^^^^^^^^^^^^^^^^^^^^^^^^^^^^^^^^^^^^^^^
  File "/home/airflow/.local/lib/python3.12/site-packages/airflow/models/taskinstance.py", line 767, in _execute_task
    result = _execute_callable(context=context, **execute_callable_kwargs)
             ^^^^^^^^^^^^^^^^^^^^^^^^^^^^^^^^^^^^^^^^^^^^^^^^^^^^^^^^^^^^^
  File "/home/airflow/.local/lib/python3.12/site-packages/airflow/models/taskinstance.py", line 733, in _execute_callable
    return ExecutionCallableRunner(
           ^^^^^^^^^^^^^^^^^^^^^^^^
  File "/home/airflow/.local/lib/python3.12/site-packages/airflow/utils/operator_helpers.py", line 252, in run
    return self.func(*args, **kwargs)
           ^^^^^^^^^^^^^^^^^^^^^^^^^^
  File "/home/airflow/.local/lib/python3.12/site-packages/airflow/models/baseoperator.py", line 406, in wrapper
    return func(self, *args, **kwargs)
           ^^^^^^^^^^^^^^^^^^^^^^^^^^^
  File "/home/airflow/.local/lib/python3.12/site-packages/airflow/operators/bash.py", line 249, in execute
    raise AirflowException(
airflow.exceptions.AirflowException: Bash command failed. The command returned a non-zero exit code 2.
[2024-11-05T12:53:55.202+0000] {local_task_job_runner.py:266} INFO - Task exited with return code 1
[2024-11-05T12:53:55.438+0000] {local_task_job_runner.py:245} INFO - ::endgroup::
