[2024-11-05T13:47:39.273+0000] {local_task_job_runner.py:123} INFO - ::group::Pre task execution logs
[2024-11-05T13:47:39.319+0000] {taskinstance.py:2612} INFO - Dependencies all met for dep_context=non-requeueable deps ti=<TaskInstance: dbt_docs_serve_dag.dbt_docs_serve manual__2024-11-05T13:47:37.636530+00:00 [queued]>
[2024-11-05T13:47:39.339+0000] {taskinstance.py:2612} INFO - Dependencies all met for dep_context=requeueable deps ti=<TaskInstance: dbt_docs_serve_dag.dbt_docs_serve manual__2024-11-05T13:47:37.636530+00:00 [queued]>
[2024-11-05T13:47:39.339+0000] {taskinstance.py:2865} INFO - Starting attempt 1 of 2
[2024-11-05T13:47:39.421+0000] {taskinstance.py:2888} INFO - Executing <Task(BashOperator): dbt_docs_serve> on 2024-11-05 13:47:37.636530+00:00
[2024-11-05T13:47:39.433+0000] {warnings.py:112} WARNING - /home/***/.local/lib/python3.12/site-packages/***/task/task_runner/standard_task_runner.py:70: DeprecationWarning: This process (pid=440) is multi-threaded, use of fork() may lead to deadlocks in the child.
  pid = os.fork()

[2024-11-05T13:47:39.435+0000] {standard_task_runner.py:72} INFO - Started process 441 to run task
[2024-11-05T13:47:39.436+0000] {standard_task_runner.py:104} INFO - Running: ['***', 'tasks', 'run', 'dbt_docs_serve_dag', 'dbt_docs_serve', 'manual__2024-11-05T13:47:37.636530+00:00', '--job-id', '105', '--raw', '--subdir', 'DAGS_FOLDER/dbt_docs_serve_dag.py', '--cfg-path', '/tmp/tmpovuisb45']
[2024-11-05T13:47:39.438+0000] {standard_task_runner.py:105} INFO - Job 105: Subtask dbt_docs_serve
[2024-11-05T13:47:39.598+0000] {task_command.py:467} INFO - Running <TaskInstance: dbt_docs_serve_dag.dbt_docs_serve manual__2024-11-05T13:47:37.636530+00:00 [running]> on host bbd20199defe
[2024-11-05T13:47:39.839+0000] {taskinstance.py:3131} INFO - Exporting env vars: AIRFLOW_CTX_DAG_OWNER='***' AIRFLOW_CTX_DAG_ID='dbt_docs_serve_dag' AIRFLOW_CTX_TASK_ID='dbt_docs_serve' AIRFLOW_CTX_EXECUTION_DATE='2024-11-05T13:47:37.636530+00:00' AIRFLOW_CTX_TRY_NUMBER='1' AIRFLOW_CTX_DAG_RUN_ID='manual__2024-11-05T13:47:37.636530+00:00'
[2024-11-05T13:47:39.840+0000] {taskinstance.py:731} INFO - ::endgroup::
[2024-11-05T13:47:39.861+0000] {subprocess.py:63} INFO - Tmp dir root location: /tmp
[2024-11-05T13:47:39.862+0000] {subprocess.py:75} INFO - Running command: ['/usr/bin/bash', '-c', 'cd /opt/dbt && nohup dbt docs serve  --port 8001 &']
[2024-11-05T13:47:39.873+0000] {subprocess.py:86} INFO - Output:
[2024-11-05T13:47:46.027+0000] {subprocess.py:93} INFO - [0m13:47:46  Running with dbt=1.8.2
[2024-11-05T13:47:47.058+0000] {subprocess.py:93} INFO - [0m13:47:47  Encountered an error:
[2024-11-05T13:47:47.061+0000] {subprocess.py:93} INFO - [Errno 98] Address already in use
[2024-11-05T13:47:47.066+0000] {subprocess.py:93} INFO - [0m13:47:47  Traceback (most recent call last):
[2024-11-05T13:47:47.067+0000] {subprocess.py:93} INFO -   File "/home/***/.local/lib/python3.12/site-packages/dbt/cli/requires.py", line 138, in wrapper
[2024-11-05T13:47:47.067+0000] {subprocess.py:93} INFO -     result, success = func(*args, **kwargs)
[2024-11-05T13:47:47.068+0000] {subprocess.py:93} INFO -                       ^^^^^^^^^^^^^^^^^^^^^
[2024-11-05T13:47:47.072+0000] {subprocess.py:93} INFO -   File "/home/***/.local/lib/python3.12/site-packages/dbt/cli/requires.py", line 101, in wrapper
[2024-11-05T13:47:47.073+0000] {subprocess.py:93} INFO -     return func(*args, **kwargs)
[2024-11-05T13:47:47.073+0000] {subprocess.py:93} INFO -            ^^^^^^^^^^^^^^^^^^^^^
[2024-11-05T13:47:47.078+0000] {subprocess.py:93} INFO -   File "/home/***/.local/lib/python3.12/site-packages/dbt/cli/requires.py", line 218, in wrapper
[2024-11-05T13:47:47.079+0000] {subprocess.py:93} INFO -     return func(*args, **kwargs)
[2024-11-05T13:47:47.080+0000] {subprocess.py:93} INFO -            ^^^^^^^^^^^^^^^^^^^^^
[2024-11-05T13:47:47.080+0000] {subprocess.py:93} INFO -   File "/home/***/.local/lib/python3.12/site-packages/dbt/cli/requires.py", line 247, in wrapper
[2024-11-05T13:47:47.081+0000] {subprocess.py:93} INFO -     return func(*args, **kwargs)
[2024-11-05T13:47:47.082+0000] {subprocess.py:93} INFO -            ^^^^^^^^^^^^^^^^^^^^^
[2024-11-05T13:47:47.083+0000] {subprocess.py:93} INFO -   File "/home/***/.local/lib/python3.12/site-packages/dbt/cli/requires.py", line 294, in wrapper
[2024-11-05T13:47:47.083+0000] {subprocess.py:93} INFO -     return func(*args, **kwargs)
[2024-11-05T13:47:47.083+0000] {subprocess.py:93} INFO -            ^^^^^^^^^^^^^^^^^^^^^
[2024-11-05T13:47:47.084+0000] {subprocess.py:93} INFO -   File "/home/***/.local/lib/python3.12/site-packages/dbt/cli/main.py", line 303, in docs_serve
[2024-11-05T13:47:47.085+0000] {subprocess.py:93} INFO -     results = task.run()
[2024-11-05T13:47:47.092+0000] {subprocess.py:93} INFO -               ^^^^^^^^^^
[2024-11-05T13:47:47.094+0000] {subprocess.py:93} INFO -   File "/home/***/.local/lib/python3.12/site-packages/dbt/task/docs/serve.py", line 24, in run
[2024-11-05T13:47:47.095+0000] {subprocess.py:93} INFO -     with socketserver.TCPServer((host, port), SimpleHTTPRequestHandler) as httpd:
[2024-11-05T13:47:47.095+0000] {subprocess.py:93} INFO -          ^^^^^^^^^^^^^^^^^^^^^^^^^^^^^^^^^^^^^^^^^^^^^^^^^^^^^^^^^^^^^^
[2024-11-05T13:47:47.095+0000] {subprocess.py:93} INFO -   File "/usr/local/lib/python3.12/socketserver.py", line 457, in __init__
[2024-11-05T13:47:47.096+0000] {subprocess.py:93} INFO -     self.server_bind()
[2024-11-05T13:47:47.097+0000] {subprocess.py:93} INFO -   File "/usr/local/lib/python3.12/socketserver.py", line 473, in server_bind
[2024-11-05T13:47:47.097+0000] {subprocess.py:93} INFO -     self.socket.bind(self.server_address)
[2024-11-05T13:47:47.098+0000] {subprocess.py:93} INFO - OSError: [Errno 98] Address already in use
[2024-11-05T13:47:47.098+0000] {subprocess.py:93} INFO - 
[2024-11-05T13:47:49.033+0000] {subprocess.py:97} INFO - Command exited with return code 0
[2024-11-05T13:47:49.068+0000] {taskinstance.py:340} INFO - ::group::Post task execution logs
[2024-11-05T13:47:49.069+0000] {taskinstance.py:352} INFO - Marking task as SUCCESS. dag_id=dbt_docs_serve_dag, task_id=dbt_docs_serve, run_id=manual__2024-11-05T13:47:37.636530+00:00, execution_date=20241105T134737, start_date=20241105T134739, end_date=20241105T134749
[2024-11-05T13:47:49.112+0000] {local_task_job_runner.py:266} INFO - Task exited with return code 0
[2024-11-05T13:47:49.138+0000] {taskinstance.py:3900} INFO - 1 downstream tasks scheduled from follow-on schedule check
[2024-11-05T13:47:49.141+0000] {local_task_job_runner.py:245} INFO - ::endgroup::
