[2024-11-05T16:21:34.039+0000] {local_task_job_runner.py:123} INFO - ::group::Pre task execution logs
[2024-11-05T16:21:34.067+0000] {taskinstance.py:2612} INFO - Dependencies all met for dep_context=non-requeueable deps ti=<TaskInstance: dbt_docs_serve_dag.dbt_docs_serve manual__2024-11-05T16:21:32.215318+00:00 [queued]>
[2024-11-05T16:21:34.079+0000] {taskinstance.py:2612} INFO - Dependencies all met for dep_context=requeueable deps ti=<TaskInstance: dbt_docs_serve_dag.dbt_docs_serve manual__2024-11-05T16:21:32.215318+00:00 [queued]>
[2024-11-05T16:21:34.080+0000] {taskinstance.py:2865} INFO - Starting attempt 1 of 2
[2024-11-05T16:21:34.099+0000] {taskinstance.py:2888} INFO - Executing <Task(BashOperator): dbt_docs_serve> on 2024-11-05 16:21:32.215318+00:00
[2024-11-05T16:21:34.105+0000] {warnings.py:112} WARNING - /home/***/.local/lib/python3.12/site-packages/***/task/task_runner/standard_task_runner.py:70: DeprecationWarning: This process (pid=185) is multi-threaded, use of fork() may lead to deadlocks in the child.
  pid = os.fork()

[2024-11-05T16:21:34.107+0000] {standard_task_runner.py:72} INFO - Started process 186 to run task
[2024-11-05T16:21:34.107+0000] {standard_task_runner.py:104} INFO - Running: ['***', 'tasks', 'run', 'dbt_docs_serve_dag', 'dbt_docs_serve', 'manual__2024-11-05T16:21:32.215318+00:00', '--job-id', '126', '--raw', '--subdir', 'DAGS_FOLDER/dbt_docs_serve_dag.py', '--cfg-path', '/tmp/tmpbmikp1x0']
[2024-11-05T16:21:34.109+0000] {standard_task_runner.py:105} INFO - Job 126: Subtask dbt_docs_serve
[2024-11-05T16:21:34.168+0000] {task_command.py:467} INFO - Running <TaskInstance: dbt_docs_serve_dag.dbt_docs_serve manual__2024-11-05T16:21:32.215318+00:00 [running]> on host 97a2f369554a
[2024-11-05T16:21:34.269+0000] {taskinstance.py:3131} INFO - Exporting env vars: AIRFLOW_CTX_DAG_OWNER='***' AIRFLOW_CTX_DAG_ID='dbt_docs_serve_dag' AIRFLOW_CTX_TASK_ID='dbt_docs_serve' AIRFLOW_CTX_EXECUTION_DATE='2024-11-05T16:21:32.215318+00:00' AIRFLOW_CTX_TRY_NUMBER='1' AIRFLOW_CTX_DAG_RUN_ID='manual__2024-11-05T16:21:32.215318+00:00'
[2024-11-05T16:21:34.270+0000] {taskinstance.py:731} INFO - ::endgroup::
[2024-11-05T16:21:34.289+0000] {subprocess.py:63} INFO - Tmp dir root location: /tmp
[2024-11-05T16:21:34.289+0000] {subprocess.py:75} INFO - Running command: ['/usr/bin/bash', '-c', 'cd /opt/dbt &&  dbt docs serve --port 8001 --host 0.0.0.0']
[2024-11-05T16:21:34.301+0000] {subprocess.py:86} INFO - Output:
[2024-11-05T16:21:37.655+0000] {subprocess.py:93} INFO - [0m16:21:37  Running with dbt=1.8.2
[2024-11-05T16:21:38.149+0000] {subprocess.py:93} INFO - [0m16:21:38  Encountered an error:
[2024-11-05T16:21:38.150+0000] {subprocess.py:93} INFO - [Errno 98] Address already in use
[2024-11-05T16:21:38.150+0000] {subprocess.py:93} INFO - [0m16:21:38  Traceback (most recent call last):
[2024-11-05T16:21:38.151+0000] {subprocess.py:93} INFO -   File "/home/***/.local/lib/python3.12/site-packages/dbt/cli/requires.py", line 138, in wrapper
[2024-11-05T16:21:38.151+0000] {subprocess.py:93} INFO -     result, success = func(*args, **kwargs)
[2024-11-05T16:21:38.152+0000] {subprocess.py:93} INFO -                       ^^^^^^^^^^^^^^^^^^^^^
[2024-11-05T16:21:38.152+0000] {subprocess.py:93} INFO -   File "/home/***/.local/lib/python3.12/site-packages/dbt/cli/requires.py", line 101, in wrapper
[2024-11-05T16:21:38.153+0000] {subprocess.py:93} INFO -     return func(*args, **kwargs)
[2024-11-05T16:21:38.153+0000] {subprocess.py:93} INFO -            ^^^^^^^^^^^^^^^^^^^^^
[2024-11-05T16:21:38.154+0000] {subprocess.py:93} INFO -   File "/home/***/.local/lib/python3.12/site-packages/dbt/cli/requires.py", line 218, in wrapper
[2024-11-05T16:21:38.154+0000] {subprocess.py:93} INFO -     return func(*args, **kwargs)
[2024-11-05T16:21:38.155+0000] {subprocess.py:93} INFO -            ^^^^^^^^^^^^^^^^^^^^^
[2024-11-05T16:21:38.155+0000] {subprocess.py:93} INFO -   File "/home/***/.local/lib/python3.12/site-packages/dbt/cli/requires.py", line 247, in wrapper
[2024-11-05T16:21:38.157+0000] {subprocess.py:93} INFO -     return func(*args, **kwargs)
[2024-11-05T16:21:38.158+0000] {subprocess.py:93} INFO -            ^^^^^^^^^^^^^^^^^^^^^
[2024-11-05T16:21:38.158+0000] {subprocess.py:93} INFO -   File "/home/***/.local/lib/python3.12/site-packages/dbt/cli/requires.py", line 294, in wrapper
[2024-11-05T16:21:38.159+0000] {subprocess.py:93} INFO -     return func(*args, **kwargs)
[2024-11-05T16:21:38.159+0000] {subprocess.py:93} INFO -            ^^^^^^^^^^^^^^^^^^^^^
[2024-11-05T16:21:38.160+0000] {subprocess.py:93} INFO -   File "/home/***/.local/lib/python3.12/site-packages/dbt/cli/main.py", line 303, in docs_serve
[2024-11-05T16:21:38.161+0000] {subprocess.py:93} INFO -     results = task.run()
[2024-11-05T16:21:38.161+0000] {subprocess.py:93} INFO -               ^^^^^^^^^^
[2024-11-05T16:21:38.162+0000] {subprocess.py:93} INFO -   File "/home/***/.local/lib/python3.12/site-packages/dbt/task/docs/serve.py", line 24, in run
[2024-11-05T16:21:38.162+0000] {subprocess.py:93} INFO -     with socketserver.TCPServer((host, port), SimpleHTTPRequestHandler) as httpd:
[2024-11-05T16:21:38.163+0000] {subprocess.py:93} INFO -          ^^^^^^^^^^^^^^^^^^^^^^^^^^^^^^^^^^^^^^^^^^^^^^^^^^^^^^^^^^^^^^
[2024-11-05T16:21:38.165+0000] {subprocess.py:93} INFO -   File "/usr/local/lib/python3.12/socketserver.py", line 457, in __init__
[2024-11-05T16:21:38.165+0000] {subprocess.py:93} INFO -     self.server_bind()
[2024-11-05T16:21:38.166+0000] {subprocess.py:93} INFO -   File "/usr/local/lib/python3.12/socketserver.py", line 473, in server_bind
[2024-11-05T16:21:38.166+0000] {subprocess.py:93} INFO -     self.socket.bind(self.server_address)
[2024-11-05T16:21:38.167+0000] {subprocess.py:93} INFO - OSError: [Errno 98] Address already in use
[2024-11-05T16:21:38.167+0000] {subprocess.py:93} INFO - 
[2024-11-05T16:21:39.378+0000] {subprocess.py:97} INFO - Command exited with return code 2
[2024-11-05T16:21:39.392+0000] {taskinstance.py:3310} ERROR - Task failed with exception
Traceback (most recent call last):
  File "/home/airflow/.local/lib/python3.12/site-packages/airflow/models/taskinstance.py", line 767, in _execute_task
    result = _execute_callable(context=context, **execute_callable_kwargs)
             ^^^^^^^^^^^^^^^^^^^^^^^^^^^^^^^^^^^^^^^^^^^^^^^^^^^^^^^^^^^^^
  File "/home/airflow/.local/lib/python3.12/site-packages/airflow/models/taskinstance.py", line 733, in _execute_callable
    return ExecutionCallableRunner(
           ^^^^^^^^^^^^^^^^^^^^^^^^
  File "/home/airflow/.local/lib/python3.12/site-packages/airflow/utils/operator_helpers.py", line 252, in run
    return self.func(*args, **kwargs)
           ^^^^^^^^^^^^^^^^^^^^^^^^^^
  File "/home/airflow/.local/lib/python3.12/site-packages/airflow/models/baseoperator.py", line 406, in wrapper
    return func(self, *args, **kwargs)
           ^^^^^^^^^^^^^^^^^^^^^^^^^^^
  File "/home/airflow/.local/lib/python3.12/site-packages/airflow/operators/bash.py", line 249, in execute
    raise AirflowException(
airflow.exceptions.AirflowException: Bash command failed. The command returned a non-zero exit code 2.
[2024-11-05T16:21:39.401+0000] {taskinstance.py:1225} INFO - Marking task as UP_FOR_RETRY. dag_id=dbt_docs_serve_dag, task_id=dbt_docs_serve, run_id=manual__2024-11-05T16:21:32.215318+00:00, execution_date=20241105T162132, start_date=20241105T162134, end_date=20241105T162139
[2024-11-05T16:21:39.428+0000] {taskinstance.py:340} INFO - ::group::Post task execution logs
[2024-11-05T16:21:39.429+0000] {standard_task_runner.py:124} ERROR - Failed to execute job 126 for task dbt_docs_serve (Bash command failed. The command returned a non-zero exit code 2.; 186)
Traceback (most recent call last):
  File "/home/airflow/.local/lib/python3.12/site-packages/airflow/task/task_runner/standard_task_runner.py", line 117, in _start_by_fork
    ret = args.func(args, dag=self.dag)
          ^^^^^^^^^^^^^^^^^^^^^^^^^^^^^
  File "/home/airflow/.local/lib/python3.12/site-packages/airflow/cli/cli_config.py", line 49, in command
    return func(*args, **kwargs)
           ^^^^^^^^^^^^^^^^^^^^^
  File "/home/airflow/.local/lib/python3.12/site-packages/airflow/utils/cli.py", line 115, in wrapper
    return f(*args, **kwargs)
           ^^^^^^^^^^^^^^^^^^
  File "/home/airflow/.local/lib/python3.12/site-packages/airflow/cli/commands/task_command.py", line 483, in task_run
    task_return_code = _run_task_by_selected_method(args, _dag, ti)
                       ^^^^^^^^^^^^^^^^^^^^^^^^^^^^^^^^^^^^^^^^^^^^
  File "/home/airflow/.local/lib/python3.12/site-packages/airflow/cli/commands/task_command.py", line 256, in _run_task_by_selected_method
    return _run_raw_task(args, ti)
           ^^^^^^^^^^^^^^^^^^^^^^^
  File "/home/airflow/.local/lib/python3.12/site-packages/airflow/cli/commands/task_command.py", line 341, in _run_raw_task
    return ti._run_raw_task(
           ^^^^^^^^^^^^^^^^^
  File "/home/airflow/.local/lib/python3.12/site-packages/airflow/utils/session.py", line 97, in wrapper
    return func(*args, session=session, **kwargs)
           ^^^^^^^^^^^^^^^^^^^^^^^^^^^^^^^^^^^^^^
  File "/home/airflow/.local/lib/python3.12/site-packages/airflow/models/taskinstance.py", line 3004, in _run_raw_task
    return _run_raw_task(
           ^^^^^^^^^^^^^^
  File "/home/airflow/.local/lib/python3.12/site-packages/airflow/models/taskinstance.py", line 273, in _run_raw_task
    TaskInstance._execute_task_with_callbacks(
  File "/home/airflow/.local/lib/python3.12/site-packages/airflow/models/taskinstance.py", line 3158, in _execute_task_with_callbacks
    result = self._execute_task(context, task_orig)
             ^^^^^^^^^^^^^^^^^^^^^^^^^^^^^^^^^^^^^^
  File "/home/airflow/.local/lib/python3.12/site-packages/airflow/models/taskinstance.py", line 3182, in _execute_task
    return _execute_task(self, context, task_orig)
           ^^^^^^^^^^^^^^^^^^^^^^^^^^^^^^^^^^^^^^^
  File "/home/airflow/.local/lib/python3.12/site-packages/airflow/models/taskinstance.py", line 767, in _execute_task
    result = _execute_callable(context=context, **execute_callable_kwargs)
             ^^^^^^^^^^^^^^^^^^^^^^^^^^^^^^^^^^^^^^^^^^^^^^^^^^^^^^^^^^^^^
  File "/home/airflow/.local/lib/python3.12/site-packages/airflow/models/taskinstance.py", line 733, in _execute_callable
    return ExecutionCallableRunner(
           ^^^^^^^^^^^^^^^^^^^^^^^^
  File "/home/airflow/.local/lib/python3.12/site-packages/airflow/utils/operator_helpers.py", line 252, in run
    return self.func(*args, **kwargs)
           ^^^^^^^^^^^^^^^^^^^^^^^^^^
  File "/home/airflow/.local/lib/python3.12/site-packages/airflow/models/baseoperator.py", line 406, in wrapper
    return func(self, *args, **kwargs)
           ^^^^^^^^^^^^^^^^^^^^^^^^^^^
  File "/home/airflow/.local/lib/python3.12/site-packages/airflow/operators/bash.py", line 249, in execute
    raise AirflowException(
airflow.exceptions.AirflowException: Bash command failed. The command returned a non-zero exit code 2.
[2024-11-05T16:21:39.449+0000] {local_task_job_runner.py:266} INFO - Task exited with return code 1
[2024-11-05T16:21:39.482+0000] {taskinstance.py:3900} INFO - 0 downstream tasks scheduled from follow-on schedule check
[2024-11-05T16:21:39.484+0000] {local_task_job_runner.py:245} INFO - ::endgroup::
